# Goxel 0.14.0
# One line per voxel
# X Y Z RRGGBB
0 32 0 3f3f3f
1 32 0 3f3f3f
2 32 0 3f3f3f
3 32 0 3f3f3f
4 32 0 3f3f3f
5 32 0 3f3f3f
6 32 0 3f3f3f
7 32 0 3f3f3f
8 32 0 3f3f3f
9 32 0 3f3f3f
10 32 0 3f3f3f
11 32 0 3f3f3f
12 32 0 3f3f3f
13 32 0 3f3f3f
14 32 0 3f3f3f
15 32 0 3f3f3f
0 33 0 3f3f3f
1 33 0 3f3f3f
2 33 0 3f3f3f
3 33 0 3f3f3f
4 33 0 3f3f3f
5 33 0 3f3f3f
6 33 0 3f3f3f
7 33 0 3f3f3f
8 33 0 3f3f3f
9 33 0 3f3f3f
10 33 0 3f3f3f
11 33 0 3f3f3f
12 33 0 3f3f3f
13 33 0 3f3f3f
14 33 0 3f3f3f
15 33 0 3f3f3f
0 34 0 3f3f3f
1 34 0 3f3f3f
2 34 0 3f3f3f
3 34 0 3f3f3f
4 34 0 3f3f3f
5 34 0 3f3f3f
6 34 0 3f3f3f
7 34 0 3f3f3f
8 34 0 3f3f3f
9 34 0 3f3f3f
10 34 0 3f3f3f
11 34 0 3f3f3f
12 34 0 3f3f3f
13 34 0 3f3f3f
14 34 0 3f3f3f
15 34 0 3f3f3f
0 35 0 3f3f3f
1 35 0 3f3f3f
2 35 0 3f3f3f
3 35 0 3f3f3f
4 35 0 3f3f3f
5 35 0 3f3f3f
6 35 0 3f3f3f
7 35 0 3f3f3f
8 35 0 3f3f3f
9 35 0 3f3f3f
10 35 0 3f3f3f
11 35 0 3f3f3f
12 35 0 3f3f3f
13 35 0 3f3f3f
14 35 0 3f3f3f
15 35 0 3f3f3f
0 36 0 3f3f3f
1 36 0 3f3f3f
2 36 0 3f3f3f
3 36 0 3f3f3f
4 36 0 3f3f3f
5 36 0 3f3f3f
6 36 0 3f3f3f
7 36 0 3f3f3f
8 36 0 3f3f3f
9 36 0 3f3f3f
10 36 0 3f3f3f
11 36 0 3f3f3f
12 36 0 3f3f3f
13 36 0 3f3f3f
14 36 0 3f3f3f
15 36 0 3f3f3f
0 37 0 3f3f3f
1 37 0 3f3f3f
2 37 0 3f3f3f
3 37 0 3f3f3f
4 37 0 3f3f3f
5 37 0 3f3f3f
6 37 0 3f3f3f
7 37 0 3f3f3f
8 37 0 3f3f3f
9 37 0 3f3f3f
10 37 0 3f3f3f
11 37 0 3f3f3f
12 37 0 3f3f3f
13 37 0 3f3f3f
14 37 0 3f3f3f
15 37 0 3f3f3f
0 38 0 3f3f3f
1 38 0 3f3f3f
2 38 0 3f3f3f
3 38 0 3f3f3f
4 38 0 3f3f3f
5 38 0 3f3f3f
6 38 0 3f3f3f
7 38 0 3f3f3f
8 38 0 3f3f3f
9 38 0 3f3f3f
10 38 0 3f3f3f
11 38 0 3f3f3f
12 38 0 3f3f3f
13 38 0 3f3f3f
14 38 0 3f3f3f
15 38 0 3f3f3f
0 39 0 3f3f3f
1 39 0 3f3f3f
2 39 0 3f3f3f
3 39 0 3f3f3f
4 39 0 3f3f3f
5 39 0 3f3f3f
6 39 0 3f3f3f
7 39 0 3f3f3f
8 39 0 3f3f3f
9 39 0 3f3f3f
10 39 0 3f3f3f
11 39 0 3f3f3f
12 39 0 3f3f3f
13 39 0 3f3f3f
14 39 0 3f3f3f
15 39 0 3f3f3f
0 40 0 3f3f3f
1 40 0 3f3f3f
2 40 0 3f3f3f
3 40 0 3f3f3f
4 40 0 3f3f3f
5 40 0 3f3f3f
6 40 0 3f3f3f
7 40 0 3f3f3f
8 40 0 3f3f3f
9 40 0 3f3f3f
10 40 0 3f3f3f
11 40 0 3f3f3f
12 40 0 3f3f3f
13 40 0 3f3f3f
14 40 0 3f3f3f
15 40 0 3f3f3f
0 41 0 3f3f3f
1 41 0 3f3f3f
2 41 0 3f3f3f
3 41 0 3f3f3f
4 41 0 3f3f3f
5 41 0 3f3f3f
6 41 0 3f3f3f
7 41 0 3f3f3f
8 41 0 3f3f3f
9 41 0 3f3f3f
10 41 0 3f3f3f
11 41 0 3f3f3f
12 41 0 3f3f3f
13 41 0 3f3f3f
14 41 0 3f3f3f
15 41 0 3f3f3f
0 42 0 3f3f3f
1 42 0 3f3f3f
2 42 0 3f3f3f
3 42 0 3f3f3f
4 42 0 3f3f3f
5 42 0 3f3f3f
6 42 0 3f3f3f
7 42 0 3f3f3f
8 42 0 3f3f3f
9 42 0 3f3f3f
10 42 0 3f3f3f
11 42 0 3f3f3f
12 42 0 3f3f3f
13 42 0 3f3f3f
14 42 0 3f3f3f
15 42 0 3f3f3f
0 43 0 3f3f3f
1 43 0 3f3f3f
2 43 0 3f3f3f
3 43 0 3f3f3f
4 43 0 3f3f3f
5 43 0 3f3f3f
6 43 0 3f3f3f
7 43 0 3f3f3f
8 43 0 3f3f3f
9 43 0 3f3f3f
10 43 0 3f3f3f
11 43 0 3f3f3f
12 43 0 3f3f3f
13 43 0 3f3f3f
14 43 0 3f3f3f
15 43 0 3f3f3f
0 44 0 3f3f3f
1 44 0 3f3f3f
2 44 0 3f3f3f
3 44 0 3f3f3f
4 44 0 3f3f3f
5 44 0 3f3f3f
6 44 0 3f3f3f
7 44 0 3f3f3f
8 44 0 3f3f3f
9 44 0 3f3f3f
10 44 0 3f3f3f
11 44 0 3f3f3f
12 44 0 3f3f3f
13 44 0 3f3f3f
14 44 0 3f3f3f
15 44 0 3f3f3f
0 45 0 3f3f3f
1 45 0 3f3f3f
2 45 0 3f3f3f
3 45 0 3f3f3f
4 45 0 3f3f3f
5 45 0 3f3f3f
6 45 0 3f3f3f
7 45 0 3f3f3f
8 45 0 3f3f3f
9 45 0 3f3f3f
10 45 0 3f3f3f
11 45 0 3f3f3f
12 45 0 3f3f3f
13 45 0 3f3f3f
14 45 0 3f3f3f
15 45 0 3f3f3f
0 46 0 3f3f3f
1 46 0 3f3f3f
2 46 0 3f3f3f
3 46 0 3f3f3f
4 46 0 3f3f3f
5 46 0 3f3f3f
6 46 0 3f3f3f
7 46 0 3f3f3f
8 46 0 3f3f3f
9 46 0 3f3f3f
10 46 0 3f3f3f
11 46 0 3f3f3f
12 46 0 3f3f3f
13 46 0 3f3f3f
14 46 0 3f3f3f
15 46 0 3f3f3f
0 47 0 3f3f3f
1 47 0 3f3f3f
2 47 0 3f3f3f
3 47 0 3f3f3f
4 47 0 3f3f3f
5 47 0 3f3f3f
6 47 0 3f3f3f
7 47 0 3f3f3f
8 47 0 3f3f3f
9 47 0 3f3f3f
10 47 0 3f3f3f
11 47 0 3f3f3f
12 47 0 3f3f3f
13 47 0 3f3f3f
14 47 0 3f3f3f
15 47 0 3f3f3f
0 32 1 3f3f3f
1 32 1 3f3f3f
2 32 1 3f3f3f
3 32 1 3f3f3f
4 32 1 3f3f3f
5 32 1 3f3f3f
6 32 1 3f3f3f
7 32 1 3f3f3f
8 32 1 3f3f3f
9 32 1 3f3f3f
10 32 1 3f3f3f
11 32 1 3f3f3f
12 32 1 3f3f3f
13 32 1 3f3f3f
14 32 1 3f3f3f
15 32 1 3f3f3f
0 33 1 3f3f3f
1 33 1 3f3f3f
2 33 1 3f3f3f
3 33 1 3f3f3f
4 33 1 3f3f3f
5 33 1 3f3f3f
6 33 1 3f3f3f
7 33 1 3f3f3f
8 33 1 3f3f3f
9 33 1 3f3f3f
10 33 1 3f3f3f
11 33 1 3f3f3f
12 33 1 3f3f3f
13 33 1 3f3f3f
14 33 1 3f3f3f
15 33 1 3f3f3f
0 34 1 3f3f3f
1 34 1 3f3f3f
2 34 1 3f3f3f
3 34 1 3f3f3f
4 34 1 3f3f3f
5 34 1 3f3f3f
6 34 1 3f3f3f
7 34 1 3f3f3f
8 34 1 3f3f3f
9 34 1 3f3f3f
10 34 1 3f3f3f
11 34 1 3f3f3f
12 34 1 3f3f3f
13 34 1 3f3f3f
14 34 1 3f3f3f
15 34 1 3f3f3f
0 35 1 3f3f3f
1 35 1 3f3f3f
2 35 1 3f3f3f
3 35 1 3f3f3f
4 35 1 3f3f3f
5 35 1 3f3f3f
6 35 1 3f3f3f
7 35 1 3f3f3f
8 35 1 3f3f3f
9 35 1 3f3f3f
10 35 1 3f3f3f
11 35 1 3f3f3f
12 35 1 3f3f3f
13 35 1 3f3f3f
14 35 1 3f3f3f
15 35 1 3f3f3f
0 36 1 3f3f3f
1 36 1 3f3f3f
2 36 1 3f3f3f
3 36 1 3f3f3f
4 36 1 3f3f3f
5 36 1 3f3f3f
6 36 1 3f3f3f
7 36 1 3f3f3f
8 36 1 3f3f3f
9 36 1 3f3f3f
10 36 1 3f3f3f
11 36 1 3f3f3f
12 36 1 3f3f3f
13 36 1 3f3f3f
14 36 1 3f3f3f
15 36 1 3f3f3f
0 37 1 3f3f3f
1 37 1 3f3f3f
2 37 1 3f3f3f
3 37 1 3f3f3f
4 37 1 3f3f3f
5 37 1 3f3f3f
6 37 1 3f3f3f
7 37 1 3f3f3f
8 37 1 3f3f3f
9 37 1 3f3f3f
10 37 1 3f3f3f
11 37 1 3f3f3f
12 37 1 3f3f3f
13 37 1 3f3f3f
14 37 1 3f3f3f
15 37 1 3f3f3f
0 38 1 3f3f3f
1 38 1 3f3f3f
2 38 1 3f3f3f
3 38 1 3f3f3f
4 38 1 3f3f3f
5 38 1 3f3f3f
6 38 1 3f3f3f
7 38 1 3f3f3f
8 38 1 3f3f3f
9 38 1 3f3f3f
10 38 1 3f3f3f
11 38 1 3f3f3f
12 38 1 3f3f3f
13 38 1 3f3f3f
14 38 1 3f3f3f
15 38 1 3f3f3f
0 39 1 3f3f3f
1 39 1 3f3f3f
2 39 1 3f3f3f
3 39 1 3f3f3f
4 39 1 3f3f3f
5 39 1 3f3f3f
6 39 1 3f3f3f
7 39 1 3f3f3f
8 39 1 3f3f3f
9 39 1 3f3f3f
10 39 1 3f3f3f
11 39 1 3f3f3f
12 39 1 3f3f3f
13 39 1 3f3f3f
14 39 1 3f3f3f
15 39 1 3f3f3f
0 40 1 3f3f3f
1 40 1 3f3f3f
2 40 1 3f3f3f
3 40 1 3f3f3f
4 40 1 3f3f3f
5 40 1 3f3f3f
6 40 1 3f3f3f
7 40 1 3f3f3f
8 40 1 3f3f3f
9 40 1 3f3f3f
10 40 1 3f3f3f
11 40 1 3f3f3f
12 40 1 3f3f3f
13 40 1 3f3f3f
14 40 1 3f3f3f
15 40 1 3f3f3f
0 41 1 3f3f3f
1 41 1 3f3f3f
2 41 1 3f3f3f
3 41 1 3f3f3f
4 41 1 3f3f3f
5 41 1 3f3f3f
6 41 1 3f3f3f
7 41 1 3f3f3f
8 41 1 3f3f3f
9 41 1 3f3f3f
10 41 1 3f3f3f
11 41 1 3f3f3f
12 41 1 3f3f3f
13 41 1 3f3f3f
14 41 1 3f3f3f
15 41 1 3f3f3f
0 42 1 3f3f3f
1 42 1 3f3f3f
2 42 1 3f3f3f
3 42 1 3f3f3f
4 42 1 3f3f3f
5 42 1 3f3f3f
6 42 1 3f3f3f
7 42 1 3f3f3f
8 42 1 3f3f3f
9 42 1 3f3f3f
10 42 1 3f3f3f
11 42 1 3f3f3f
12 42 1 3f3f3f
13 42 1 3f3f3f
14 42 1 3f3f3f
15 42 1 3f3f3f
0 43 1 3f3f3f
1 43 1 3f3f3f
2 43 1 3f3f3f
3 43 1 3f3f3f
4 43 1 3f3f3f
5 43 1 3f3f3f
6 43 1 3f3f3f
7 43 1 3f3f3f
8 43 1 3f3f3f
9 43 1 3f3f3f
10 43 1 3f3f3f
11 43 1 3f3f3f
12 43 1 3f3f3f
13 43 1 3f3f3f
14 43 1 3f3f3f
15 43 1 3f3f3f
0 44 1 3f3f3f
1 44 1 3f3f3f
2 44 1 3f3f3f
3 44 1 3f3f3f
4 44 1 3f3f3f
5 44 1 3f3f3f
6 44 1 3f3f3f
7 44 1 3f3f3f
8 44 1 3f3f3f
9 44 1 3f3f3f
10 44 1 3f3f3f
11 44 1 3f3f3f
12 44 1 3f3f3f
13 44 1 3f3f3f
14 44 1 3f3f3f
15 44 1 3f3f3f
0 45 1 3f3f3f
1 45 1 3f3f3f
2 45 1 3f3f3f
3 45 1 3f3f3f
4 45 1 3f3f3f
5 45 1 3f3f3f
6 45 1 3f3f3f
7 45 1 3f3f3f
8 45 1 3f3f3f
9 45 1 3f3f3f
10 45 1 3f3f3f
11 45 1 3f3f3f
12 45 1 3f3f3f
13 45 1 3f3f3f
14 45 1 3f3f3f
15 45 1 3f3f3f
0 46 1 3f3f3f
1 46 1 3f3f3f
2 46 1 3f3f3f
3 46 1 3f3f3f
4 46 1 3f3f3f
5 46 1 3f3f3f
6 46 1 3f3f3f
7 46 1 3f3f3f
8 46 1 3f3f3f
9 46 1 3f3f3f
10 46 1 3f3f3f
11 46 1 3f3f3f
12 46 1 3f3f3f
13 46 1 3f3f3f
14 46 1 3f3f3f
15 46 1 3f3f3f
0 47 1 3f3f3f
1 47 1 3f3f3f
2 47 1 3f3f3f
3 47 1 3f3f3f
4 47 1 3f3f3f
5 47 1 3f3f3f
6 47 1 3f3f3f
7 47 1 3f3f3f
8 47 1 3f3f3f
9 47 1 3f3f3f
10 47 1 3f3f3f
11 47 1 3f3f3f
12 47 1 3f3f3f
13 47 1 3f3f3f
14 47 1 3f3f3f
15 47 1 3f3f3f
0 32 2 7f7f7f
1 32 2 7f7f7f
2 32 2 7f7f7f
3 32 2 7f7f7f
4 32 2 7f7f7f
5 32 2 7f7f7f
6 32 2 7f7f7f
7 32 2 7f7f7f
8 32 2 7f7f7f
9 32 2 7f7f7f
10 32 2 7f7f7f
11 32 2 7f7f7f
12 32 2 7f7f7f
13 32 2 7f7f7f
14 32 2 7f7f7f
15 32 2 7f7f7f
0 33 2 7f7f7f
1 33 2 7f7f7f
2 33 2 7f7f7f
3 33 2 7f7f7f
4 33 2 7f7f7f
5 33 2 7f7f7f
6 33 2 7f7f7f
7 33 2 7f7f7f
8 33 2 7f7f7f
9 33 2 7f7f7f
10 33 2 7f7f7f
11 33 2 7f7f7f
12 33 2 7f7f7f
13 33 2 7f7f7f
14 33 2 7f7f7f
15 33 2 7f7f7f
0 34 2 7f7f7f
1 34 2 7f7f7f
2 34 2 7f7f7f
3 34 2 7f7f7f
4 34 2 7f7f7f
5 34 2 7f7f7f
6 34 2 7f7f7f
7 34 2 7f7f7f
8 34 2 7f7f7f
9 34 2 7f7f7f
10 34 2 7f7f7f
11 34 2 7f7f7f
12 34 2 7f7f7f
13 34 2 7f7f7f
14 34 2 7f7f7f
15 34 2 7f7f7f
0 35 2 7f7f7f
1 35 2 7f7f7f
2 35 2 7f7f7f
3 35 2 7f7f7f
4 35 2 7f7f7f
5 35 2 7f7f7f
6 35 2 7f7f7f
7 35 2 7f7f7f
8 35 2 7f7f7f
9 35 2 7f7f7f
10 35 2 7f7f7f
11 35 2 7f7f7f
12 35 2 7f7f7f
13 35 2 7f7f7f
14 35 2 7f7f7f
15 35 2 7f7f7f
0 36 2 7f7f7f
1 36 2 7f7f7f
2 36 2 7f7f7f
3 36 2 7f7f7f
4 36 2 7f7f7f
5 36 2 7f7f7f
6 36 2 7f7f7f
7 36 2 7f7f7f
8 36 2 7f7f7f
9 36 2 7f7f7f
10 36 2 7f7f7f
11 36 2 7f7f7f
12 36 2 7f7f7f
13 36 2 7f7f7f
14 36 2 7f7f7f
15 36 2 7f7f7f
0 37 2 7f7f7f
1 37 2 7f7f7f
2 37 2 7f7f7f
3 37 2 7f7f7f
4 37 2 7f7f7f
5 37 2 7f7f7f
6 37 2 7f7f7f
7 37 2 7f7f7f
8 37 2 7f7f7f
9 37 2 7f7f7f
10 37 2 7f7f7f
11 37 2 7f7f7f
12 37 2 7f7f7f
13 37 2 7f7f7f
14 37 2 7f7f7f
15 37 2 7f7f7f
0 38 2 7f7f7f
1 38 2 7f7f7f
2 38 2 7f7f7f
3 38 2 7f7f7f
4 38 2 7f7f7f
5 38 2 7f7f7f
6 38 2 7f7f7f
7 38 2 7f7f7f
8 38 2 7f7f7f
9 38 2 7f7f7f
10 38 2 7f7f7f
11 38 2 7f7f7f
12 38 2 7f7f7f
13 38 2 7f7f7f
14 38 2 7f7f7f
15 38 2 7f7f7f
0 39 2 7f7f7f
1 39 2 7f7f7f
2 39 2 7f7f7f
3 39 2 7f7f7f
4 39 2 7f7f7f
5 39 2 7f7f7f
6 39 2 7f7f7f
7 39 2 7f7f7f
8 39 2 7f7f7f
9 39 2 7f7f7f
10 39 2 7f7f7f
11 39 2 7f7f7f
12 39 2 7f7f7f
13 39 2 7f7f7f
14 39 2 7f7f7f
15 39 2 7f7f7f
0 40 2 7f7f7f
1 40 2 7f7f7f
2 40 2 7f7f7f
3 40 2 7f7f7f
4 40 2 7f7f7f
5 40 2 7f7f7f
6 40 2 7f7f7f
7 40 2 7f7f7f
8 40 2 7f7f7f
9 40 2 7f7f7f
10 40 2 7f7f7f
11 40 2 7f7f7f
12 40 2 7f7f7f
13 40 2 7f7f7f
14 40 2 7f7f7f
15 40 2 7f7f7f
0 41 2 7f7f7f
1 41 2 7f7f7f
2 41 2 7f7f7f
3 41 2 7f7f7f
4 41 2 7f7f7f
5 41 2 7f7f7f
6 41 2 7f7f7f
7 41 2 7f7f7f
8 41 2 7f7f7f
9 41 2 7f7f7f
10 41 2 7f7f7f
11 41 2 7f7f7f
12 41 2 7f7f7f
13 41 2 7f7f7f
14 41 2 7f7f7f
15 41 2 7f7f7f
0 42 2 7f7f7f
1 42 2 7f7f7f
2 42 2 7f7f7f
3 42 2 7f7f7f
4 42 2 7f7f7f
5 42 2 7f7f7f
6 42 2 7f7f7f
7 42 2 7f7f7f
8 42 2 7f7f7f
9 42 2 7f7f7f
10 42 2 7f7f7f
11 42 2 7f7f7f
12 42 2 7f7f7f
13 42 2 7f7f7f
14 42 2 7f7f7f
15 42 2 7f7f7f
0 43 2 7f7f7f
1 43 2 7f7f7f
2 43 2 7f7f7f
3 43 2 7f7f7f
4 43 2 7f7f7f
5 43 2 7f7f7f
6 43 2 7f7f7f
7 43 2 7f7f7f
8 43 2 7f7f7f
9 43 2 7f7f7f
10 43 2 7f7f7f
11 43 2 7f7f7f
12 43 2 7f7f7f
13 43 2 7f7f7f
14 43 2 7f7f7f
15 43 2 7f7f7f
0 44 2 7f7f7f
1 44 2 7f7f7f
2 44 2 7f7f7f
3 44 2 7f7f7f
4 44 2 7f7f7f
5 44 2 7f7f7f
6 44 2 7f7f7f
7 44 2 7f7f7f
8 44 2 7f7f7f
9 44 2 7f7f7f
10 44 2 7f7f7f
11 44 2 7f7f7f
12 44 2 7f7f7f
13 44 2 7f7f7f
14 44 2 7f7f7f
15 44 2 7f7f7f
0 45 2 7f7f7f
1 45 2 7f7f7f
2 45 2 7f7f7f
3 45 2 7f7f7f
4 45 2 7f7f7f
5 45 2 7f7f7f
6 45 2 7f7f7f
7 45 2 7f7f7f
8 45 2 7f7f7f
9 45 2 7f7f7f
10 45 2 7f7f7f
11 45 2 7f7f7f
12 45 2 7f7f7f
13 45 2 7f7f7f
14 45 2 7f7f7f
15 45 2 7f7f7f
0 46 2 7f7f7f
1 46 2 7f7f7f
2 46 2 7f7f7f
3 46 2 7f7f7f
4 46 2 7f7f7f
5 46 2 7f7f7f
6 46 2 7f7f7f
7 46 2 7f7f7f
8 46 2 7f7f7f
9 46 2 7f7f7f
10 46 2 7f7f7f
11 46 2 7f7f7f
12 46 2 7f7f7f
13 46 2 7f7f7f
14 46 2 7f7f7f
15 46 2 7f7f7f
0 47 2 7f7f7f
1 47 2 7f7f7f
2 47 2 7f7f7f
3 47 2 7f7f7f
4 47 2 7f7f7f
5 47 2 7f7f7f
6 47 2 7f7f7f
7 47 2 7f7f7f
8 47 2 7f7f7f
9 47 2 7f7f7f
10 47 2 7f7f7f
11 47 2 7f7f7f
12 47 2 7f7f7f
13 47 2 7f7f7f
14 47 2 7f7f7f
15 47 2 7f7f7f
0 32 3 7f7f7f
1 32 3 7f7f7f
2 32 3 7f7f7f
3 32 3 7f7f7f
4 32 3 7f7f7f
5 32 3 7f7f7f
6 32 3 7f7f7f
7 32 3 7f7f7f
8 32 3 7f7f7f
9 32 3 7f7f7f
10 32 3 7f7f7f
11 32 3 7f7f7f
12 32 3 7f7f7f
13 32 3 7f7f7f
14 32 3 7f7f7f
15 32 3 7f7f7f
0 33 3 7f7f7f
1 33 3 7f7f7f
2 33 3 7f7f7f
3 33 3 7f7f7f
4 33 3 7f7f7f
5 33 3 7f7f7f
6 33 3 7f7f7f
7 33 3 7f7f7f
8 33 3 7f7f7f
9 33 3 7f7f7f
10 33 3 7f7f7f
11 33 3 7f7f7f
12 33 3 7f7f7f
13 33 3 7f7f7f
14 33 3 7f7f7f
15 33 3 7f7f7f
0 34 3 7f7f7f
1 34 3 7f7f7f
2 34 3 7f7f7f
3 34 3 7f7f7f
4 34 3 7f7f7f
5 34 3 7f7f7f
6 34 3 7f7f7f
7 34 3 7f7f7f
8 34 3 7f7f7f
9 34 3 7f7f7f
10 34 3 7f7f7f
11 34 3 7f7f7f
12 34 3 7f7f7f
13 34 3 7f7f7f
14 34 3 7f7f7f
15 34 3 7f7f7f
0 35 3 7f7f7f
1 35 3 7f7f7f
2 35 3 7f7f7f
3 35 3 7f7f7f
4 35 3 7f7f7f
5 35 3 7f7f7f
6 35 3 7f7f7f
7 35 3 7f7f7f
8 35 3 7f7f7f
9 35 3 7f7f7f
10 35 3 7f7f7f
11 35 3 7f7f7f
12 35 3 7f7f7f
13 35 3 7f7f7f
14 35 3 7f7f7f
15 35 3 7f7f7f
0 36 3 7f7f7f
1 36 3 7f7f7f
2 36 3 7f7f7f
3 36 3 7f7f7f
4 36 3 7f7f7f
5 36 3 7f7f7f
6 36 3 7f7f7f
7 36 3 7f7f7f
8 36 3 7f7f7f
9 36 3 7f7f7f
10 36 3 7f7f7f
11 36 3 7f7f7f
12 36 3 7f7f7f
13 36 3 7f7f7f
14 36 3 7f7f7f
15 36 3 7f7f7f
0 37 3 7f7f7f
1 37 3 7f7f7f
2 37 3 7f7f7f
3 37 3 7f7f7f
4 37 3 7f7f7f
5 37 3 7f7f7f
6 37 3 7f7f7f
7 37 3 7f7f7f
8 37 3 7f7f7f
9 37 3 7f7f7f
10 37 3 7f7f7f
11 37 3 7f7f7f
12 37 3 7f7f7f
13 37 3 7f7f7f
14 37 3 7f7f7f
15 37 3 7f7f7f
0 38 3 7f7f7f
1 38 3 7f7f7f
2 38 3 7f7f7f
3 38 3 7f7f7f
4 38 3 7f7f7f
5 38 3 7f7f7f
6 38 3 7f7f7f
7 38 3 7f7f7f
8 38 3 7f7f7f
9 38 3 7f7f7f
10 38 3 7f7f7f
11 38 3 7f7f7f
12 38 3 7f7f7f
13 38 3 7f7f7f
14 38 3 7f7f7f
15 38 3 7f7f7f
0 39 3 7f7f7f
1 39 3 7f7f7f
2 39 3 7f7f7f
3 39 3 7f7f7f
4 39 3 7f7f7f
5 39 3 7f7f7f
6 39 3 7f7f7f
7 39 3 7f7f7f
8 39 3 7f7f7f
9 39 3 7f7f7f
10 39 3 7f7f7f
11 39 3 7f7f7f
12 39 3 7f7f7f
13 39 3 7f7f7f
14 39 3 7f7f7f
15 39 3 7f7f7f
0 40 3 7f7f7f
1 40 3 7f7f7f
2 40 3 7f7f7f
3 40 3 7f7f7f
4 40 3 7f7f7f
5 40 3 7f7f7f
6 40 3 7f7f7f
7 40 3 7f7f7f
8 40 3 7f7f7f
9 40 3 7f7f7f
10 40 3 7f7f7f
11 40 3 7f7f7f
12 40 3 7f7f7f
13 40 3 7f7f7f
14 40 3 7f7f7f
15 40 3 7f7f7f
0 41 3 7f7f7f
1 41 3 7f7f7f
2 41 3 7f7f7f
3 41 3 7f7f7f
4 41 3 7f7f7f
5 41 3 7f7f7f
6 41 3 7f7f7f
7 41 3 7f7f7f
8 41 3 7f7f7f
9 41 3 7f7f7f
10 41 3 7f7f7f
11 41 3 7f7f7f
12 41 3 7f7f7f
13 41 3 7f7f7f
14 41 3 7f7f7f
15 41 3 7f7f7f
0 42 3 7f7f7f
1 42 3 7f7f7f
2 42 3 7f7f7f
3 42 3 7f7f7f
4 42 3 7f7f7f
5 42 3 7f7f7f
6 42 3 7f7f7f
7 42 3 7f7f7f
8 42 3 7f7f7f
9 42 3 7f7f7f
10 42 3 7f7f7f
11 42 3 7f7f7f
12 42 3 7f7f7f
13 42 3 7f7f7f
14 42 3 7f7f7f
15 42 3 7f7f7f
0 43 3 7f7f7f
1 43 3 7f7f7f
2 43 3 7f7f7f
3 43 3 7f7f7f
4 43 3 7f7f7f
5 43 3 7f7f7f
6 43 3 7f7f7f
7 43 3 7f7f7f
8 43 3 7f7f7f
9 43 3 7f7f7f
10 43 3 7f7f7f
11 43 3 7f7f7f
12 43 3 7f7f7f
13 43 3 7f7f7f
14 43 3 7f7f7f
15 43 3 7f7f7f
0 44 3 7f7f7f
1 44 3 7f7f7f
2 44 3 7f7f7f
3 44 3 7f7f7f
4 44 3 7f7f7f
5 44 3 7f7f7f
6 44 3 7f7f7f
7 44 3 7f7f7f
8 44 3 7f7f7f
9 44 3 7f7f7f
10 44 3 7f7f7f
11 44 3 7f7f7f
12 44 3 7f7f7f
13 44 3 7f7f7f
14 44 3 7f7f7f
15 44 3 7f7f7f
0 45 3 7f7f7f
1 45 3 7f7f7f
2 45 3 7f7f7f
3 45 3 7f7f7f
4 45 3 7f7f7f
5 45 3 7f7f7f
6 45 3 7f7f7f
7 45 3 7f7f7f
8 45 3 7f7f7f
9 45 3 7f7f7f
10 45 3 7f7f7f
11 45 3 7f7f7f
12 45 3 7f7f7f
13 45 3 7f7f7f
14 45 3 7f7f7f
15 45 3 7f7f7f
0 46 3 7f7f7f
1 46 3 7f7f7f
2 46 3 7f7f7f
3 46 3 7f7f7f
4 46 3 7f7f7f
5 46 3 7f7f7f
6 46 3 7f7f7f
7 46 3 7f7f7f
8 46 3 7f7f7f
9 46 3 7f7f7f
10 46 3 7f7f7f
11 46 3 7f7f7f
12 46 3 7f7f7f
13 46 3 7f7f7f
14 46 3 7f7f7f
15 46 3 7f7f7f
0 47 3 7f7f7f
1 47 3 7f7f7f
2 47 3 7f7f7f
3 47 3 7f7f7f
4 47 3 7f7f7f
5 47 3 7f7f7f
6 47 3 7f7f7f
7 47 3 7f7f7f
8 47 3 7f7f7f
9 47 3 7f7f7f
10 47 3 7f7f7f
11 47 3 7f7f7f
12 47 3 7f7f7f
13 47 3 7f7f7f
14 47 3 7f7f7f
15 47 3 7f7f7f
0 32 4 7f7f7f
1 32 4 7f7f7f
2 32 4 7f7f7f
3 32 4 7f7f7f
4 32 4 7f7f7f
5 32 4 7f7f7f
6 32 4 7f7f7f
7 32 4 7f7f7f
8 32 4 7f7f7f
9 32 4 7f7f7f
10 32 4 7f7f7f
11 32 4 7f7f7f
12 32 4 7f7f7f
13 32 4 7f7f7f
14 32 4 7f7f7f
15 32 4 7f7f7f
0 33 4 7f7f7f
1 33 4 7f7f7f
2 33 4 7f7f7f
3 33 4 7f7f7f
4 33 4 7f7f7f
5 33 4 7f7f7f
6 33 4 7f7f7f
7 33 4 7f7f7f
8 33 4 7f7f7f
9 33 4 7f7f7f
10 33 4 7f7f7f
11 33 4 7f7f7f
12 33 4 7f7f7f
13 33 4 7f7f7f
14 33 4 7f7f7f
15 33 4 7f7f7f
0 34 4 7f7f7f
1 34 4 7f7f7f
2 34 4 7f7f7f
3 34 4 7f7f7f
4 34 4 7f7f7f
5 34 4 7f7f7f
6 34 4 7f7f7f
7 34 4 7f7f7f
8 34 4 7f7f7f
9 34 4 7f7f7f
10 34 4 7f7f7f
11 34 4 7f7f7f
12 34 4 7f7f7f
13 34 4 7f7f7f
14 34 4 7f7f7f
15 34 4 7f7f7f
0 35 4 7f7f7f
1 35 4 7f7f7f
2 35 4 7f7f7f
3 35 4 7f7f7f
4 35 4 7f7f7f
5 35 4 7f7f7f
6 35 4 7f7f7f
7 35 4 7f7f7f
8 35 4 7f7f7f
9 35 4 7f7f7f
10 35 4 7f7f7f
11 35 4 7f7f7f
12 35 4 7f7f7f
13 35 4 7f7f7f
14 35 4 7f7f7f
15 35 4 7f7f7f
0 36 4 7f7f7f
1 36 4 7f7f7f
2 36 4 7f7f7f
3 36 4 7f7f7f
4 36 4 7f7f7f
5 36 4 7f7f7f
6 36 4 7f7f7f
7 36 4 7f7f7f
8 36 4 7f7f7f
9 36 4 7f7f7f
10 36 4 7f7f7f
11 36 4 7f7f7f
12 36 4 7f7f7f
13 36 4 7f7f7f
14 36 4 7f7f7f
15 36 4 7f7f7f
0 37 4 7f7f7f
1 37 4 7f7f7f
2 37 4 7f7f7f
3 37 4 7f7f7f
4 37 4 7f7f7f
5 37 4 7f7f7f
6 37 4 7f7f7f
7 37 4 7f7f7f
8 37 4 7f7f7f
9 37 4 7f7f7f
10 37 4 7f7f7f
11 37 4 7f7f7f
12 37 4 7f7f7f
13 37 4 7f7f7f
14 37 4 7f7f7f
15 37 4 7f7f7f
0 38 4 7f7f7f
1 38 4 7f7f7f
2 38 4 7f7f7f
3 38 4 7f7f7f
4 38 4 7f7f7f
5 38 4 7f7f7f
6 38 4 7f7f7f
7 38 4 7f7f7f
8 38 4 7f7f7f
9 38 4 7f7f7f
10 38 4 7f7f7f
11 38 4 7f7f7f
12 38 4 7f7f7f
13 38 4 7f7f7f
14 38 4 7f7f7f
15 38 4 7f7f7f
0 39 4 7f7f7f
1 39 4 7f7f7f
2 39 4 7f7f7f
3 39 4 7f7f7f
4 39 4 7f7f7f
5 39 4 7f7f7f
6 39 4 7f7f7f
7 39 4 7f7f7f
8 39 4 7f7f7f
9 39 4 7f7f7f
10 39 4 7f7f7f
11 39 4 7f7f7f
12 39 4 7f7f7f
13 39 4 7f7f7f
14 39 4 7f7f7f
15 39 4 7f7f7f
0 40 4 7f7f7f
1 40 4 7f7f7f
2 40 4 7f7f7f
3 40 4 7f7f7f
4 40 4 7f7f7f
5 40 4 7f7f7f
6 40 4 7f7f7f
7 40 4 7f7f7f
8 40 4 7f7f7f
9 40 4 7f7f7f
10 40 4 7f7f7f
11 40 4 7f7f7f
12 40 4 7f7f7f
13 40 4 7f7f7f
14 40 4 7f7f7f
15 40 4 7f7f7f
0 41 4 7f7f7f
1 41 4 7f7f7f
2 41 4 7f7f7f
3 41 4 7f7f7f
4 41 4 7f7f7f
5 41 4 7f7f7f
6 41 4 7f7f7f
7 41 4 7f7f7f
8 41 4 7f7f7f
9 41 4 7f7f7f
10 41 4 7f7f7f
11 41 4 7f7f7f
12 41 4 7f7f7f
13 41 4 7f7f7f
14 41 4 7f7f7f
15 41 4 7f7f7f
0 42 4 7f7f7f
1 42 4 7f7f7f
2 42 4 7f7f7f
3 42 4 7f7f7f
4 42 4 7f7f7f
5 42 4 7f7f7f
6 42 4 7f7f7f
7 42 4 7f7f7f
8 42 4 7f7f7f
9 42 4 7f7f7f
10 42 4 7f7f7f
11 42 4 7f7f7f
12 42 4 7f7f7f
13 42 4 7f7f7f
14 42 4 7f7f7f
15 42 4 7f7f7f
0 43 4 7f7f7f
1 43 4 7f7f7f
2 43 4 7f7f7f
3 43 4 7f7f7f
4 43 4 7f7f7f
5 43 4 7f7f7f
6 43 4 7f7f7f
7 43 4 7f7f7f
8 43 4 7f7f7f
9 43 4 7f7f7f
10 43 4 7f7f7f
11 43 4 7f7f7f
12 43 4 7f7f7f
13 43 4 7f7f7f
14 43 4 7f7f7f
15 43 4 7f7f7f
0 44 4 7f7f7f
1 44 4 7f7f7f
2 44 4 7f7f7f
3 44 4 7f7f7f
4 44 4 7f7f7f
5 44 4 7f7f7f
6 44 4 7f7f7f
7 44 4 7f7f7f
8 44 4 7f7f7f
9 44 4 7f7f7f
10 44 4 7f7f7f
11 44 4 7f7f7f
12 44 4 7f7f7f
13 44 4 7f7f7f
14 44 4 7f7f7f
15 44 4 7f7f7f
0 45 4 7f7f7f
1 45 4 7f7f7f
2 45 4 7f7f7f
3 45 4 7f7f7f
4 45 4 7f7f7f
5 45 4 7f7f7f
6 45 4 7f7f7f
7 45 4 7f7f7f
8 45 4 7f7f7f
9 45 4 7f7f7f
10 45 4 7f7f7f
11 45 4 7f7f7f
12 45 4 7f7f7f
13 45 4 7f7f7f
14 45 4 7f7f7f
15 45 4 7f7f7f
0 46 4 7f7f7f
1 46 4 7f7f7f
2 46 4 7f7f7f
3 46 4 7f7f7f
4 46 4 7f7f7f
5 46 4 7f7f7f
6 46 4 7f7f7f
7 46 4 7f7f7f
8 46 4 7f7f7f
9 46 4 7f7f7f
10 46 4 7f7f7f
11 46 4 7f7f7f
12 46 4 7f7f7f
13 46 4 7f7f7f
14 46 4 7f7f7f
15 46 4 7f7f7f
0 47 4 7f7f7f
1 47 4 7f7f7f
2 47 4 7f7f7f
3 47 4 7f7f7f
4 47 4 7f7f7f
5 47 4 7f7f7f
6 47 4 7f7f7f
7 47 4 7f7f7f
8 47 4 7f7f7f
9 47 4 7f7f7f
10 47 4 7f7f7f
11 47 4 7f7f7f
12 47 4 7f7f7f
13 47 4 7f7f7f
14 47 4 7f7f7f
15 47 4 7f7f7f
0 32 5 7f7f7f
1 32 5 7f7f7f
2 32 5 7f7f7f
3 32 5 7f7f7f
4 32 5 7f7f7f
5 32 5 7f7f7f
6 32 5 7f7f7f
7 32 5 7f7f7f
8 32 5 7f7f7f
9 32 5 7f7f7f
10 32 5 7f7f7f
11 32 5 7f7f7f
12 32 5 7f7f7f
13 32 5 7f7f7f
14 32 5 7f7f7f
15 32 5 7f7f7f
0 33 5 7f7f7f
1 33 5 7f7f7f
2 33 5 7f7f7f
3 33 5 7f7f7f
4 33 5 7f7f7f
5 33 5 7f7f7f
6 33 5 7f7f7f
7 33 5 7f7f7f
8 33 5 7f7f7f
9 33 5 7f7f7f
10 33 5 7f7f7f
11 33 5 7f7f7f
12 33 5 7f7f7f
13 33 5 7f7f7f
14 33 5 7f7f7f
15 33 5 7f7f7f
0 34 5 7f7f7f
1 34 5 7f7f7f
2 34 5 7f7f7f
3 34 5 7f7f7f
4 34 5 7f7f7f
5 34 5 7f7f7f
6 34 5 7f7f7f
7 34 5 7f7f7f
8 34 5 7f7f7f
9 34 5 7f7f7f
10 34 5 7f7f7f
11 34 5 7f7f7f
12 34 5 7f7f7f
13 34 5 7f7f7f
14 34 5 7f7f7f
15 34 5 7f7f7f
0 35 5 7f7f7f
1 35 5 7f7f7f
2 35 5 7f7f7f
3 35 5 7f7f7f
4 35 5 7f7f7f
5 35 5 7f7f7f
6 35 5 7f7f7f
7 35 5 7f7f7f
8 35 5 7f7f7f
9 35 5 7f7f7f
10 35 5 7f7f7f
11 35 5 7f7f7f
12 35 5 7f7f7f
13 35 5 7f7f7f
14 35 5 7f7f7f
15 35 5 7f7f7f
0 36 5 7f7f7f
1 36 5 7f7f7f
2 36 5 7f7f7f
3 36 5 7f7f7f
4 36 5 7f7f7f
5 36 5 7f7f7f
6 36 5 7f7f7f
7 36 5 7f7f7f
8 36 5 7f7f7f
9 36 5 7f7f7f
10 36 5 7f7f7f
11 36 5 7f7f7f
12 36 5 7f7f7f
13 36 5 7f7f7f
14 36 5 7f7f7f
15 36 5 7f7f7f
0 37 5 7f7f7f
1 37 5 7f7f7f
2 37 5 7f7f7f
3 37 5 7f7f7f
4 37 5 7f7f7f
5 37 5 7f7f7f
6 37 5 7f7f7f
7 37 5 7f7f7f
8 37 5 7f7f7f
9 37 5 7f7f7f
10 37 5 7f7f7f
11 37 5 7f7f7f
12 37 5 7f7f7f
13 37 5 7f7f7f
14 37 5 7f7f7f
15 37 5 7f7f7f
0 38 5 7f7f7f
1 38 5 7f7f7f
2 38 5 7f7f7f
3 38 5 7f7f7f
4 38 5 7f7f7f
5 38 5 7f7f7f
6 38 5 7f7f7f
7 38 5 7f7f7f
8 38 5 7f7f7f
9 38 5 7f7f7f
10 38 5 7f7f7f
11 38 5 7f7f7f
12 38 5 7f7f7f
13 38 5 7f7f7f
14 38 5 7f7f7f
15 38 5 7f7f7f
0 39 5 7f7f7f
1 39 5 7f7f7f
2 39 5 7f7f7f
3 39 5 7f7f7f
4 39 5 7f7f7f
5 39 5 7f7f7f
6 39 5 7f7f7f
7 39 5 7f7f7f
8 39 5 7f7f7f
9 39 5 7f7f7f
10 39 5 7f7f7f
11 39 5 7f7f7f
12 39 5 7f7f7f
13 39 5 7f7f7f
14 39 5 7f7f7f
15 39 5 7f7f7f
0 40 5 7f7f7f
1 40 5 7f7f7f
2 40 5 7f7f7f
3 40 5 7f7f7f
4 40 5 7f7f7f
5 40 5 7f7f7f
6 40 5 7f7f7f
7 40 5 7f7f7f
8 40 5 7f7f7f
9 40 5 7f7f7f
10 40 5 7f7f7f
11 40 5 7f7f7f
12 40 5 7f7f7f
13 40 5 7f7f7f
14 40 5 7f7f7f
15 40 5 7f7f7f
0 41 5 7f7f7f
1 41 5 7f7f7f
2 41 5 7f7f7f
3 41 5 7f7f7f
4 41 5 7f7f7f
5 41 5 7f7f7f
6 41 5 7f7f7f
7 41 5 7f7f7f
8 41 5 7f7f7f
9 41 5 7f7f7f
10 41 5 7f7f7f
11 41 5 7f7f7f
12 41 5 7f7f7f
13 41 5 7f7f7f
14 41 5 7f7f7f
15 41 5 7f7f7f
0 42 5 7f7f7f
1 42 5 7f7f7f
2 42 5 7f7f7f
3 42 5 7f7f7f
4 42 5 7f7f7f
5 42 5 7f7f7f
6 42 5 7f7f7f
7 42 5 7f7f7f
8 42 5 7f7f7f
9 42 5 7f7f7f
10 42 5 7f7f7f
11 42 5 7f7f7f
12 42 5 7f7f7f
13 42 5 7f7f7f
14 42 5 7f7f7f
15 42 5 7f7f7f
0 43 5 7f7f7f
1 43 5 7f7f7f
2 43 5 7f7f7f
3 43 5 7f7f7f
4 43 5 7f7f7f
5 43 5 7f7f7f
6 43 5 7f7f7f
7 43 5 7f7f7f
8 43 5 7f7f7f
9 43 5 7f7f7f
10 43 5 7f7f7f
11 43 5 7f7f7f
12 43 5 7f7f7f
13 43 5 7f7f7f
14 43 5 7f7f7f
15 43 5 7f7f7f
0 44 5 7f7f7f
1 44 5 7f7f7f
2 44 5 7f7f7f
3 44 5 7f7f7f
4 44 5 7f7f7f
5 44 5 7f7f7f
6 44 5 7f7f7f
7 44 5 7f7f7f
8 44 5 7f7f7f
9 44 5 7f7f7f
10 44 5 7f7f7f
11 44 5 7f7f7f
12 44 5 7f7f7f
13 44 5 7f7f7f
14 44 5 7f7f7f
15 44 5 7f7f7f
0 45 5 7f7f7f
1 45 5 7f7f7f
2 45 5 7f7f7f
3 45 5 7f7f7f
4 45 5 7f7f7f
5 45 5 7f7f7f
6 45 5 7f7f7f
7 45 5 7f7f7f
8 45 5 7f7f7f
9 45 5 7f7f7f
10 45 5 7f7f7f
11 45 5 7f7f7f
12 45 5 7f7f7f
13 45 5 7f7f7f
14 45 5 7f7f7f
15 45 5 7f7f7f
0 46 5 7f7f7f
1 46 5 7f7f7f
2 46 5 7f7f7f
3 46 5 7f7f7f
4 46 5 7f7f7f
5 46 5 7f7f7f
6 46 5 7f7f7f
7 46 5 7f7f7f
8 46 5 7f7f7f
9 46 5 7f7f7f
10 46 5 7f7f7f
11 46 5 7f7f7f
12 46 5 7f7f7f
13 46 5 7f7f7f
14 46 5 7f7f7f
15 46 5 7f7f7f
0 47 5 7f7f7f
1 47 5 7f7f7f
2 47 5 7f7f7f
3 47 5 7f7f7f
4 47 5 7f7f7f
5 47 5 7f7f7f
6 47 5 7f7f7f
7 47 5 7f7f7f
8 47 5 7f7f7f
9 47 5 7f7f7f
10 47 5 7f7f7f
11 47 5 7f7f7f
12 47 5 7f7f7f
13 47 5 7f7f7f
14 47 5 7f7f7f
15 47 5 7f7f7f
0 32 6 7f7f7f
1 32 6 7f7f7f
2 32 6 7f7f7f
3 32 6 7f7f7f
4 32 6 7f7f7f
5 32 6 7f7f7f
6 32 6 7f7f7f
7 32 6 7f7f7f
8 32 6 7f7f7f
9 32 6 7f7f7f
10 32 6 7f7f7f
11 32 6 7f7f7f
12 32 6 7f7f7f
13 32 6 7f7f7f
14 32 6 7f7f7f
15 32 6 7f7f7f
0 33 6 7f7f7f
1 33 6 7f7f7f
2 33 6 7f7f7f
3 33 6 7f7f7f
4 33 6 7f7f7f
5 33 6 7f7f7f
6 33 6 7f7f7f
7 33 6 7f7f7f
8 33 6 7f7f7f
9 33 6 7f7f7f
10 33 6 7f7f7f
11 33 6 7f7f7f
12 33 6 7f7f7f
13 33 6 7f7f7f
14 33 6 7f7f7f
15 33 6 7f7f7f
0 34 6 7f7f7f
1 34 6 7f7f7f
2 34 6 7f7f7f
3 34 6 7f7f7f
4 34 6 7f7f7f
5 34 6 7f7f7f
6 34 6 7f7f7f
7 34 6 7f7f7f
8 34 6 7f7f7f
9 34 6 7f7f7f
10 34 6 7f7f7f
11 34 6 7f7f7f
12 34 6 7f7f7f
13 34 6 7f7f7f
14 34 6 7f7f7f
15 34 6 7f7f7f
0 35 6 7f7f7f
1 35 6 7f7f7f
2 35 6 7f7f7f
3 35 6 7f7f7f
4 35 6 7f7f7f
5 35 6 7f7f7f
6 35 6 7f7f7f
7 35 6 7f7f7f
8 35 6 7f7f7f
9 35 6 7f7f7f
10 35 6 7f7f7f
11 35 6 7f7f7f
12 35 6 7f7f7f
13 35 6 7f7f7f
14 35 6 7f7f7f
15 35 6 7f7f7f
0 36 6 7f7f7f
1 36 6 7f7f7f
2 36 6 7f7f7f
3 36 6 7f7f7f
4 36 6 7f7f7f
5 36 6 7f7f7f
6 36 6 7f7f7f
7 36 6 7f7f7f
8 36 6 7f7f7f
9 36 6 7f7f7f
10 36 6 7f7f7f
11 36 6 7f7f7f
12 36 6 7f7f7f
13 36 6 7f7f7f
14 36 6 7f7f7f
15 36 6 7f7f7f
0 37 6 7f7f7f
1 37 6 7f7f7f
2 37 6 7f7f7f
3 37 6 7f7f7f
4 37 6 7f7f7f
5 37 6 7f7f7f
6 37 6 7f7f7f
7 37 6 7f7f7f
8 37 6 7f7f7f
9 37 6 7f7f7f
10 37 6 7f7f7f
11 37 6 7f7f7f
12 37 6 7f7f7f
13 37 6 7f7f7f
14 37 6 7f7f7f
15 37 6 7f7f7f
0 38 6 7f7f7f
1 38 6 7f7f7f
2 38 6 7f7f7f
3 38 6 7f7f7f
4 38 6 7f7f7f
5 38 6 7f7f7f
6 38 6 7f7f7f
7 38 6 7f7f7f
8 38 6 7f7f7f
9 38 6 7f7f7f
10 38 6 7f7f7f
11 38 6 7f7f7f
12 38 6 7f7f7f
13 38 6 7f7f7f
14 38 6 7f7f7f
15 38 6 7f7f7f
0 39 6 7f7f7f
1 39 6 7f7f7f
2 39 6 7f7f7f
3 39 6 7f7f7f
4 39 6 7f7f7f
5 39 6 7f7f7f
6 39 6 7f7f7f
7 39 6 7f7f7f
8 39 6 7f7f7f
9 39 6 7f7f7f
10 39 6 7f7f7f
11 39 6 7f7f7f
12 39 6 7f7f7f
13 39 6 7f7f7f
14 39 6 7f7f7f
15 39 6 7f7f7f
0 40 6 7f7f7f
1 40 6 7f7f7f
2 40 6 7f7f7f
3 40 6 7f7f7f
4 40 6 7f7f7f
5 40 6 7f7f7f
6 40 6 7f7f7f
7 40 6 7f7f7f
8 40 6 7f7f7f
9 40 6 7f7f7f
10 40 6 7f7f7f
11 40 6 7f7f7f
12 40 6 7f7f7f
13 40 6 7f7f7f
14 40 6 7f7f7f
15 40 6 7f7f7f
0 41 6 7f7f7f
1 41 6 7f7f7f
2 41 6 7f7f7f
3 41 6 7f7f7f
4 41 6 7f7f7f
5 41 6 7f7f7f
6 41 6 7f7f7f
7 41 6 7f7f7f
8 41 6 7f7f7f
9 41 6 7f7f7f
10 41 6 7f7f7f
11 41 6 7f7f7f
12 41 6 7f7f7f
13 41 6 7f7f7f
14 41 6 7f7f7f
15 41 6 7f7f7f
0 42 6 7f7f7f
1 42 6 7f7f7f
2 42 6 7f7f7f
3 42 6 7f7f7f
4 42 6 7f7f7f
5 42 6 7f7f7f
6 42 6 7f7f7f
7 42 6 7f7f7f
8 42 6 7f7f7f
9 42 6 7f7f7f
10 42 6 7f7f7f
11 42 6 7f7f7f
12 42 6 7f7f7f
13 42 6 7f7f7f
14 42 6 7f7f7f
15 42 6 7f7f7f
0 43 6 7f7f7f
1 43 6 7f7f7f
2 43 6 7f7f7f
3 43 6 7f7f7f
4 43 6 7f7f7f
5 43 6 7f7f7f
6 43 6 7f7f7f
7 43 6 7f7f7f
8 43 6 7f7f7f
9 43 6 7f7f7f
10 43 6 7f7f7f
11 43 6 7f7f7f
12 43 6 7f7f7f
13 43 6 7f7f7f
14 43 6 7f7f7f
15 43 6 7f7f7f
0 44 6 7f7f7f
1 44 6 7f7f7f
2 44 6 7f7f7f
3 44 6 7f7f7f
4 44 6 7f7f7f
5 44 6 7f7f7f
6 44 6 7f7f7f
7 44 6 7f7f7f
8 44 6 7f7f7f
9 44 6 7f7f7f
10 44 6 7f7f7f
11 44 6 7f7f7f
12 44 6 7f7f7f
13 44 6 7f7f7f
14 44 6 7f7f7f
15 44 6 7f7f7f
0 45 6 7f7f7f
1 45 6 7f7f7f
2 45 6 7f7f7f
3 45 6 7f7f7f
4 45 6 7f7f7f
5 45 6 7f7f7f
6 45 6 7f7f7f
7 45 6 7f7f7f
8 45 6 7f7f7f
9 45 6 7f7f7f
10 45 6 7f7f7f
11 45 6 7f7f7f
12 45 6 7f7f7f
13 45 6 7f7f7f
14 45 6 7f7f7f
15 45 6 7f7f7f
0 46 6 7f7f7f
1 46 6 7f7f7f
2 46 6 7f7f7f
3 46 6 7f7f7f
4 46 6 7f7f7f
5 46 6 7f7f7f
6 46 6 7f7f7f
7 46 6 7f7f7f
8 46 6 7f7f7f
9 46 6 7f7f7f
10 46 6 7f7f7f
11 46 6 7f7f7f
12 46 6 7f7f7f
13 46 6 7f7f7f
14 46 6 7f7f7f
15 46 6 7f7f7f
0 47 6 7f7f7f
1 47 6 7f7f7f
2 47 6 7f7f7f
3 47 6 7f7f7f
4 47 6 7f7f7f
5 47 6 7f7f7f
6 47 6 7f7f7f
7 47 6 7f7f7f
8 47 6 7f7f7f
9 47 6 7f7f7f
10 47 6 7f7f7f
11 47 6 7f7f7f
12 47 6 7f7f7f
13 47 6 7f7f7f
14 47 6 7f7f7f
15 47 6 7f7f7f
0 32 7 7f7f7f
1 32 7 7f7f7f
2 32 7 7f7f7f
3 32 7 7f7f7f
4 32 7 7f7f7f
5 32 7 7f7f7f
6 32 7 7f7f7f
7 32 7 7f7f7f
8 32 7 7f7f7f
9 32 7 7f7f7f
10 32 7 7f7f7f
11 32 7 7f7f7f
12 32 7 7f7f7f
13 32 7 7f7f7f
14 32 7 7f7f7f
15 32 7 7f7f7f
0 33 7 7f7f7f
1 33 7 7f7f7f
2 33 7 7f7f7f
3 33 7 7f7f7f
4 33 7 7f7f7f
5 33 7 7f7f7f
6 33 7 7f7f7f
7 33 7 7f7f7f
8 33 7 7f7f7f
9 33 7 7f7f7f
10 33 7 7f7f7f
11 33 7 7f7f7f
12 33 7 7f7f7f
13 33 7 7f7f7f
14 33 7 7f7f7f
15 33 7 7f7f7f
0 34 7 7f7f7f
1 34 7 7f7f7f
2 34 7 7f7f7f
3 34 7 7f7f7f
4 34 7 7f7f7f
5 34 7 7f7f7f
6 34 7 7f7f7f
7 34 7 7f7f7f
8 34 7 7f7f7f
9 34 7 7f7f7f
10 34 7 7f7f7f
11 34 7 7f7f7f
12 34 7 7f7f7f
13 34 7 7f7f7f
14 34 7 7f7f7f
15 34 7 7f7f7f
0 35 7 7f7f7f
1 35 7 7f7f7f
2 35 7 7f7f7f
3 35 7 7f7f7f
4 35 7 7f7f7f
5 35 7 7f7f7f
6 35 7 7f7f7f
7 35 7 7f7f7f
8 35 7 7f7f7f
9 35 7 7f7f7f
10 35 7 7f7f7f
11 35 7 7f7f7f
12 35 7 7f7f7f
13 35 7 7f7f7f
14 35 7 7f7f7f
15 35 7 7f7f7f
0 36 7 7f7f7f
1 36 7 7f7f7f
2 36 7 7f7f7f
3 36 7 7f7f7f
4 36 7 7f7f7f
5 36 7 7f7f7f
6 36 7 7f7f7f
7 36 7 7f7f7f
8 36 7 7f7f7f
9 36 7 7f7f7f
10 36 7 7f7f7f
11 36 7 7f7f7f
12 36 7 7f7f7f
13 36 7 7f7f7f
14 36 7 7f7f7f
15 36 7 7f7f7f
0 37 7 7f7f7f
1 37 7 7f7f7f
2 37 7 7f7f7f
3 37 7 7f7f7f
4 37 7 7f7f7f
5 37 7 7f7f7f
6 37 7 7f7f7f
7 37 7 7f7f7f
8 37 7 7f7f7f
9 37 7 7f7f7f
10 37 7 7f7f7f
11 37 7 7f7f7f
12 37 7 7f7f7f
13 37 7 7f7f7f
14 37 7 7f7f7f
15 37 7 7f7f7f
0 38 7 7f7f7f
1 38 7 7f7f7f
2 38 7 7f7f7f
3 38 7 7f7f7f
4 38 7 7f7f7f
5 38 7 7f7f7f
6 38 7 7f7f7f
7 38 7 7f7f7f
8 38 7 7f7f7f
9 38 7 7f7f7f
10 38 7 7f7f7f
11 38 7 7f7f7f
12 38 7 7f7f7f
13 38 7 7f7f7f
14 38 7 7f7f7f
15 38 7 7f7f7f
0 39 7 7f7f7f
1 39 7 7f7f7f
2 39 7 7f7f7f
3 39 7 7f7f7f
4 39 7 7f7f7f
5 39 7 7f7f7f
6 39 7 7f7f7f
7 39 7 7f7f7f
8 39 7 7f7f7f
9 39 7 7f7f7f
10 39 7 7f7f7f
11 39 7 7f7f7f
12 39 7 7f7f7f
13 39 7 7f7f7f
14 39 7 7f7f7f
15 39 7 7f7f7f
0 40 7 7f7f7f
1 40 7 7f7f7f
2 40 7 7f7f7f
3 40 7 7f7f7f
4 40 7 7f7f7f
5 40 7 7f7f7f
6 40 7 7f7f7f
7 40 7 7f7f7f
8 40 7 7f7f7f
9 40 7 7f7f7f
10 40 7 7f7f7f
11 40 7 7f7f7f
12 40 7 7f7f7f
13 40 7 7f7f7f
14 40 7 7f7f7f
15 40 7 7f7f7f
0 41 7 7f7f7f
1 41 7 7f7f7f
2 41 7 7f7f7f
3 41 7 7f7f7f
4 41 7 7f7f7f
5 41 7 7f7f7f
6 41 7 7f7f7f
7 41 7 7f7f7f
8 41 7 7f7f7f
9 41 7 7f7f7f
10 41 7 7f7f7f
11 41 7 7f7f7f
12 41 7 7f7f7f
13 41 7 7f7f7f
14 41 7 7f7f7f
15 41 7 7f7f7f
0 42 7 7f7f7f
1 42 7 7f7f7f
2 42 7 7f7f7f
3 42 7 7f7f7f
4 42 7 7f7f7f
5 42 7 7f7f7f
6 42 7 7f7f7f
7 42 7 7f7f7f
8 42 7 7f7f7f
9 42 7 7f7f7f
10 42 7 7f7f7f
11 42 7 7f7f7f
12 42 7 7f7f7f
13 42 7 7f7f7f
14 42 7 7f7f7f
15 42 7 7f7f7f
0 43 7 7f7f7f
1 43 7 7f7f7f
2 43 7 7f7f7f
3 43 7 7f7f7f
4 43 7 7f7f7f
5 43 7 7f7f7f
6 43 7 7f7f7f
7 43 7 7f7f7f
8 43 7 7f7f7f
9 43 7 7f7f7f
10 43 7 7f7f7f
11 43 7 7f7f7f
12 43 7 7f7f7f
13 43 7 7f7f7f
14 43 7 7f7f7f
15 43 7 7f7f7f
0 44 7 7f7f7f
1 44 7 7f7f7f
2 44 7 7f7f7f
3 44 7 7f7f7f
4 44 7 7f7f7f
5 44 7 7f7f7f
6 44 7 7f7f7f
7 44 7 7f7f7f
8 44 7 7f7f7f
9 44 7 7f7f7f
10 44 7 7f7f7f
11 44 7 7f7f7f
12 44 7 7f7f7f
13 44 7 7f7f7f
14 44 7 7f7f7f
15 44 7 7f7f7f
0 45 7 7f7f7f
1 45 7 7f7f7f
2 45 7 7f7f7f
3 45 7 7f7f7f
4 45 7 7f7f7f
5 45 7 7f7f7f
6 45 7 7f7f7f
7 45 7 7f7f7f
8 45 7 7f7f7f
9 45 7 7f7f7f
10 45 7 7f7f7f
11 45 7 7f7f7f
12 45 7 7f7f7f
13 45 7 7f7f7f
14 45 7 7f7f7f
15 45 7 7f7f7f
0 46 7 7f7f7f
1 46 7 7f7f7f
2 46 7 7f7f7f
3 46 7 7f7f7f
4 46 7 7f7f7f
5 46 7 7f7f7f
6 46 7 7f7f7f
7 46 7 7f7f7f
8 46 7 7f7f7f
9 46 7 7f7f7f
10 46 7 7f7f7f
11 46 7 7f7f7f
12 46 7 7f7f7f
13 46 7 7f7f7f
14 46 7 7f7f7f
15 46 7 7f7f7f
0 47 7 7f7f7f
1 47 7 7f7f7f
2 47 7 7f7f7f
3 47 7 7f7f7f
4 47 7 7f7f7f
5 47 7 7f7f7f
6 47 7 7f7f7f
7 47 7 7f7f7f
8 47 7 7f7f7f
9 47 7 7f7f7f
10 47 7 7f7f7f
11 47 7 7f7f7f
12 47 7 7f7f7f
13 47 7 7f7f7f
14 47 7 7f7f7f
15 47 7 7f7f7f
0 32 8 7f7f7f
1 32 8 7f7f7f
2 32 8 7f7f7f
3 32 8 7f7f7f
4 32 8 7f7f7f
5 32 8 7f7f7f
6 32 8 7f7f7f
7 32 8 7f7f7f
8 32 8 7f7f7f
9 32 8 7f7f7f
10 32 8 7f7f7f
11 32 8 7f7f7f
12 32 8 7f7f7f
13 32 8 7f7f7f
14 32 8 7f7f7f
15 32 8 7f7f7f
0 33 8 7f7f7f
1 33 8 7f7f7f
2 33 8 7f7f7f
3 33 8 7f7f7f
4 33 8 7f7f7f
5 33 8 7f7f7f
6 33 8 7f7f7f
7 33 8 7f7f7f
8 33 8 7f7f7f
9 33 8 7f7f7f
10 33 8 7f7f7f
11 33 8 7f7f7f
12 33 8 7f7f7f
13 33 8 7f7f7f
14 33 8 7f7f7f
15 33 8 7f7f7f
0 34 8 7f7f7f
1 34 8 7f7f7f
2 34 8 7f7f7f
3 34 8 7f7f7f
4 34 8 7f7f7f
5 34 8 7f7f7f
6 34 8 7f7f7f
7 34 8 7f7f7f
8 34 8 7f7f7f
9 34 8 7f7f7f
10 34 8 7f7f7f
11 34 8 7f7f7f
12 34 8 7f7f7f
13 34 8 7f7f7f
14 34 8 7f7f7f
15 34 8 7f7f7f
0 35 8 7f7f7f
1 35 8 7f7f7f
2 35 8 7f7f7f
3 35 8 7f7f7f
4 35 8 7f7f7f
5 35 8 7f7f7f
6 35 8 7f7f7f
7 35 8 7f7f7f
8 35 8 7f7f7f
9 35 8 7f7f7f
10 35 8 7f7f7f
11 35 8 7f7f7f
12 35 8 7f7f7f
13 35 8 7f7f7f
14 35 8 7f7f7f
15 35 8 7f7f7f
0 36 8 7f7f7f
1 36 8 7f7f7f
2 36 8 7f7f7f
3 36 8 7f7f7f
4 36 8 7f7f7f
5 36 8 7f7f7f
6 36 8 7f7f7f
7 36 8 7f7f7f
8 36 8 7f7f7f
9 36 8 7f7f7f
10 36 8 7f7f7f
11 36 8 7f7f7f
12 36 8 7f7f7f
13 36 8 7f7f7f
14 36 8 7f7f7f
15 36 8 7f7f7f
0 37 8 7f7f7f
1 37 8 7f7f7f
2 37 8 7f7f7f
3 37 8 7f7f7f
4 37 8 7f7f7f
5 37 8 7f7f7f
6 37 8 7f7f7f
7 37 8 7f7f7f
8 37 8 7f7f7f
9 37 8 7f7f7f
10 37 8 7f7f7f
11 37 8 7f7f7f
12 37 8 7f7f7f
13 37 8 7f7f7f
14 37 8 7f7f7f
15 37 8 7f7f7f
0 38 8 7f7f7f
1 38 8 7f7f7f
2 38 8 7f7f7f
3 38 8 7f7f7f
4 38 8 7f7f7f
5 38 8 7f7f7f
6 38 8 7f7f7f
7 38 8 7f7f7f
8 38 8 7f7f7f
9 38 8 7f7f7f
10 38 8 7f7f7f
11 38 8 7f7f7f
12 38 8 7f7f7f
13 38 8 7f7f7f
14 38 8 7f7f7f
15 38 8 7f7f7f
0 39 8 7f7f7f
1 39 8 7f7f7f
2 39 8 7f7f7f
3 39 8 7f7f7f
4 39 8 7f7f7f
5 39 8 7f7f7f
6 39 8 7f7f7f
7 39 8 7f7f7f
8 39 8 7f7f7f
9 39 8 7f7f7f
10 39 8 7f7f7f
11 39 8 7f7f7f
12 39 8 7f7f7f
13 39 8 7f7f7f
14 39 8 7f7f7f
15 39 8 7f7f7f
0 40 8 7f7f7f
1 40 8 7f7f7f
2 40 8 7f7f7f
3 40 8 7f7f7f
4 40 8 7f7f7f
5 40 8 7f7f7f
6 40 8 7f7f7f
7 40 8 7f7f7f
8 40 8 7f7f7f
9 40 8 7f7f7f
10 40 8 7f7f7f
11 40 8 7f7f7f
12 40 8 7f7f7f
13 40 8 7f7f7f
14 40 8 7f7f7f
15 40 8 7f7f7f
0 41 8 7f7f7f
1 41 8 7f7f7f
2 41 8 7f7f7f
3 41 8 7f7f7f
4 41 8 7f7f7f
5 41 8 7f7f7f
6 41 8 7f7f7f
7 41 8 7f7f7f
8 41 8 7f7f7f
9 41 8 7f7f7f
10 41 8 7f7f7f
11 41 8 7f7f7f
12 41 8 7f7f7f
13 41 8 7f7f7f
14 41 8 7f7f7f
15 41 8 7f7f7f
0 42 8 7f7f7f
1 42 8 7f7f7f
2 42 8 7f7f7f
3 42 8 7f7f7f
4 42 8 7f7f7f
5 42 8 7f7f7f
6 42 8 7f7f7f
7 42 8 7f7f7f
8 42 8 7f7f7f
9 42 8 7f7f7f
10 42 8 7f7f7f
11 42 8 7f7f7f
12 42 8 7f7f7f
13 42 8 7f7f7f
14 42 8 7f7f7f
15 42 8 7f7f7f
0 43 8 7f7f7f
1 43 8 7f7f7f
2 43 8 7f7f7f
3 43 8 7f7f7f
4 43 8 7f7f7f
5 43 8 7f7f7f
6 43 8 7f7f7f
7 43 8 7f7f7f
8 43 8 7f7f7f
9 43 8 7f7f7f
10 43 8 7f7f7f
11 43 8 7f7f7f
12 43 8 7f7f7f
13 43 8 7f7f7f
14 43 8 7f7f7f
15 43 8 7f7f7f
0 44 8 7f7f7f
1 44 8 7f7f7f
2 44 8 7f7f7f
3 44 8 7f7f7f
4 44 8 7f7f7f
5 44 8 7f7f7f
6 44 8 7f7f7f
7 44 8 7f7f7f
8 44 8 7f7f7f
9 44 8 7f7f7f
10 44 8 7f7f7f
11 44 8 7f7f7f
12 44 8 7f7f7f
13 44 8 7f7f7f
14 44 8 7f7f7f
15 44 8 7f7f7f
0 45 8 7f7f7f
1 45 8 7f7f7f
2 45 8 7f7f7f
3 45 8 7f7f7f
4 45 8 7f7f7f
5 45 8 7f7f7f
6 45 8 7f7f7f
7 45 8 7f7f7f
8 45 8 7f7f7f
9 45 8 7f7f7f
10 45 8 7f7f7f
11 45 8 7f7f7f
12 45 8 7f7f7f
13 45 8 7f7f7f
14 45 8 7f7f7f
15 45 8 7f7f7f
0 46 8 7f7f7f
1 46 8 7f7f7f
2 46 8 7f7f7f
3 46 8 7f7f7f
4 46 8 7f7f7f
5 46 8 7f7f7f
6 46 8 7f7f7f
7 46 8 7f7f7f
8 46 8 7f7f7f
9 46 8 7f7f7f
10 46 8 7f7f7f
11 46 8 7f7f7f
12 46 8 7f7f7f
13 46 8 7f7f7f
14 46 8 7f7f7f
15 46 8 7f7f7f
0 47 8 7f7f7f
1 47 8 7f7f7f
2 47 8 7f7f7f
3 47 8 7f7f7f
4 47 8 7f7f7f
5 47 8 7f7f7f
6 47 8 7f7f7f
7 47 8 7f7f7f
8 47 8 7f7f7f
9 47 8 7f7f7f
10 47 8 7f7f7f
11 47 8 7f7f7f
12 47 8 7f7f7f
13 47 8 7f7f7f
14 47 8 7f7f7f
15 47 8 7f7f7f
0 32 9 7f7f7f
1 32 9 7f7f7f
2 32 9 7f7f7f
3 32 9 7f7f7f
4 32 9 7f7f7f
5 32 9 7f7f7f
6 32 9 7f7f7f
7 32 9 7f7f7f
8 32 9 7f7f7f
9 32 9 7f7f7f
10 32 9 7f7f7f
11 32 9 7f7f7f
12 32 9 7f7f7f
13 32 9 7f7f7f
14 32 9 7f7f7f
15 32 9 7f7f7f
0 33 9 7f7f7f
1 33 9 7f7f7f
2 33 9 7f7f7f
3 33 9 7f7f7f
4 33 9 7f7f7f
5 33 9 7f7f7f
6 33 9 7f7f7f
7 33 9 7f7f7f
8 33 9 7f7f7f
9 33 9 7f7f7f
10 33 9 7f7f7f
11 33 9 7f7f7f
12 33 9 7f7f7f
13 33 9 7f7f7f
14 33 9 7f7f7f
15 33 9 7f7f7f
0 34 9 7f7f7f
1 34 9 7f7f7f
2 34 9 7f7f7f
3 34 9 7f7f7f
4 34 9 7f7f7f
5 34 9 7f7f7f
6 34 9 7f7f7f
7 34 9 7f7f7f
8 34 9 7f7f7f
9 34 9 7f7f7f
10 34 9 7f7f7f
11 34 9 7f7f7f
12 34 9 7f7f7f
13 34 9 7f7f7f
14 34 9 7f7f7f
15 34 9 7f7f7f
0 35 9 7f7f7f
1 35 9 7f7f7f
2 35 9 7f7f7f
3 35 9 7f7f7f
4 35 9 7f7f7f
5 35 9 7f7f7f
6 35 9 7f7f7f
7 35 9 7f7f7f
8 35 9 7f7f7f
9 35 9 7f7f7f
10 35 9 7f7f7f
11 35 9 7f7f7f
12 35 9 7f7f7f
13 35 9 7f7f7f
14 35 9 7f7f7f
15 35 9 7f7f7f
0 36 9 7f7f7f
1 36 9 7f7f7f
2 36 9 7f7f7f
3 36 9 7f7f7f
4 36 9 7f7f7f
5 36 9 7f7f7f
6 36 9 7f7f7f
7 36 9 7f7f7f
8 36 9 7f7f7f
9 36 9 7f7f7f
10 36 9 7f7f7f
11 36 9 7f7f7f
12 36 9 7f7f7f
13 36 9 7f7f7f
14 36 9 7f7f7f
15 36 9 7f7f7f
0 37 9 7f7f7f
1 37 9 7f7f7f
2 37 9 7f7f7f
3 37 9 7f7f7f
4 37 9 7f7f7f
5 37 9 7f7f7f
6 37 9 7f7f7f
7 37 9 7f7f7f
8 37 9 7f7f7f
9 37 9 7f7f7f
10 37 9 7f7f7f
11 37 9 7f7f7f
12 37 9 7f7f7f
13 37 9 7f7f7f
14 37 9 7f7f7f
15 37 9 7f7f7f
0 38 9 7f7f7f
1 38 9 7f7f7f
2 38 9 7f7f7f
3 38 9 7f7f7f
4 38 9 7f7f7f
5 38 9 7f7f7f
6 38 9 7f7f7f
7 38 9 7f7f7f
8 38 9 7f7f7f
9 38 9 7f7f7f
10 38 9 7f7f7f
11 38 9 7f7f7f
12 38 9 7f7f7f
13 38 9 7f7f7f
14 38 9 7f7f7f
15 38 9 7f7f7f
0 39 9 7f7f7f
1 39 9 7f7f7f
2 39 9 7f7f7f
3 39 9 7f7f7f
4 39 9 7f7f7f
5 39 9 7f7f7f
6 39 9 7f7f7f
7 39 9 7f7f7f
8 39 9 7f7f7f
9 39 9 7f7f7f
10 39 9 7f7f7f
11 39 9 7f7f7f
12 39 9 7f7f7f
13 39 9 7f7f7f
14 39 9 7f7f7f
15 39 9 7f7f7f
0 40 9 7f7f7f
1 40 9 7f7f7f
2 40 9 7f7f7f
3 40 9 7f7f7f
4 40 9 7f7f7f
5 40 9 7f7f7f
6 40 9 7f7f7f
7 40 9 7f7f7f
8 40 9 7f7f7f
9 40 9 7f7f7f
10 40 9 7f7f7f
11 40 9 7f7f7f
12 40 9 7f7f7f
13 40 9 7f7f7f
14 40 9 7f7f7f
15 40 9 7f7f7f
0 41 9 7f7f7f
1 41 9 7f7f7f
2 41 9 7f7f7f
3 41 9 7f7f7f
4 41 9 7f7f7f
5 41 9 7f7f7f
6 41 9 7f7f7f
7 41 9 7f7f7f
8 41 9 7f7f7f
9 41 9 7f7f7f
10 41 9 7f7f7f
11 41 9 7f7f7f
12 41 9 7f7f7f
13 41 9 7f7f7f
14 41 9 7f7f7f
15 41 9 7f7f7f
0 42 9 7f7f7f
1 42 9 7f7f7f
2 42 9 7f7f7f
3 42 9 7f7f7f
4 42 9 7f7f7f
5 42 9 7f7f7f
6 42 9 7f7f7f
7 42 9 7f7f7f
8 42 9 7f7f7f
9 42 9 7f7f7f
10 42 9 7f7f7f
11 42 9 7f7f7f
12 42 9 7f7f7f
13 42 9 7f7f7f
14 42 9 7f7f7f
15 42 9 7f7f7f
0 43 9 7f7f7f
1 43 9 7f7f7f
2 43 9 7f7f7f
3 43 9 7f7f7f
4 43 9 7f7f7f
5 43 9 7f7f7f
6 43 9 7f7f7f
7 43 9 7f7f7f
8 43 9 7f7f7f
9 43 9 7f7f7f
10 43 9 7f7f7f
11 43 9 7f7f7f
12 43 9 7f7f7f
13 43 9 7f7f7f
14 43 9 7f7f7f
15 43 9 7f7f7f
0 44 9 7f7f7f
1 44 9 7f7f7f
2 44 9 7f7f7f
3 44 9 7f7f7f
4 44 9 7f7f7f
5 44 9 7f7f7f
6 44 9 7f7f7f
7 44 9 7f7f7f
8 44 9 7f7f7f
9 44 9 7f7f7f
10 44 9 7f7f7f
11 44 9 7f7f7f
12 44 9 7f7f7f
13 44 9 7f7f7f
14 44 9 7f7f7f
15 44 9 7f7f7f
0 45 9 7f7f7f
1 45 9 7f7f7f
2 45 9 7f7f7f
3 45 9 7f7f7f
4 45 9 7f7f7f
5 45 9 7f7f7f
6 45 9 7f7f7f
7 45 9 7f7f7f
8 45 9 7f7f7f
9 45 9 7f7f7f
10 45 9 7f7f7f
11 45 9 7f7f7f
12 45 9 7f7f7f
13 45 9 7f7f7f
14 45 9 7f7f7f
15 45 9 7f7f7f
0 46 9 7f7f7f
1 46 9 7f7f7f
2 46 9 7f7f7f
3 46 9 7f7f7f
4 46 9 7f7f7f
5 46 9 7f7f7f
6 46 9 7f7f7f
7 46 9 7f7f7f
8 46 9 7f7f7f
9 46 9 7f7f7f
10 46 9 7f7f7f
11 46 9 7f7f7f
12 46 9 7f7f7f
13 46 9 7f7f7f
14 46 9 7f7f7f
15 46 9 7f7f7f
0 47 9 7f7f7f
1 47 9 7f7f7f
2 47 9 7f7f7f
3 47 9 7f7f7f
4 47 9 7f7f7f
5 47 9 7f7f7f
6 47 9 7f7f7f
7 47 9 7f7f7f
8 47 9 7f7f7f
9 47 9 7f7f7f
10 47 9 7f7f7f
11 47 9 7f7f7f
12 47 9 7f7f7f
13 47 9 7f7f7f
14 47 9 7f7f7f
15 47 9 7f7f7f
0 32 10 7f7f7f
1 32 10 7f7f7f
2 32 10 7f7f7f
3 32 10 7f7f7f
4 32 10 7f7f7f
5 32 10 7f7f7f
6 32 10 7f7f7f
7 32 10 7f7f7f
8 32 10 7f7f7f
9 32 10 7f7f7f
10 32 10 7f7f7f
11 32 10 7f7f7f
12 32 10 7f7f7f
13 32 10 7f7f7f
14 32 10 7f7f7f
15 32 10 7f7f7f
0 33 10 7f7f7f
1 33 10 7f7f7f
2 33 10 7f7f7f
3 33 10 7f7f7f
4 33 10 7f7f7f
5 33 10 7f7f7f
6 33 10 7f7f7f
7 33 10 7f7f7f
8 33 10 7f7f7f
9 33 10 7f7f7f
10 33 10 7f7f7f
11 33 10 7f7f7f
12 33 10 7f7f7f
13 33 10 7f7f7f
14 33 10 7f7f7f
15 33 10 7f7f7f
0 34 10 7f7f7f
1 34 10 7f7f7f
2 34 10 7f7f7f
3 34 10 7f7f7f
4 34 10 7f7f7f
5 34 10 7f7f7f
6 34 10 7f7f7f
7 34 10 7f7f7f
8 34 10 7f7f7f
9 34 10 7f7f7f
10 34 10 7f7f7f
11 34 10 7f7f7f
12 34 10 7f7f7f
13 34 10 7f7f7f
14 34 10 7f7f7f
15 34 10 7f7f7f
0 35 10 7f7f7f
1 35 10 7f7f7f
2 35 10 7f7f7f
3 35 10 7f7f7f
4 35 10 7f7f7f
5 35 10 7f7f7f
6 35 10 7f7f7f
7 35 10 7f7f7f
8 35 10 7f7f7f
9 35 10 7f7f7f
10 35 10 7f7f7f
11 35 10 7f7f7f
12 35 10 7f7f7f
13 35 10 7f7f7f
14 35 10 7f7f7f
15 35 10 7f7f7f
0 36 10 7f7f7f
1 36 10 7f7f7f
2 36 10 7f7f7f
3 36 10 7f7f7f
4 36 10 7f7f7f
5 36 10 7f7f7f
6 36 10 7f7f7f
7 36 10 7f7f7f
8 36 10 7f7f7f
9 36 10 7f7f7f
10 36 10 7f7f7f
11 36 10 7f7f7f
12 36 10 7f7f7f
13 36 10 7f7f7f
14 36 10 7f7f7f
15 36 10 7f7f7f
0 37 10 7f7f7f
1 37 10 7f7f7f
2 37 10 7f7f7f
3 37 10 7f7f7f
4 37 10 7f7f7f
5 37 10 7f7f7f
6 37 10 7f7f7f
7 37 10 7f7f7f
8 37 10 7f7f7f
9 37 10 7f7f7f
10 37 10 7f7f7f
11 37 10 7f7f7f
12 37 10 7f7f7f
13 37 10 7f7f7f
14 37 10 7f7f7f
15 37 10 7f7f7f
0 38 10 7f7f7f
1 38 10 7f7f7f
2 38 10 7f7f7f
3 38 10 7f7f7f
4 38 10 7f7f7f
5 38 10 7f7f7f
6 38 10 7f7f7f
7 38 10 7f7f7f
8 38 10 7f7f7f
9 38 10 7f7f7f
10 38 10 7f7f7f
11 38 10 7f7f7f
12 38 10 7f7f7f
13 38 10 7f7f7f
14 38 10 7f7f7f
15 38 10 7f7f7f
0 39 10 7f7f7f
1 39 10 7f7f7f
2 39 10 7f7f7f
3 39 10 7f7f7f
4 39 10 7f7f7f
5 39 10 7f7f7f
6 39 10 7f7f7f
7 39 10 7f7f7f
8 39 10 7f7f7f
9 39 10 7f7f7f
10 39 10 7f7f7f
11 39 10 7f7f7f
12 39 10 7f7f7f
13 39 10 7f7f7f
14 39 10 7f7f7f
15 39 10 7f7f7f
0 40 10 7f7f7f
1 40 10 7f7f7f
2 40 10 7f7f7f
3 40 10 7f7f7f
4 40 10 7f7f7f
5 40 10 7f7f7f
6 40 10 7f7f7f
7 40 10 7f7f7f
8 40 10 7f7f7f
9 40 10 7f7f7f
10 40 10 7f7f7f
11 40 10 7f7f7f
0 41 10 7f7f7f
1 41 10 7f7f7f
2 41 10 7f7f7f
3 41 10 7f7f7f
4 41 10 7f7f7f
5 41 10 7f7f7f
6 41 10 7f7f7f
7 41 10 7f7f7f
8 41 10 7f7f7f
9 41 10 7f7f7f
10 41 10 7f7f7f
11 41 10 7f7f7f
0 42 10 7f7f7f
1 42 10 7f7f7f
2 42 10 7f7f7f
3 42 10 7f7f7f
4 42 10 7f7f7f
5 42 10 7f7f7f
6 42 10 7f7f7f
7 42 10 7f7f7f
8 42 10 7f7f7f
9 42 10 7f7f7f
10 42 10 7f7f7f
11 42 10 7f7f7f
0 43 10 7f7f7f
1 43 10 7f7f7f
2 43 10 7f7f7f
3 43 10 7f7f7f
4 43 10 7f7f7f
5 43 10 7f7f7f
6 43 10 7f7f7f
7 43 10 7f7f7f
8 43 10 7f7f7f
9 43 10 7f7f7f
10 43 10 7f7f7f
11 43 10 7f7f7f
0 44 10 7f7f7f
1 44 10 7f7f7f
2 44 10 7f7f7f
3 44 10 7f7f7f
4 44 10 7f7f7f
5 44 10 7f7f7f
6 44 10 7f7f7f
7 44 10 7f7f7f
8 44 10 7f7f7f
9 44 10 7f7f7f
10 44 10 7f7f7f
11 44 10 7f7f7f
0 45 10 7f7f7f
1 45 10 7f7f7f
2 45 10 7f7f7f
3 45 10 7f7f7f
4 45 10 7f7f7f
5 45 10 7f7f7f
6 45 10 7f7f7f
7 45 10 7f7f7f
8 45 10 7f7f7f
9 45 10 7f7f7f
10 45 10 7f7f7f
11 45 10 7f7f7f
0 46 10 7f7f7f
1 46 10 7f7f7f
2 46 10 7f7f7f
3 46 10 7f7f7f
4 46 10 7f7f7f
5 46 10 7f7f7f
6 46 10 7f7f7f
7 46 10 7f7f7f
8 46 10 7f7f7f
9 46 10 7f7f7f
10 46 10 7f7f7f
11 46 10 7f7f7f
0 47 10 7f7f7f
1 47 10 7f7f7f
2 47 10 7f7f7f
3 47 10 7f7f7f
4 47 10 7f7f7f
5 47 10 7f7f7f
6 47 10 7f7f7f
7 47 10 7f7f7f
8 47 10 7f7f7f
9 47 10 7f7f7f
10 47 10 7f7f7f
11 47 10 7f7f7f
0 32 11 7f7f7f
1 32 11 7f7f7f
2 32 11 7f7f7f
3 32 11 7f7f7f
4 32 11 7f7f7f
5 32 11 7f7f7f
6 32 11 7f7f7f
7 32 11 7f7f7f
8 32 11 7f7f7f
9 32 11 7f7f7f
10 32 11 7f7f7f
11 32 11 7f7f7f
12 32 11 7f7f7f
13 32 11 7f7f7f
14 32 11 7f7f7f
15 32 11 7f7f7f
0 33 11 7f7f7f
1 33 11 7f7f7f
2 33 11 7f7f7f
3 33 11 7f7f7f
4 33 11 7f7f7f
5 33 11 7f7f7f
6 33 11 7f7f7f
7 33 11 7f7f7f
8 33 11 7f7f7f
9 33 11 7f7f7f
10 33 11 7f7f7f
11 33 11 7f7f7f
12 33 11 7f7f7f
13 33 11 7f7f7f
14 33 11 7f7f7f
15 33 11 7f7f7f
0 34 11 7f7f7f
1 34 11 7f7f7f
2 34 11 7f7f7f
3 34 11 7f7f7f
4 34 11 7f7f7f
5 34 11 7f7f7f
6 34 11 7f7f7f
7 34 11 7f7f7f
8 34 11 7f7f7f
9 34 11 7f7f7f
10 34 11 7f7f7f
11 34 11 7f7f7f
12 34 11 7f7f7f
13 34 11 7f7f7f
14 34 11 7f7f7f
15 34 11 7f7f7f
0 35 11 7f7f7f
1 35 11 7f7f7f
2 35 11 7f7f7f
3 35 11 7f7f7f
4 35 11 7f7f7f
5 35 11 7f7f7f
6 35 11 7f7f7f
7 35 11 7f7f7f
8 35 11 7f7f7f
9 35 11 7f7f7f
10 35 11 7f7f7f
11 35 11 7f7f7f
12 35 11 7f7f7f
13 35 11 7f7f7f
14 35 11 7f7f7f
15 35 11 7f7f7f
0 36 11 7f7f7f
1 36 11 7f7f7f
2 36 11 7f7f7f
3 36 11 7f7f7f
4 36 11 7f7f7f
5 36 11 7f7f7f
6 36 11 7f7f7f
7 36 11 7f7f7f
8 36 11 7f7f7f
9 36 11 7f7f7f
10 36 11 7f7f7f
11 36 11 7f7f7f
12 36 11 7f7f7f
13 36 11 7f7f7f
14 36 11 7f7f7f
15 36 11 7f7f7f
0 37 11 7f7f7f
1 37 11 7f7f7f
2 37 11 7f7f7f
3 37 11 7f7f7f
4 37 11 7f7f7f
5 37 11 7f7f7f
6 37 11 7f7f7f
7 37 11 7f7f7f
8 37 11 7f7f7f
9 37 11 7f7f7f
10 37 11 7f7f7f
11 37 11 7f7f7f
12 37 11 7f7f7f
13 37 11 7f7f7f
14 37 11 7f7f7f
15 37 11 7f7f7f
0 38 11 7f7f7f
1 38 11 7f7f7f
2 38 11 7f7f7f
3 38 11 7f7f7f
4 38 11 7f7f7f
5 38 11 7f7f7f
6 38 11 7f7f7f
7 38 11 7f7f7f
8 38 11 7f7f7f
9 38 11 7f7f7f
10 38 11 7f7f7f
11 38 11 7f7f7f
12 38 11 7f7f7f
13 38 11 7f7f7f
14 38 11 7f7f7f
15 38 11 7f7f7f
0 39 11 7f7f7f
1 39 11 7f7f7f
2 39 11 7f7f7f
3 39 11 7f7f7f
4 39 11 7f7f7f
5 39 11 7f7f7f
6 39 11 7f7f7f
7 39 11 7f7f7f
8 39 11 7f7f7f
9 39 11 7f7f7f
10 39 11 7f7f7f
11 39 11 7f7f7f
12 39 11 7f7f7f
13 39 11 7f7f7f
14 39 11 7f7f7f
15 39 11 7f7f7f
0 40 11 7f7f7f
1 40 11 7f7f7f
2 40 11 7f7f7f
3 40 11 7f7f7f
4 40 11 7f7f7f
5 40 11 7f7f7f
6 40 11 7f7f7f
7 40 11 7f7f7f
8 40 11 7f7f7f
9 40 11 7f7f7f
10 40 11 7f7f7f
11 40 11 7f7f7f
0 41 11 7f7f7f
1 41 11 7f7f7f
2 41 11 7f7f7f
3 41 11 7f7f7f
4 41 11 7f7f7f
5 41 11 7f7f7f
6 41 11 7f7f7f
7 41 11 7f7f7f
8 41 11 7f7f7f
9 41 11 7f7f7f
10 41 11 7f7f7f
11 41 11 7f7f7f
0 42 11 7f7f7f
1 42 11 7f7f7f
2 42 11 7f7f7f
3 42 11 7f7f7f
4 42 11 7f7f7f
5 42 11 7f7f7f
6 42 11 7f7f7f
7 42 11 7f7f7f
8 42 11 7f7f7f
9 42 11 7f7f7f
10 42 11 7f7f7f
11 42 11 7f7f7f
0 43 11 7f7f7f
1 43 11 7f7f7f
2 43 11 7f7f7f
3 43 11 7f7f7f
4 43 11 7f7f7f
5 43 11 7f7f7f
6 43 11 7f7f7f
7 43 11 7f7f7f
8 43 11 7f7f7f
9 43 11 7f7f7f
10 43 11 7f7f7f
11 43 11 7f7f7f
0 44 11 7f7f7f
1 44 11 7f7f7f
2 44 11 7f7f7f
3 44 11 7f7f7f
4 44 11 7f7f7f
5 44 11 7f7f7f
6 44 11 7f7f7f
7 44 11 7f7f7f
8 44 11 7f7f7f
9 44 11 7f7f7f
10 44 11 7f7f7f
11 44 11 7f7f7f
0 45 11 7f7f7f
1 45 11 7f7f7f
2 45 11 7f7f7f
3 45 11 7f7f7f
4 45 11 7f7f7f
5 45 11 7f7f7f
6 45 11 7f7f7f
7 45 11 7f7f7f
8 45 11 7f7f7f
9 45 11 7f7f7f
10 45 11 7f7f7f
11 45 11 7f7f7f
0 46 11 7f7f7f
1 46 11 7f7f7f
2 46 11 7f7f7f
3 46 11 7f7f7f
4 46 11 7f7f7f
5 46 11 7f7f7f
6 46 11 7f7f7f
7 46 11 7f7f7f
8 46 11 7f7f7f
9 46 11 7f7f7f
10 46 11 7f7f7f
11 46 11 7f7f7f
0 47 11 7f7f7f
1 47 11 7f7f7f
2 47 11 7f7f7f
3 47 11 7f7f7f
4 47 11 7f7f7f
5 47 11 7f7f7f
6 47 11 7f7f7f
7 47 11 7f7f7f
8 47 11 7f7f7f
9 47 11 7f7f7f
10 47 11 7f7f7f
11 47 11 7f7f7f
0 32 12 7f7f7f
1 32 12 7f7f7f
2 32 12 7f7f7f
3 32 12 7f7f7f
4 32 12 7f7f7f
5 32 12 7f7f7f
6 32 12 7f7f7f
7 32 12 7f7f7f
8 32 12 7f7f7f
9 32 12 7f7f7f
10 32 12 7f7f7f
11 32 12 7f7f7f
12 32 12 7f7f7f
13 32 12 7f7f7f
14 32 12 7f7f7f
15 32 12 7f7f7f
0 33 12 7f7f7f
1 33 12 7f7f7f
2 33 12 7f7f7f
3 33 12 7f7f7f
4 33 12 7f7f7f
5 33 12 7f7f7f
6 33 12 7f7f7f
7 33 12 7f7f7f
8 33 12 7f7f7f
9 33 12 7f7f7f
10 33 12 7f7f7f
11 33 12 7f7f7f
12 33 12 7f7f7f
13 33 12 7f7f7f
14 33 12 7f7f7f
15 33 12 7f7f7f
0 34 12 7f7f7f
1 34 12 7f7f7f
2 34 12 7f7f7f
3 34 12 7f7f7f
4 34 12 7f7f7f
5 34 12 7f7f7f
6 34 12 7f7f7f
7 34 12 7f7f7f
8 34 12 7f7f7f
9 34 12 7f7f7f
10 34 12 7f7f7f
11 34 12 7f7f7f
12 34 12 7f7f7f
13 34 12 7f7f7f
14 34 12 7f7f7f
15 34 12 7f7f7f
0 35 12 7f7f7f
1 35 12 7f7f7f
2 35 12 7f7f7f
3 35 12 7f7f7f
4 35 12 7f7f7f
5 35 12 7f7f7f
6 35 12 7f7f7f
7 35 12 7f7f7f
8 35 12 7f7f7f
9 35 12 7f7f7f
10 35 12 7f7f7f
11 35 12 7f7f7f
12 35 12 7f7f7f
13 35 12 7f7f7f
14 35 12 7f7f7f
15 35 12 7f7f7f
0 36 12 7f7f7f
1 36 12 7f7f7f
2 36 12 7f7f7f
3 36 12 7f7f7f
4 36 12 7f7f7f
5 36 12 7f7f7f
6 36 12 7f7f7f
7 36 12 7f7f7f
8 36 12 7f7f7f
9 36 12 7f7f7f
10 36 12 7f7f7f
11 36 12 7f7f7f
12 36 12 7f7f7f
13 36 12 7f7f7f
14 36 12 7f7f7f
15 36 12 7f7f7f
0 37 12 7f7f7f
1 37 12 7f7f7f
2 37 12 7f7f7f
3 37 12 7f7f7f
4 37 12 7f7f7f
5 37 12 7f7f7f
6 37 12 7f7f7f
7 37 12 7f7f7f
8 37 12 7f7f7f
9 37 12 7f7f7f
10 37 12 7f7f7f
11 37 12 7f7f7f
12 37 12 7f7f7f
13 37 12 7f7f7f
14 37 12 7f7f7f
15 37 12 7f7f7f
0 38 12 7f7f7f
1 38 12 7f7f7f
2 38 12 7f7f7f
3 38 12 7f7f7f
4 38 12 7f7f7f
5 38 12 7f7f7f
6 38 12 7f7f7f
7 38 12 7f7f7f
8 38 12 7f7f7f
9 38 12 7f7f7f
10 38 12 7f7f7f
11 38 12 7f7f7f
12 38 12 7f7f7f
13 38 12 7f7f7f
14 38 12 7f7f7f
15 38 12 7f7f7f
0 39 12 7f7f7f
1 39 12 7f7f7f
2 39 12 7f7f7f
3 39 12 7f7f7f
4 39 12 7f7f7f
5 39 12 7f7f7f
6 39 12 7f7f7f
7 39 12 7f7f7f
8 39 12 7f7f7f
9 39 12 7f7f7f
10 39 12 7f7f7f
11 39 12 7f7f7f
12 39 12 7f7f7f
13 39 12 7f7f7f
14 39 12 7f7f7f
15 39 12 7f7f7f
0 40 12 7f7f7f
1 40 12 7f7f7f
2 40 12 7f7f7f
3 40 12 7f7f7f
4 40 12 7f7f7f
5 40 12 7f7f7f
6 40 12 7f7f7f
7 40 12 7f7f7f
8 40 12 7f7f7f
9 40 12 7f7f7f
10 40 12 7f7f7f
11 40 12 7f7f7f
0 41 12 7f7f7f
1 41 12 7f7f7f
2 41 12 7f7f7f
3 41 12 7f7f7f
4 41 12 7f7f7f
5 41 12 7f7f7f
6 41 12 7f7f7f
7 41 12 7f7f7f
8 41 12 7f7f7f
9 41 12 7f7f7f
10 41 12 7f7f7f
11 41 12 7f7f7f
0 42 12 7f7f7f
1 42 12 7f7f7f
2 42 12 7f7f7f
3 42 12 7f7f7f
4 42 12 7f7f7f
5 42 12 7f7f7f
6 42 12 7f7f7f
7 42 12 7f7f7f
8 42 12 7f7f7f
9 42 12 7f7f7f
10 42 12 7f7f7f
11 42 12 7f7f7f
0 43 12 7f7f7f
1 43 12 7f7f7f
2 43 12 7f7f7f
3 43 12 7f7f7f
4 43 12 7f7f7f
5 43 12 7f7f7f
6 43 12 7f7f7f
7 43 12 7f7f7f
8 43 12 7f7f7f
9 43 12 7f7f7f
10 43 12 7f7f7f
11 43 12 7f7f7f
0 44 12 7f7f7f
1 44 12 7f7f7f
2 44 12 7f7f7f
3 44 12 7f7f7f
4 44 12 7f7f7f
5 44 12 7f7f7f
6 44 12 7f7f7f
7 44 12 7f7f7f
8 44 12 7f7f7f
9 44 12 7f7f7f
10 44 12 7f7f7f
11 44 12 7f7f7f
0 45 12 7f7f7f
1 45 12 7f7f7f
2 45 12 7f7f7f
3 45 12 7f7f7f
4 45 12 7f7f7f
5 45 12 7f7f7f
6 45 12 7f7f7f
7 45 12 7f7f7f
8 45 12 7f7f7f
9 45 12 7f7f7f
10 45 12 7f7f7f
11 45 12 7f7f7f
0 46 12 7f7f7f
1 46 12 7f7f7f
2 46 12 7f7f7f
3 46 12 7f7f7f
4 46 12 7f7f7f
5 46 12 7f7f7f
6 46 12 7f7f7f
7 46 12 7f7f7f
8 46 12 7f7f7f
9 46 12 7f7f7f
10 46 12 7f7f7f
11 46 12 7f7f7f
0 47 12 7f7f7f
1 47 12 7f7f7f
2 47 12 7f7f7f
3 47 12 7f7f7f
4 47 12 7f7f7f
5 47 12 7f7f7f
6 47 12 7f7f7f
7 47 12 7f7f7f
8 47 12 7f7f7f
9 47 12 7f7f7f
10 47 12 7f7f7f
11 47 12 7f7f7f
0 32 13 7f7f7f
1 32 13 7f7f7f
2 32 13 7f7f7f
3 32 13 7f7f7f
4 32 13 7f7f7f
5 32 13 7f7f7f
6 32 13 7f7f7f
7 32 13 7f7f7f
8 32 13 7f7f7f
9 32 13 7f7f7f
10 32 13 7f7f7f
11 32 13 7f7f7f
12 32 13 7f7f7f
13 32 13 7f7f7f
14 32 13 7f7f7f
15 32 13 7f7f7f
0 33 13 7f7f7f
1 33 13 7f7f7f
2 33 13 7f7f7f
3 33 13 7f7f7f
4 33 13 7f7f7f
5 33 13 7f7f7f
6 33 13 7f7f7f
7 33 13 7f7f7f
8 33 13 7f7f7f
9 33 13 7f7f7f
10 33 13 7f7f7f
11 33 13 7f7f7f
12 33 13 7f7f7f
13 33 13 7f7f7f
14 33 13 7f7f7f
15 33 13 7f7f7f
0 34 13 7f7f7f
1 34 13 7f7f7f
2 34 13 7f7f7f
3 34 13 7f7f7f
4 34 13 7f7f7f
5 34 13 7f7f7f
6 34 13 7f7f7f
7 34 13 7f7f7f
8 34 13 7f7f7f
9 34 13 7f7f7f
10 34 13 7f7f7f
11 34 13 7f7f7f
12 34 13 7f7f7f
13 34 13 7f7f7f
14 34 13 7f7f7f
15 34 13 7f7f7f
0 35 13 7f7f7f
1 35 13 7f7f7f
2 35 13 7f7f7f
3 35 13 7f7f7f
4 35 13 7f7f7f
5 35 13 7f7f7f
6 35 13 7f7f7f
7 35 13 7f7f7f
8 35 13 7f7f7f
9 35 13 7f7f7f
10 35 13 7f7f7f
11 35 13 7f7f7f
12 35 13 7f7f7f
13 35 13 7f7f7f
14 35 13 7f7f7f
15 35 13 7f7f7f
0 36 13 7f7f7f
1 36 13 7f7f7f
2 36 13 7f7f7f
3 36 13 7f7f7f
4 36 13 7f7f7f
5 36 13 7f7f7f
6 36 13 7f7f7f
7 36 13 7f7f7f
8 36 13 7f7f7f
9 36 13 7f7f7f
10 36 13 7f7f7f
11 36 13 7f7f7f
12 36 13 7f7f7f
13 36 13 7f7f7f
14 36 13 7f7f7f
15 36 13 7f7f7f
0 37 13 7f7f7f
1 37 13 7f7f7f
2 37 13 7f7f7f
3 37 13 7f7f7f
4 37 13 7f7f7f
5 37 13 7f7f7f
6 37 13 7f7f7f
7 37 13 7f7f7f
8 37 13 7f7f7f
9 37 13 7f7f7f
10 37 13 7f7f7f
11 37 13 7f7f7f
12 37 13 7f7f7f
13 37 13 7f7f7f
14 37 13 7f7f7f
15 37 13 7f7f7f
0 38 13 7f7f7f
1 38 13 7f7f7f
2 38 13 7f7f7f
3 38 13 7f7f7f
4 38 13 7f7f7f
5 38 13 7f7f7f
6 38 13 7f7f7f
7 38 13 7f7f7f
8 38 13 7f7f7f
9 38 13 7f7f7f
10 38 13 7f7f7f
11 38 13 7f7f7f
12 38 13 7f7f7f
13 38 13 7f7f7f
14 38 13 7f7f7f
15 38 13 7f7f7f
0 39 13 7f7f7f
1 39 13 7f7f7f
2 39 13 7f7f7f
3 39 13 7f7f7f
4 39 13 7f7f7f
5 39 13 7f7f7f
6 39 13 7f7f7f
7 39 13 7f7f7f
8 39 13 7f7f7f
9 39 13 7f7f7f
10 39 13 7f7f7f
11 39 13 7f7f7f
12 39 13 7f7f7f
13 39 13 7f7f7f
14 39 13 7f7f7f
15 39 13 7f7f7f
0 40 13 7f7f7f
1 40 13 7f7f7f
2 40 13 7f7f7f
3 40 13 7f7f7f
4 40 13 7f7f7f
5 40 13 7f7f7f
6 40 13 7f7f7f
7 40 13 7f7f7f
8 40 13 7f7f7f
9 40 13 7f7f7f
10 40 13 7f7f7f
11 40 13 7f7f7f
0 41 13 7f7f7f
1 41 13 7f7f7f
2 41 13 7f7f7f
3 41 13 7f7f7f
4 41 13 7f7f7f
5 41 13 7f7f7f
6 41 13 7f7f7f
7 41 13 7f7f7f
8 41 13 7f7f7f
9 41 13 7f7f7f
10 41 13 7f7f7f
11 41 13 7f7f7f
0 42 13 7f7f7f
1 42 13 7f7f7f
2 42 13 7f7f7f
3 42 13 7f7f7f
4 42 13 7f7f7f
5 42 13 7f7f7f
6 42 13 7f7f7f
7 42 13 7f7f7f
8 42 13 7f7f7f
9 42 13 7f7f7f
10 42 13 7f7f7f
11 42 13 7f7f7f
0 43 13 7f7f7f
1 43 13 7f7f7f
2 43 13 7f7f7f
3 43 13 7f7f7f
4 43 13 7f7f7f
5 43 13 7f7f7f
6 43 13 7f7f7f
7 43 13 7f7f7f
8 43 13 7f7f7f
9 43 13 7f7f7f
10 43 13 7f7f7f
11 43 13 7f7f7f
0 44 13 7f7f7f
1 44 13 7f7f7f
2 44 13 7f7f7f
3 44 13 7f7f7f
4 44 13 7f7f7f
5 44 13 7f7f7f
6 44 13 7f7f7f
7 44 13 7f7f7f
8 44 13 7f7f7f
9 44 13 7f7f7f
10 44 13 7f7f7f
11 44 13 7f7f7f
0 45 13 7f7f7f
1 45 13 7f7f7f
2 45 13 7f7f7f
3 45 13 7f7f7f
4 45 13 7f7f7f
5 45 13 7f7f7f
6 45 13 7f7f7f
7 45 13 7f7f7f
8 45 13 7f7f7f
9 45 13 7f7f7f
10 45 13 7f7f7f
11 45 13 7f7f7f
0 46 13 7f7f7f
1 46 13 7f7f7f
2 46 13 7f7f7f
3 46 13 7f7f7f
4 46 13 7f7f7f
5 46 13 7f7f7f
6 46 13 7f7f7f
7 46 13 7f7f7f
8 46 13 7f7f7f
9 46 13 7f7f7f
10 46 13 7f7f7f
11 46 13 7f7f7f
0 47 13 7f7f7f
1 47 13 7f7f7f
2 47 13 7f7f7f
3 47 13 7f7f7f
4 47 13 7f7f7f
5 47 13 7f7f7f
6 47 13 7f7f7f
7 47 13 7f7f7f
8 47 13 7f7f7f
9 47 13 7f7f7f
10 47 13 7f7f7f
11 47 13 7f7f7f
0 32 14 7f7f7f
1 32 14 7f7f7f
2 32 14 7f7f7f
3 32 14 7f7f7f
4 32 14 7f7f7f
5 32 14 7f7f7f
6 32 14 7f7f7f
7 32 14 7f7f7f
8 32 14 7f7f7f
9 32 14 7f7f7f
10 32 14 7f7f7f
11 32 14 7f7f7f
12 32 14 7f7f7f
13 32 14 7f7f7f
14 32 14 7f7f7f
15 32 14 7f7f7f
0 33 14 7f7f7f
1 33 14 7f7f7f
2 33 14 7f7f7f
3 33 14 7f7f7f
4 33 14 7f7f7f
5 33 14 7f7f7f
6 33 14 7f7f7f
7 33 14 7f7f7f
8 33 14 7f7f7f
9 33 14 7f7f7f
10 33 14 7f7f7f
11 33 14 7f7f7f
12 33 14 7f7f7f
13 33 14 7f7f7f
14 33 14 7f7f7f
15 33 14 7f7f7f
0 34 14 7f7f7f
1 34 14 7f7f7f
2 34 14 7f7f7f
3 34 14 7f7f7f
4 34 14 7f7f7f
5 34 14 7f7f7f
6 34 14 7f7f7f
7 34 14 7f7f7f
8 34 14 7f7f7f
9 34 14 7f7f7f
10 34 14 7f7f7f
11 34 14 7f7f7f
12 34 14 7f7f7f
13 34 14 7f7f7f
14 34 14 7f7f7f
15 34 14 7f7f7f
0 35 14 7f7f7f
1 35 14 7f7f7f
2 35 14 7f7f7f
3 35 14 7f7f7f
4 35 14 7f7f7f
5 35 14 7f7f7f
6 35 14 7f7f7f
7 35 14 7f7f7f
8 35 14 7f7f7f
9 35 14 7f7f7f
10 35 14 7f7f7f
11 35 14 7f7f7f
12 35 14 7f7f7f
13 35 14 7f7f7f
14 35 14 7f7f7f
15 35 14 7f7f7f
0 36 14 7f7f7f
1 36 14 7f7f7f
2 36 14 7f7f7f
3 36 14 7f7f7f
4 36 14 7f7f7f
5 36 14 7f7f7f
6 36 14 7f7f7f
7 36 14 7f7f7f
8 36 14 7f7f7f
9 36 14 7f7f7f
10 36 14 7f7f7f
11 36 14 7f7f7f
12 36 14 7f7f7f
13 36 14 7f7f7f
14 36 14 7f7f7f
15 36 14 7f7f7f
0 37 14 7f7f7f
1 37 14 7f7f7f
2 37 14 7f7f7f
3 37 14 7f7f7f
4 37 14 7f7f7f
5 37 14 7f7f7f
6 37 14 7f7f7f
7 37 14 7f7f7f
8 37 14 7f7f7f
9 37 14 7f7f7f
10 37 14 7f7f7f
11 37 14 7f7f7f
12 37 14 7f7f7f
13 37 14 7f7f7f
14 37 14 7f7f7f
15 37 14 7f7f7f
0 38 14 7f7f7f
1 38 14 7f7f7f
2 38 14 7f7f7f
3 38 14 7f7f7f
4 38 14 7f7f7f
5 38 14 7f7f7f
6 38 14 7f7f7f
7 38 14 7f7f7f
8 38 14 7f7f7f
9 38 14 7f7f7f
10 38 14 7f7f7f
11 38 14 7f7f7f
12 38 14 7f7f7f
13 38 14 7f7f7f
14 38 14 7f7f7f
15 38 14 7f7f7f
0 39 14 7f7f7f
1 39 14 7f7f7f
2 39 14 7f7f7f
3 39 14 7f7f7f
4 39 14 7f7f7f
5 39 14 7f7f7f
6 39 14 7f7f7f
7 39 14 7f7f7f
8 39 14 7f7f7f
9 39 14 7f7f7f
10 39 14 7f7f7f
11 39 14 7f7f7f
12 39 14 7f7f7f
13 39 14 7f7f7f
14 39 14 7f7f7f
15 39 14 7f7f7f
0 40 14 7f7f7f
1 40 14 7f7f7f
2 40 14 7f7f7f
3 40 14 7f7f7f
4 40 14 7f7f7f
5 40 14 7f7f7f
6 40 14 7f7f7f
7 40 14 7f7f7f
8 40 14 7f7f7f
9 40 14 7f7f7f
10 40 14 7f7f7f
11 40 14 7f7f7f
0 41 14 7f7f7f
1 41 14 7f7f7f
2 41 14 7f7f7f
3 41 14 7f7f7f
4 41 14 7f7f7f
5 41 14 7f7f7f
6 41 14 7f7f7f
7 41 14 7f7f7f
8 41 14 7f7f7f
9 41 14 7f7f7f
10 41 14 7f7f7f
11 41 14 7f7f7f
0 42 14 7f7f7f
1 42 14 7f7f7f
2 42 14 7f7f7f
3 42 14 7f7f7f
4 42 14 7f7f7f
5 42 14 7f7f7f
6 42 14 7f7f7f
7 42 14 7f7f7f
8 42 14 7f7f7f
9 42 14 7f7f7f
10 42 14 7f7f7f
11 42 14 7f7f7f
0 43 14 7f7f7f
1 43 14 7f7f7f
2 43 14 7f7f7f
3 43 14 7f7f7f
4 43 14 7f7f7f
5 43 14 7f7f7f
6 43 14 7f7f7f
7 43 14 7f7f7f
8 43 14 7f7f7f
9 43 14 7f7f7f
10 43 14 7f7f7f
11 43 14 7f7f7f
0 44 14 7f7f7f
1 44 14 7f7f7f
2 44 14 7f7f7f
3 44 14 7f7f7f
4 44 14 7f7f7f
5 44 14 7f7f7f
6 44 14 7f7f7f
7 44 14 7f7f7f
8 44 14 7f7f7f
9 44 14 7f7f7f
10 44 14 7f7f7f
11 44 14 7f7f7f
0 45 14 7f7f7f
1 45 14 7f7f7f
2 45 14 7f7f7f
3 45 14 7f7f7f
4 45 14 7f7f7f
5 45 14 7f7f7f
6 45 14 7f7f7f
7 45 14 7f7f7f
8 45 14 7f7f7f
9 45 14 7f7f7f
10 45 14 7f7f7f
11 45 14 7f7f7f
0 46 14 7f7f7f
1 46 14 7f7f7f
2 46 14 7f7f7f
3 46 14 7f7f7f
4 46 14 7f7f7f
5 46 14 7f7f7f
6 46 14 7f7f7f
7 46 14 7f7f7f
8 46 14 7f7f7f
9 46 14 7f7f7f
10 46 14 7f7f7f
11 46 14 7f7f7f
0 47 14 7f7f7f
1 47 14 7f7f7f
2 47 14 7f7f7f
3 47 14 7f7f7f
4 47 14 7f7f7f
5 47 14 7f7f7f
6 47 14 7f7f7f
7 47 14 7f7f7f
8 47 14 7f7f7f
9 47 14 7f7f7f
10 47 14 7f7f7f
11 47 14 7f7f7f
0 32 15 7f7f7f
1 32 15 7f7f7f
2 32 15 7f7f7f
3 32 15 7f7f7f
4 32 15 7f7f7f
5 32 15 7f7f7f
6 32 15 7f7f7f
7 32 15 7f7f7f
8 32 15 7f7f7f
9 32 15 7f7f7f
10 32 15 7f7f7f
11 32 15 7f7f7f
12 32 15 7f7f7f
13 32 15 7f7f7f
14 32 15 7f7f7f
15 32 15 7f7f7f
0 33 15 7f7f7f
1 33 15 7f7f7f
2 33 15 7f7f7f
3 33 15 7f7f7f
4 33 15 7f7f7f
5 33 15 7f7f7f
6 33 15 7f7f7f
7 33 15 7f7f7f
8 33 15 7f7f7f
9 33 15 7f7f7f
10 33 15 7f7f7f
11 33 15 7f7f7f
12 33 15 7f7f7f
13 33 15 7f7f7f
14 33 15 7f7f7f
15 33 15 7f7f7f
0 34 15 7f7f7f
1 34 15 7f7f7f
2 34 15 7f7f7f
3 34 15 7f7f7f
4 34 15 7f7f7f
5 34 15 7f7f7f
6 34 15 7f7f7f
7 34 15 7f7f7f
8 34 15 7f7f7f
9 34 15 7f7f7f
10 34 15 7f7f7f
11 34 15 7f7f7f
12 34 15 7f7f7f
13 34 15 7f7f7f
14 34 15 7f7f7f
15 34 15 7f7f7f
0 35 15 7f7f7f
1 35 15 7f7f7f
2 35 15 7f7f7f
3 35 15 7f7f7f
4 35 15 7f7f7f
5 35 15 7f7f7f
6 35 15 7f7f7f
7 35 15 7f7f7f
8 35 15 7f7f7f
9 35 15 7f7f7f
10 35 15 7f7f7f
11 35 15 7f7f7f
12 35 15 7f7f7f
13 35 15 7f7f7f
14 35 15 7f7f7f
15 35 15 7f7f7f
0 36 15 7f7f7f
1 36 15 7f7f7f
2 36 15 7f7f7f
3 36 15 7f7f7f
4 36 15 7f7f7f
5 36 15 7f7f7f
6 36 15 7f7f7f
7 36 15 7f7f7f
8 36 15 7f7f7f
9 36 15 7f7f7f
10 36 15 7f7f7f
11 36 15 7f7f7f
12 36 15 7f7f7f
13 36 15 7f7f7f
14 36 15 7f7f7f
15 36 15 7f7f7f
0 37 15 7f7f7f
1 37 15 7f7f7f
2 37 15 7f7f7f
3 37 15 7f7f7f
4 37 15 7f7f7f
5 37 15 7f7f7f
6 37 15 7f7f7f
7 37 15 7f7f7f
8 37 15 7f7f7f
9 37 15 7f7f7f
10 37 15 7f7f7f
11 37 15 7f7f7f
12 37 15 7f7f7f
13 37 15 7f7f7f
14 37 15 7f7f7f
15 37 15 7f7f7f
0 38 15 7f7f7f
1 38 15 7f7f7f
2 38 15 7f7f7f
3 38 15 7f7f7f
4 38 15 7f7f7f
5 38 15 7f7f7f
6 38 15 7f7f7f
7 38 15 7f7f7f
8 38 15 7f7f7f
9 38 15 7f7f7f
10 38 15 7f7f7f
11 38 15 7f7f7f
12 38 15 7f7f7f
13 38 15 7f7f7f
14 38 15 7f7f7f
15 38 15 7f7f7f
0 39 15 7f7f7f
1 39 15 7f7f7f
2 39 15 7f7f7f
3 39 15 7f7f7f
4 39 15 7f7f7f
5 39 15 7f7f7f
6 39 15 7f7f7f
7 39 15 7f7f7f
8 39 15 7f7f7f
9 39 15 7f7f7f
10 39 15 7f7f7f
11 39 15 7f7f7f
12 39 15 7f7f7f
13 39 15 7f7f7f
14 39 15 7f7f7f
15 39 15 7f7f7f
0 40 15 7f7f7f
1 40 15 7f7f7f
2 40 15 7f7f7f
3 40 15 7f7f7f
4 40 15 7f7f7f
5 40 15 7f7f7f
6 40 15 7f7f7f
7 40 15 7f7f7f
8 40 15 7f7f7f
9 40 15 7f7f7f
10 40 15 7f7f7f
11 40 15 7f7f7f
0 41 15 7f7f7f
1 41 15 7f7f7f
2 41 15 7f7f7f
3 41 15 7f7f7f
4 41 15 7f7f7f
5 41 15 7f7f7f
6 41 15 7f7f7f
7 41 15 7f7f7f
8 41 15 7f7f7f
9 41 15 7f7f7f
10 41 15 7f7f7f
11 41 15 7f7f7f
0 42 15 7f7f7f
1 42 15 7f7f7f
2 42 15 7f7f7f
3 42 15 7f7f7f
4 42 15 7f7f7f
5 42 15 7f7f7f
6 42 15 7f7f7f
7 42 15 7f7f7f
8 42 15 7f7f7f
9 42 15 7f7f7f
10 42 15 7f7f7f
11 42 15 7f7f7f
0 43 15 7f7f7f
1 43 15 7f7f7f
2 43 15 7f7f7f
3 43 15 7f7f7f
4 43 15 7f7f7f
5 43 15 7f7f7f
6 43 15 7f7f7f
7 43 15 7f7f7f
8 43 15 7f7f7f
9 43 15 7f7f7f
10 43 15 7f7f7f
11 43 15 7f7f7f
0 44 15 7f7f7f
1 44 15 7f7f7f
2 44 15 7f7f7f
3 44 15 7f7f7f
4 44 15 7f7f7f
5 44 15 7f7f7f
6 44 15 7f7f7f
7 44 15 7f7f7f
8 44 15 7f7f7f
9 44 15 7f7f7f
10 44 15 7f7f7f
11 44 15 7f7f7f
0 45 15 7f7f7f
1 45 15 7f7f7f
2 45 15 7f7f7f
3 45 15 7f7f7f
4 45 15 7f7f7f
5 45 15 7f7f7f
6 45 15 7f7f7f
7 45 15 7f7f7f
8 45 15 7f7f7f
9 45 15 7f7f7f
10 45 15 7f7f7f
11 45 15 7f7f7f
0 46 15 7f7f7f
1 46 15 7f7f7f
2 46 15 7f7f7f
3 46 15 7f7f7f
4 46 15 7f7f7f
5 46 15 7f7f7f
6 46 15 7f7f7f
7 46 15 7f7f7f
8 46 15 7f7f7f
9 46 15 7f7f7f
10 46 15 7f7f7f
11 46 15 7f7f7f
0 47 15 7f7f7f
1 47 15 7f7f7f
2 47 15 7f7f7f
3 47 15 7f7f7f
4 47 15 7f7f7f
5 47 15 7f7f7f
6 47 15 7f7f7f
7 47 15 7f7f7f
8 47 15 7f7f7f
9 47 15 7f7f7f
10 47 15 7f7f7f
11 47 15 7f7f7f
16 32 0 3f3f3f
17 32 0 3f3f3f
18 32 0 3f3f3f
19 32 0 3f3f3f
20 32 0 3f3f3f
21 32 0 3f3f3f
22 32 0 3f3f3f
23 32 0 3f3f3f
24 32 0 3f3f3f
25 32 0 3f3f3f
26 32 0 3f3f3f
27 32 0 3f3f3f
28 32 0 3f3f3f
29 32 0 3f3f3f
30 32 0 3f3f3f
31 32 0 3f3f3f
16 33 0 3f3f3f
17 33 0 3f3f3f
18 33 0 3f3f3f
19 33 0 3f3f3f
20 33 0 3f3f3f
21 33 0 3f3f3f
22 33 0 3f3f3f
23 33 0 3f3f3f
24 33 0 3f3f3f
25 33 0 3f3f3f
26 33 0 3f3f3f
27 33 0 3f3f3f
28 33 0 3f3f3f
29 33 0 3f3f3f
30 33 0 3f3f3f
31 33 0 3f3f3f
16 34 0 3f3f3f
17 34 0 3f3f3f
18 34 0 3f3f3f
19 34 0 3f3f3f
20 34 0 3f3f3f
21 34 0 3f3f3f
22 34 0 3f3f3f
23 34 0 3f3f3f
24 34 0 3f3f3f
25 34 0 3f3f3f
26 34 0 3f3f3f
27 34 0 3f3f3f
28 34 0 3f3f3f
29 34 0 3f3f3f
30 34 0 3f3f3f
31 34 0 3f3f3f
16 35 0 3f3f3f
17 35 0 3f3f3f
18 35 0 3f3f3f
19 35 0 3f3f3f
20 35 0 3f3f3f
21 35 0 3f3f3f
22 35 0 3f3f3f
23 35 0 3f3f3f
24 35 0 3f3f3f
25 35 0 3f3f3f
26 35 0 3f3f3f
27 35 0 3f3f3f
28 35 0 3f3f3f
29 35 0 3f3f3f
30 35 0 3f3f3f
31 35 0 3f3f3f
16 36 0 3f3f3f
17 36 0 3f3f3f
18 36 0 3f3f3f
19 36 0 3f3f3f
20 36 0 3f3f3f
21 36 0 3f3f3f
22 36 0 3f3f3f
23 36 0 3f3f3f
24 36 0 3f3f3f
25 36 0 3f3f3f
26 36 0 3f3f3f
27 36 0 3f3f3f
28 36 0 3f3f3f
29 36 0 3f3f3f
30 36 0 3f3f3f
31 36 0 3f3f3f
16 37 0 3f3f3f
17 37 0 3f3f3f
18 37 0 3f3f3f
19 37 0 3f3f3f
20 37 0 3f3f3f
21 37 0 3f3f3f
22 37 0 3f3f3f
23 37 0 3f3f3f
24 37 0 3f3f3f
25 37 0 3f3f3f
26 37 0 3f3f3f
27 37 0 3f3f3f
28 37 0 3f3f3f
29 37 0 3f3f3f
30 37 0 3f3f3f
31 37 0 3f3f3f
16 38 0 3f3f3f
17 38 0 3f3f3f
18 38 0 3f3f3f
19 38 0 3f3f3f
20 38 0 3f3f3f
21 38 0 3f3f3f
22 38 0 3f3f3f
23 38 0 3f3f3f
24 38 0 3f3f3f
25 38 0 3f3f3f
26 38 0 3f3f3f
27 38 0 3f3f3f
28 38 0 3f3f3f
29 38 0 3f3f3f
30 38 0 3f3f3f
31 38 0 3f3f3f
16 39 0 3f3f3f
17 39 0 3f3f3f
18 39 0 3f3f3f
19 39 0 3f3f3f
20 39 0 3f3f3f
21 39 0 3f3f3f
22 39 0 3f3f3f
23 39 0 3f3f3f
24 39 0 3f3f3f
25 39 0 3f3f3f
26 39 0 3f3f3f
27 39 0 3f3f3f
28 39 0 3f3f3f
29 39 0 3f3f3f
30 39 0 3f3f3f
31 39 0 3f3f3f
16 40 0 3f3f3f
17 40 0 3f3f3f
18 40 0 3f3f3f
19 40 0 3f3f3f
20 40 0 3f3f3f
21 40 0 3f3f3f
22 40 0 3f3f3f
23 40 0 3f3f3f
24 40 0 3f3f3f
25 40 0 3f3f3f
26 40 0 3f3f3f
27 40 0 3f3f3f
28 40 0 3f3f3f
29 40 0 3f3f3f
30 40 0 3f3f3f
31 40 0 3f3f3f
16 41 0 3f3f3f
17 41 0 3f3f3f
18 41 0 3f3f3f
19 41 0 3f3f3f
20 41 0 3f3f3f
21 41 0 3f3f3f
22 41 0 3f3f3f
23 41 0 3f3f3f
24 41 0 3f3f3f
25 41 0 3f3f3f
26 41 0 3f3f3f
27 41 0 3f3f3f
28 41 0 3f3f3f
29 41 0 3f3f3f
30 41 0 3f3f3f
31 41 0 3f3f3f
16 42 0 3f3f3f
17 42 0 3f3f3f
18 42 0 3f3f3f
19 42 0 3f3f3f
20 42 0 3f3f3f
21 42 0 3f3f3f
22 42 0 3f3f3f
23 42 0 3f3f3f
24 42 0 3f3f3f
25 42 0 3f3f3f
26 42 0 3f3f3f
27 42 0 3f3f3f
28 42 0 3f3f3f
29 42 0 3f3f3f
30 42 0 3f3f3f
31 42 0 3f3f3f
16 43 0 3f3f3f
17 43 0 3f3f3f
18 43 0 3f3f3f
19 43 0 3f3f3f
20 43 0 3f3f3f
21 43 0 3f3f3f
22 43 0 3f3f3f
23 43 0 3f3f3f
24 43 0 3f3f3f
25 43 0 3f3f3f
26 43 0 3f3f3f
27 43 0 3f3f3f
28 43 0 3f3f3f
29 43 0 3f3f3f
30 43 0 3f3f3f
31 43 0 3f3f3f
16 44 0 3f3f3f
17 44 0 3f3f3f
18 44 0 3f3f3f
19 44 0 3f3f3f
20 44 0 3f3f3f
21 44 0 3f3f3f
22 44 0 3f3f3f
23 44 0 3f3f3f
24 44 0 3f3f3f
25 44 0 3f3f3f
26 44 0 3f3f3f
27 44 0 3f3f3f
28 44 0 3f3f3f
29 44 0 3f3f3f
30 44 0 3f3f3f
31 44 0 3f3f3f
16 45 0 3f3f3f
17 45 0 3f3f3f
18 45 0 3f3f3f
19 45 0 3f3f3f
20 45 0 3f3f3f
21 45 0 3f3f3f
22 45 0 3f3f3f
23 45 0 3f3f3f
24 45 0 3f3f3f
25 45 0 3f3f3f
26 45 0 3f3f3f
27 45 0 3f3f3f
28 45 0 3f3f3f
29 45 0 3f3f3f
30 45 0 3f3f3f
31 45 0 3f3f3f
16 46 0 3f3f3f
17 46 0 3f3f3f
18 46 0 3f3f3f
19 46 0 3f3f3f
20 46 0 3f3f3f
21 46 0 3f3f3f
22 46 0 3f3f3f
23 46 0 3f3f3f
24 46 0 3f3f3f
25 46 0 3f3f3f
26 46 0 3f3f3f
27 46 0 3f3f3f
28 46 0 3f3f3f
29 46 0 3f3f3f
30 46 0 3f3f3f
31 46 0 3f3f3f
16 47 0 3f3f3f
17 47 0 3f3f3f
18 47 0 3f3f3f
19 47 0 3f3f3f
20 47 0 3f3f3f
21 47 0 3f3f3f
22 47 0 3f3f3f
23 47 0 3f3f3f
24 47 0 3f3f3f
25 47 0 3f3f3f
26 47 0 3f3f3f
27 47 0 3f3f3f
28 47 0 3f3f3f
29 47 0 3f3f3f
30 47 0 3f3f3f
31 47 0 3f3f3f
16 32 1 3f3f3f
17 32 1 3f3f3f
18 32 1 3f3f3f
19 32 1 3f3f3f
20 32 1 3f3f3f
21 32 1 3f3f3f
22 32 1 3f3f3f
23 32 1 3f3f3f
24 32 1 3f3f3f
25 32 1 3f3f3f
26 32 1 3f3f3f
27 32 1 3f3f3f
28 32 1 3f3f3f
29 32 1 3f3f3f
30 32 1 3f3f3f
31 32 1 3f3f3f
16 33 1 3f3f3f
17 33 1 3f3f3f
18 33 1 3f3f3f
19 33 1 3f3f3f
20 33 1 3f3f3f
21 33 1 3f3f3f
22 33 1 3f3f3f
23 33 1 3f3f3f
24 33 1 3f3f3f
25 33 1 3f3f3f
26 33 1 3f3f3f
27 33 1 3f3f3f
28 33 1 3f3f3f
29 33 1 3f3f3f
30 33 1 3f3f3f
31 33 1 3f3f3f
16 34 1 3f3f3f
17 34 1 3f3f3f
18 34 1 3f3f3f
19 34 1 3f3f3f
20 34 1 3f3f3f
21 34 1 3f3f3f
22 34 1 3f3f3f
23 34 1 3f3f3f
24 34 1 3f3f3f
25 34 1 3f3f3f
26 34 1 3f3f3f
27 34 1 3f3f3f
28 34 1 3f3f3f
29 34 1 3f3f3f
30 34 1 3f3f3f
31 34 1 3f3f3f
16 35 1 3f3f3f
17 35 1 3f3f3f
18 35 1 3f3f3f
19 35 1 3f3f3f
20 35 1 3f3f3f
21 35 1 3f3f3f
22 35 1 3f3f3f
23 35 1 3f3f3f
24 35 1 3f3f3f
25 35 1 3f3f3f
26 35 1 3f3f3f
27 35 1 3f3f3f
28 35 1 3f3f3f
29 35 1 3f3f3f
30 35 1 3f3f3f
31 35 1 3f3f3f
16 36 1 3f3f3f
17 36 1 3f3f3f
18 36 1 3f3f3f
19 36 1 3f3f3f
20 36 1 3f3f3f
21 36 1 3f3f3f
22 36 1 3f3f3f
23 36 1 3f3f3f
24 36 1 3f3f3f
25 36 1 3f3f3f
26 36 1 3f3f3f
27 36 1 3f3f3f
28 36 1 3f3f3f
29 36 1 3f3f3f
30 36 1 3f3f3f
31 36 1 3f3f3f
16 37 1 3f3f3f
17 37 1 3f3f3f
18 37 1 3f3f3f
19 37 1 3f3f3f
20 37 1 3f3f3f
21 37 1 3f3f3f
22 37 1 3f3f3f
23 37 1 3f3f3f
24 37 1 3f3f3f
25 37 1 3f3f3f
26 37 1 3f3f3f
27 37 1 3f3f3f
28 37 1 3f3f3f
29 37 1 3f3f3f
30 37 1 3f3f3f
31 37 1 3f3f3f
16 38 1 3f3f3f
17 38 1 3f3f3f
18 38 1 3f3f3f
19 38 1 3f3f3f
20 38 1 3f3f3f
21 38 1 3f3f3f
22 38 1 3f3f3f
23 38 1 3f3f3f
24 38 1 3f3f3f
25 38 1 3f3f3f
26 38 1 3f3f3f
27 38 1 3f3f3f
28 38 1 3f3f3f
29 38 1 3f3f3f
30 38 1 3f3f3f
31 38 1 3f3f3f
16 39 1 3f3f3f
17 39 1 3f3f3f
18 39 1 3f3f3f
19 39 1 3f3f3f
20 39 1 3f3f3f
21 39 1 3f3f3f
22 39 1 3f3f3f
23 39 1 3f3f3f
24 39 1 3f3f3f
25 39 1 3f3f3f
26 39 1 3f3f3f
27 39 1 3f3f3f
28 39 1 3f3f3f
29 39 1 3f3f3f
30 39 1 3f3f3f
31 39 1 3f3f3f
16 40 1 3f3f3f
17 40 1 3f3f3f
18 40 1 3f3f3f
19 40 1 3f3f3f
20 40 1 3f3f3f
21 40 1 3f3f3f
22 40 1 3f3f3f
23 40 1 3f3f3f
24 40 1 3f3f3f
25 40 1 3f3f3f
26 40 1 3f3f3f
27 40 1 3f3f3f
28 40 1 3f3f3f
29 40 1 3f3f3f
30 40 1 3f3f3f
31 40 1 3f3f3f
16 41 1 3f3f3f
17 41 1 3f3f3f
18 41 1 3f3f3f
19 41 1 3f3f3f
20 41 1 3f3f3f
21 41 1 3f3f3f
22 41 1 3f3f3f
23 41 1 3f3f3f
24 41 1 3f3f3f
25 41 1 3f3f3f
26 41 1 3f3f3f
27 41 1 3f3f3f
28 41 1 3f3f3f
29 41 1 3f3f3f
30 41 1 3f3f3f
31 41 1 3f3f3f
16 42 1 3f3f3f
17 42 1 3f3f3f
18 42 1 3f3f3f
19 42 1 3f3f3f
20 42 1 3f3f3f
21 42 1 3f3f3f
22 42 1 3f3f3f
23 42 1 3f3f3f
24 42 1 3f3f3f
25 42 1 3f3f3f
26 42 1 3f3f3f
27 42 1 3f3f3f
28 42 1 3f3f3f
29 42 1 3f3f3f
30 42 1 3f3f3f
31 42 1 3f3f3f
16 43 1 3f3f3f
17 43 1 3f3f3f
18 43 1 3f3f3f
19 43 1 3f3f3f
20 43 1 3f3f3f
21 43 1 3f3f3f
22 43 1 3f3f3f
23 43 1 3f3f3f
24 43 1 3f3f3f
25 43 1 3f3f3f
26 43 1 3f3f3f
27 43 1 3f3f3f
28 43 1 3f3f3f
29 43 1 3f3f3f
30 43 1 3f3f3f
31 43 1 3f3f3f
16 44 1 3f3f3f
17 44 1 3f3f3f
18 44 1 3f3f3f
19 44 1 3f3f3f
20 44 1 3f3f3f
21 44 1 3f3f3f
22 44 1 3f3f3f
23 44 1 3f3f3f
24 44 1 3f3f3f
25 44 1 3f3f3f
26 44 1 3f3f3f
27 44 1 3f3f3f
28 44 1 3f3f3f
29 44 1 3f3f3f
30 44 1 3f3f3f
31 44 1 3f3f3f
16 45 1 3f3f3f
17 45 1 3f3f3f
18 45 1 3f3f3f
19 45 1 3f3f3f
20 45 1 3f3f3f
21 45 1 3f3f3f
22 45 1 3f3f3f
23 45 1 3f3f3f
24 45 1 3f3f3f
25 45 1 3f3f3f
26 45 1 3f3f3f
27 45 1 3f3f3f
28 45 1 3f3f3f
29 45 1 3f3f3f
30 45 1 3f3f3f
31 45 1 3f3f3f
16 46 1 3f3f3f
17 46 1 3f3f3f
18 46 1 3f3f3f
19 46 1 3f3f3f
20 46 1 3f3f3f
21 46 1 3f3f3f
22 46 1 3f3f3f
23 46 1 3f3f3f
24 46 1 3f3f3f
25 46 1 3f3f3f
26 46 1 3f3f3f
27 46 1 3f3f3f
28 46 1 3f3f3f
29 46 1 3f3f3f
30 46 1 3f3f3f
31 46 1 3f3f3f
16 47 1 3f3f3f
17 47 1 3f3f3f
18 47 1 3f3f3f
19 47 1 3f3f3f
20 47 1 3f3f3f
21 47 1 3f3f3f
22 47 1 3f3f3f
23 47 1 3f3f3f
24 47 1 3f3f3f
25 47 1 3f3f3f
26 47 1 3f3f3f
27 47 1 3f3f3f
28 47 1 3f3f3f
29 47 1 3f3f3f
30 47 1 3f3f3f
31 47 1 3f3f3f
16 32 2 7f7f7f
17 32 2 7f7f7f
18 32 2 7f7f7f
19 32 2 7f7f7f
20 32 2 7f7f7f
21 32 2 7f7f7f
22 32 2 7f7f7f
23 32 2 7f7f7f
24 32 2 7f7f7f
25 32 2 7f7f7f
26 32 2 7f7f7f
27 32 2 7f7f7f
28 32 2 7f7f7f
29 32 2 7f7f7f
30 32 2 7f7f7f
31 32 2 7f7f7f
16 33 2 7f7f7f
17 33 2 7f7f7f
18 33 2 7f7f7f
19 33 2 7f7f7f
20 33 2 7f7f7f
21 33 2 7f7f7f
22 33 2 7f7f7f
23 33 2 7f7f7f
24 33 2 7f7f7f
25 33 2 7f7f7f
26 33 2 7f7f7f
27 33 2 7f7f7f
28 33 2 7f7f7f
29 33 2 7f7f7f
30 33 2 7f7f7f
31 33 2 7f7f7f
16 34 2 7f7f7f
17 34 2 7f7f7f
18 34 2 7f7f7f
19 34 2 7f7f7f
20 34 2 7f7f7f
21 34 2 7f7f7f
22 34 2 7f7f7f
23 34 2 7f7f7f
24 34 2 7f7f7f
25 34 2 7f7f7f
26 34 2 7f7f7f
27 34 2 7f7f7f
28 34 2 7f7f7f
29 34 2 7f7f7f
30 34 2 7f7f7f
31 34 2 7f7f7f
16 35 2 7f7f7f
17 35 2 7f7f7f
18 35 2 7f7f7f
19 35 2 7f7f7f
20 35 2 7f7f7f
21 35 2 7f7f7f
22 35 2 7f7f7f
23 35 2 7f7f7f
24 35 2 7f7f7f
25 35 2 7f7f7f
26 35 2 7f7f7f
27 35 2 7f7f7f
28 35 2 7f7f7f
29 35 2 7f7f7f
30 35 2 7f7f7f
31 35 2 7f7f7f
16 36 2 7f7f7f
17 36 2 7f7f7f
18 36 2 7f7f7f
19 36 2 7f7f7f
20 36 2 7f7f7f
21 36 2 7f7f7f
22 36 2 7f7f7f
23 36 2 7f7f7f
24 36 2 7f7f7f
25 36 2 7f7f7f
26 36 2 7f7f7f
27 36 2 7f7f7f
28 36 2 7f7f7f
29 36 2 7f7f7f
30 36 2 7f7f7f
31 36 2 7f7f7f
16 37 2 7f7f7f
17 37 2 7f7f7f
18 37 2 7f7f7f
19 37 2 7f7f7f
20 37 2 7f7f7f
21 37 2 7f7f7f
22 37 2 7f7f7f
23 37 2 7f7f7f
24 37 2 7f7f7f
25 37 2 7f7f7f
26 37 2 7f7f7f
27 37 2 7f7f7f
28 37 2 7f7f7f
29 37 2 7f7f7f
30 37 2 7f7f7f
31 37 2 7f7f7f
16 38 2 7f7f7f
17 38 2 7f7f7f
18 38 2 7f7f7f
19 38 2 7f7f7f
20 38 2 7f7f7f
21 38 2 7f7f7f
22 38 2 7f7f7f
23 38 2 7f7f7f
24 38 2 7f7f7f
25 38 2 7f7f7f
26 38 2 7f7f7f
27 38 2 7f7f7f
28 38 2 7f7f7f
29 38 2 7f7f7f
30 38 2 7f7f7f
31 38 2 7f7f7f
16 39 2 7f7f7f
17 39 2 7f7f7f
18 39 2 7f7f7f
19 39 2 7f7f7f
20 39 2 7f7f7f
21 39 2 7f7f7f
22 39 2 7f7f7f
23 39 2 7f7f7f
24 39 2 7f7f7f
25 39 2 7f7f7f
26 39 2 7f7f7f
27 39 2 7f7f7f
28 39 2 7f7f7f
29 39 2 7f7f7f
30 39 2 7f7f7f
31 39 2 7f7f7f
16 40 2 7f7f7f
17 40 2 7f7f7f
18 40 2 7f7f7f
19 40 2 7f7f7f
20 40 2 7f7f7f
21 40 2 7f7f7f
22 40 2 7f7f7f
23 40 2 7f7f7f
24 40 2 7f7f7f
25 40 2 7f7f7f
26 40 2 7f7f7f
27 40 2 7f7f7f
28 40 2 7f7f7f
29 40 2 7f7f7f
30 40 2 7f7f7f
31 40 2 7f7f7f
16 41 2 7f7f7f
17 41 2 7f7f7f
18 41 2 7f7f7f
19 41 2 7f7f7f
20 41 2 7f7f7f
21 41 2 7f7f7f
22 41 2 7f7f7f
23 41 2 7f7f7f
24 41 2 7f7f7f
25 41 2 7f7f7f
26 41 2 7f7f7f
27 41 2 7f7f7f
28 41 2 7f7f7f
29 41 2 7f7f7f
30 41 2 7f7f7f
31 41 2 7f7f7f
16 42 2 7f7f7f
17 42 2 7f7f7f
18 42 2 7f7f7f
19 42 2 7f7f7f
20 42 2 7f7f7f
21 42 2 7f7f7f
22 42 2 7f7f7f
23 42 2 7f7f7f
24 42 2 7f7f7f
25 42 2 7f7f7f
26 42 2 7f7f7f
27 42 2 7f7f7f
28 42 2 7f7f7f
29 42 2 7f7f7f
30 42 2 7f7f7f
31 42 2 7f7f7f
16 43 2 7f7f7f
17 43 2 7f7f7f
18 43 2 7f7f7f
19 43 2 7f7f7f
20 43 2 7f7f7f
21 43 2 7f7f7f
22 43 2 7f7f7f
23 43 2 7f7f7f
24 43 2 7f7f7f
25 43 2 7f7f7f
26 43 2 7f7f7f
27 43 2 7f7f7f
28 43 2 7f7f7f
29 43 2 7f7f7f
30 43 2 7f7f7f
31 43 2 7f7f7f
16 44 2 7f7f7f
17 44 2 7f7f7f
18 44 2 7f7f7f
19 44 2 7f7f7f
20 44 2 7f7f7f
21 44 2 7f7f7f
22 44 2 7f7f7f
23 44 2 7f7f7f
24 44 2 7f7f7f
25 44 2 7f7f7f
26 44 2 7f7f7f
27 44 2 7f7f7f
28 44 2 7f7f7f
29 44 2 7f7f7f
30 44 2 7f7f7f
31 44 2 7f7f7f
16 45 2 7f7f7f
17 45 2 7f7f7f
18 45 2 7f7f7f
19 45 2 7f7f7f
20 45 2 7f7f7f
21 45 2 7f7f7f
22 45 2 7f7f7f
23 45 2 7f7f7f
24 45 2 7f7f7f
25 45 2 7f7f7f
26 45 2 7f7f7f
27 45 2 7f7f7f
28 45 2 7f7f7f
29 45 2 7f7f7f
30 45 2 7f7f7f
31 45 2 7f7f7f
16 46 2 7f7f7f
17 46 2 7f7f7f
18 46 2 7f7f7f
19 46 2 7f7f7f
20 46 2 7f7f7f
21 46 2 7f7f7f
22 46 2 7f7f7f
23 46 2 7f7f7f
24 46 2 7f7f7f
25 46 2 7f7f7f
26 46 2 7f7f7f
27 46 2 7f7f7f
28 46 2 7f7f7f
29 46 2 7f7f7f
30 46 2 7f7f7f
31 46 2 7f7f7f
16 47 2 7f7f7f
17 47 2 7f7f7f
18 47 2 7f7f7f
19 47 2 7f7f7f
20 47 2 7f7f7f
21 47 2 7f7f7f
22 47 2 7f7f7f
23 47 2 7f7f7f
24 47 2 7f7f7f
25 47 2 7f7f7f
26 47 2 7f7f7f
27 47 2 7f7f7f
28 47 2 7f7f7f
29 47 2 7f7f7f
30 47 2 7f7f7f
31 47 2 7f7f7f
16 32 3 7f7f7f
17 32 3 7f7f7f
18 32 3 7f7f7f
19 32 3 7f7f7f
20 32 3 7f7f7f
21 32 3 7f7f7f
22 32 3 7f7f7f
23 32 3 7f7f7f
24 32 3 7f7f7f
25 32 3 7f7f7f
26 32 3 7f7f7f
27 32 3 7f7f7f
28 32 3 7f7f7f
29 32 3 7f7f7f
30 32 3 7f7f7f
31 32 3 7f7f7f
16 33 3 7f7f7f
17 33 3 7f7f7f
18 33 3 7f7f7f
19 33 3 7f7f7f
20 33 3 7f7f7f
21 33 3 7f7f7f
22 33 3 7f7f7f
23 33 3 7f7f7f
24 33 3 7f7f7f
25 33 3 7f7f7f
26 33 3 7f7f7f
27 33 3 7f7f7f
28 33 3 7f7f7f
29 33 3 7f7f7f
30 33 3 7f7f7f
31 33 3 7f7f7f
16 34 3 7f7f7f
17 34 3 7f7f7f
18 34 3 7f7f7f
19 34 3 7f7f7f
20 34 3 7f7f7f
21 34 3 7f7f7f
22 34 3 7f7f7f
23 34 3 7f7f7f
24 34 3 7f7f7f
25 34 3 7f7f7f
26 34 3 7f7f7f
27 34 3 7f7f7f
28 34 3 7f7f7f
29 34 3 7f7f7f
30 34 3 7f7f7f
31 34 3 7f7f7f
16 35 3 7f7f7f
17 35 3 7f7f7f
18 35 3 7f7f7f
19 35 3 7f7f7f
20 35 3 7f7f7f
21 35 3 7f7f7f
22 35 3 7f7f7f
23 35 3 7f7f7f
24 35 3 7f7f7f
25 35 3 7f7f7f
26 35 3 7f7f7f
27 35 3 7f7f7f
28 35 3 7f7f7f
29 35 3 7f7f7f
30 35 3 7f7f7f
31 35 3 7f7f7f
16 36 3 7f7f7f
17 36 3 7f7f7f
18 36 3 7f7f7f
19 36 3 7f7f7f
20 36 3 7f7f7f
21 36 3 7f7f7f
22 36 3 7f7f7f
23 36 3 7f7f7f
24 36 3 7f7f7f
25 36 3 7f7f7f
26 36 3 7f7f7f
27 36 3 7f7f7f
28 36 3 7f7f7f
29 36 3 7f7f7f
30 36 3 7f7f7f
31 36 3 7f7f7f
16 37 3 7f7f7f
17 37 3 7f7f7f
18 37 3 7f7f7f
19 37 3 7f7f7f
20 37 3 7f7f7f
21 37 3 7f7f7f
22 37 3 7f7f7f
23 37 3 7f7f7f
24 37 3 7f7f7f
25 37 3 7f7f7f
26 37 3 7f7f7f
27 37 3 7f7f7f
28 37 3 7f7f7f
29 37 3 7f7f7f
30 37 3 7f7f7f
31 37 3 7f7f7f
16 38 3 7f7f7f
17 38 3 7f7f7f
18 38 3 7f7f7f
19 38 3 7f7f7f
20 38 3 7f7f7f
21 38 3 7f7f7f
22 38 3 7f7f7f
23 38 3 7f7f7f
24 38 3 7f7f7f
25 38 3 7f7f7f
26 38 3 7f7f7f
27 38 3 7f7f7f
28 38 3 7f7f7f
29 38 3 7f7f7f
30 38 3 7f7f7f
31 38 3 7f7f7f
16 39 3 7f7f7f
17 39 3 7f7f7f
18 39 3 7f7f7f
19 39 3 7f7f7f
20 39 3 7f7f7f
21 39 3 7f7f7f
22 39 3 7f7f7f
23 39 3 7f7f7f
24 39 3 7f7f7f
25 39 3 7f7f7f
26 39 3 7f7f7f
27 39 3 7f7f7f
28 39 3 7f7f7f
29 39 3 7f7f7f
30 39 3 7f7f7f
31 39 3 7f7f7f
16 40 3 7f7f7f
17 40 3 7f7f7f
18 40 3 7f7f7f
19 40 3 7f7f7f
20 40 3 7f7f7f
21 40 3 7f7f7f
22 40 3 7f7f7f
23 40 3 7f7f7f
24 40 3 7f7f7f
25 40 3 7f7f7f
26 40 3 7f7f7f
27 40 3 7f7f7f
28 40 3 7f7f7f
29 40 3 7f7f7f
30 40 3 7f7f7f
31 40 3 7f7f7f
16 41 3 7f7f7f
17 41 3 7f7f7f
18 41 3 7f7f7f
19 41 3 7f7f7f
20 41 3 7f7f7f
21 41 3 7f7f7f
22 41 3 7f7f7f
23 41 3 7f7f7f
24 41 3 7f7f7f
25 41 3 7f7f7f
26 41 3 7f7f7f
27 41 3 7f7f7f
28 41 3 7f7f7f
29 41 3 7f7f7f
30 41 3 7f7f7f
31 41 3 7f7f7f
16 42 3 7f7f7f
17 42 3 7f7f7f
18 42 3 7f7f7f
19 42 3 7f7f7f
20 42 3 7f7f7f
21 42 3 7f7f7f
22 42 3 7f7f7f
23 42 3 7f7f7f
24 42 3 7f7f7f
25 42 3 7f7f7f
26 42 3 7f7f7f
27 42 3 7f7f7f
28 42 3 7f7f7f
29 42 3 7f7f7f
30 42 3 7f7f7f
31 42 3 7f7f7f
16 43 3 7f7f7f
17 43 3 7f7f7f
18 43 3 7f7f7f
19 43 3 7f7f7f
20 43 3 7f7f7f
21 43 3 7f7f7f
22 43 3 7f7f7f
23 43 3 7f7f7f
24 43 3 7f7f7f
25 43 3 7f7f7f
26 43 3 7f7f7f
27 43 3 7f7f7f
28 43 3 7f7f7f
29 43 3 7f7f7f
30 43 3 7f7f7f
31 43 3 7f7f7f
16 44 3 7f7f7f
17 44 3 7f7f7f
18 44 3 7f7f7f
19 44 3 7f7f7f
20 44 3 7f7f7f
21 44 3 7f7f7f
22 44 3 7f7f7f
23 44 3 7f7f7f
24 44 3 7f7f7f
25 44 3 7f7f7f
26 44 3 7f7f7f
27 44 3 7f7f7f
28 44 3 7f7f7f
29 44 3 7f7f7f
30 44 3 7f7f7f
31 44 3 7f7f7f
16 45 3 7f7f7f
17 45 3 7f7f7f
18 45 3 7f7f7f
19 45 3 7f7f7f
20 45 3 7f7f7f
21 45 3 7f7f7f
22 45 3 7f7f7f
23 45 3 7f7f7f
24 45 3 7f7f7f
25 45 3 7f7f7f
26 45 3 7f7f7f
27 45 3 7f7f7f
28 45 3 7f7f7f
29 45 3 7f7f7f
30 45 3 7f7f7f
31 45 3 7f7f7f
16 46 3 7f7f7f
17 46 3 7f7f7f
18 46 3 7f7f7f
19 46 3 7f7f7f
20 46 3 7f7f7f
21 46 3 7f7f7f
22 46 3 7f7f7f
23 46 3 7f7f7f
24 46 3 7f7f7f
25 46 3 7f7f7f
26 46 3 7f7f7f
27 46 3 7f7f7f
28 46 3 7f7f7f
29 46 3 7f7f7f
30 46 3 7f7f7f
31 46 3 7f7f7f
16 47 3 7f7f7f
17 47 3 7f7f7f
18 47 3 7f7f7f
19 47 3 7f7f7f
20 47 3 7f7f7f
21 47 3 7f7f7f
22 47 3 7f7f7f
23 47 3 7f7f7f
24 47 3 7f7f7f
25 47 3 7f7f7f
26 47 3 7f7f7f
27 47 3 7f7f7f
28 47 3 7f7f7f
29 47 3 7f7f7f
30 47 3 7f7f7f
31 47 3 7f7f7f
16 32 4 7f7f7f
17 32 4 7f7f7f
18 32 4 7f7f7f
19 32 4 7f7f7f
20 32 4 7f7f7f
21 32 4 7f7f7f
22 32 4 7f7f7f
23 32 4 7f7f7f
24 32 4 7f7f7f
25 32 4 7f7f7f
26 32 4 7f7f7f
27 32 4 7f7f7f
28 32 4 7f7f7f
29 32 4 7f7f7f
30 32 4 7f7f7f
31 32 4 7f7f7f
16 33 4 7f7f7f
17 33 4 7f7f7f
18 33 4 7f7f7f
19 33 4 7f7f7f
20 33 4 7f7f7f
21 33 4 7f7f7f
22 33 4 7f7f7f
23 33 4 7f7f7f
24 33 4 7f7f7f
25 33 4 7f7f7f
26 33 4 7f7f7f
27 33 4 7f7f7f
28 33 4 7f7f7f
29 33 4 7f7f7f
30 33 4 7f7f7f
31 33 4 7f7f7f
16 34 4 7f7f7f
17 34 4 7f7f7f
18 34 4 7f7f7f
19 34 4 7f7f7f
20 34 4 7f7f7f
21 34 4 7f7f7f
22 34 4 7f7f7f
23 34 4 7f7f7f
24 34 4 7f7f7f
25 34 4 7f7f7f
26 34 4 7f7f7f
27 34 4 7f7f7f
28 34 4 7f7f7f
29 34 4 7f7f7f
30 34 4 7f7f7f
31 34 4 7f7f7f
16 35 4 7f7f7f
17 35 4 7f7f7f
18 35 4 7f7f7f
19 35 4 7f7f7f
20 35 4 7f7f7f
21 35 4 7f7f7f
22 35 4 7f7f7f
23 35 4 7f7f7f
24 35 4 7f7f7f
25 35 4 7f7f7f
26 35 4 7f7f7f
27 35 4 7f7f7f
28 35 4 7f7f7f
29 35 4 7f7f7f
30 35 4 7f7f7f
31 35 4 7f7f7f
16 36 4 7f7f7f
17 36 4 7f7f7f
18 36 4 7f7f7f
19 36 4 7f7f7f
20 36 4 7f7f7f
21 36 4 7f7f7f
22 36 4 7f7f7f
23 36 4 7f7f7f
24 36 4 7f7f7f
25 36 4 7f7f7f
26 36 4 7f7f7f
27 36 4 7f7f7f
28 36 4 7f7f7f
29 36 4 7f7f7f
30 36 4 7f7f7f
31 36 4 7f7f7f
16 37 4 7f7f7f
17 37 4 7f7f7f
18 37 4 7f7f7f
19 37 4 7f7f7f
20 37 4 7f7f7f
21 37 4 7f7f7f
22 37 4 7f7f7f
23 37 4 7f7f7f
24 37 4 7f7f7f
25 37 4 7f7f7f
26 37 4 7f7f7f
27 37 4 7f7f7f
28 37 4 7f7f7f
29 37 4 7f7f7f
30 37 4 7f7f7f
31 37 4 7f7f7f
16 38 4 7f7f7f
17 38 4 7f7f7f
18 38 4 7f7f7f
19 38 4 7f7f7f
20 38 4 7f7f7f
21 38 4 7f7f7f
22 38 4 7f7f7f
23 38 4 7f7f7f
24 38 4 7f7f7f
25 38 4 7f7f7f
26 38 4 7f7f7f
27 38 4 7f7f7f
28 38 4 7f7f7f
29 38 4 7f7f7f
30 38 4 7f7f7f
31 38 4 7f7f7f
16 39 4 7f7f7f
17 39 4 7f7f7f
18 39 4 7f7f7f
19 39 4 7f7f7f
20 39 4 7f7f7f
21 39 4 7f7f7f
22 39 4 7f7f7f
23 39 4 7f7f7f
24 39 4 7f7f7f
25 39 4 7f7f7f
26 39 4 7f7f7f
27 39 4 7f7f7f
28 39 4 7f7f7f
29 39 4 7f7f7f
30 39 4 7f7f7f
31 39 4 7f7f7f
16 40 4 7f7f7f
17 40 4 7f7f7f
18 40 4 7f7f7f
19 40 4 7f7f7f
20 40 4 7f7f7f
21 40 4 7f7f7f
22 40 4 7f7f7f
23 40 4 7f7f7f
24 40 4 7f7f7f
25 40 4 7f7f7f
26 40 4 7f7f7f
27 40 4 7f7f7f
28 40 4 7f7f7f
29 40 4 7f7f7f
30 40 4 7f7f7f
31 40 4 7f7f7f
16 41 4 7f7f7f
17 41 4 7f7f7f
18 41 4 7f7f7f
19 41 4 7f7f7f
20 41 4 7f7f7f
21 41 4 7f7f7f
22 41 4 7f7f7f
23 41 4 7f7f7f
24 41 4 7f7f7f
25 41 4 7f7f7f
26 41 4 7f7f7f
27 41 4 7f7f7f
28 41 4 7f7f7f
29 41 4 7f7f7f
30 41 4 7f7f7f
31 41 4 7f7f7f
16 42 4 7f7f7f
17 42 4 7f7f7f
18 42 4 7f7f7f
19 42 4 7f7f7f
20 42 4 7f7f7f
21 42 4 7f7f7f
22 42 4 7f7f7f
23 42 4 7f7f7f
24 42 4 7f7f7f
25 42 4 7f7f7f
26 42 4 7f7f7f
27 42 4 7f7f7f
28 42 4 7f7f7f
29 42 4 7f7f7f
30 42 4 7f7f7f
31 42 4 7f7f7f
16 43 4 7f7f7f
17 43 4 7f7f7f
18 43 4 7f7f7f
19 43 4 7f7f7f
20 43 4 7f7f7f
21 43 4 7f7f7f
22 43 4 7f7f7f
23 43 4 7f7f7f
24 43 4 7f7f7f
25 43 4 7f7f7f
26 43 4 7f7f7f
27 43 4 7f7f7f
28 43 4 7f7f7f
29 43 4 7f7f7f
30 43 4 7f7f7f
31 43 4 7f7f7f
16 44 4 7f7f7f
17 44 4 7f7f7f
18 44 4 7f7f7f
19 44 4 7f7f7f
20 44 4 7f7f7f
21 44 4 7f7f7f
22 44 4 7f7f7f
23 44 4 7f7f7f
24 44 4 7f7f7f
25 44 4 7f7f7f
26 44 4 7f7f7f
27 44 4 7f7f7f
28 44 4 7f7f7f
29 44 4 7f7f7f
30 44 4 7f7f7f
31 44 4 7f7f7f
16 45 4 7f7f7f
17 45 4 7f7f7f
18 45 4 7f7f7f
19 45 4 7f7f7f
20 45 4 7f7f7f
21 45 4 7f7f7f
22 45 4 7f7f7f
23 45 4 7f7f7f
24 45 4 7f7f7f
25 45 4 7f7f7f
26 45 4 7f7f7f
27 45 4 7f7f7f
28 45 4 7f7f7f
29 45 4 7f7f7f
30 45 4 7f7f7f
31 45 4 7f7f7f
16 46 4 7f7f7f
17 46 4 7f7f7f
18 46 4 7f7f7f
19 46 4 7f7f7f
20 46 4 7f7f7f
21 46 4 7f7f7f
22 46 4 7f7f7f
23 46 4 7f7f7f
24 46 4 7f7f7f
25 46 4 7f7f7f
26 46 4 7f7f7f
27 46 4 7f7f7f
28 46 4 7f7f7f
29 46 4 7f7f7f
30 46 4 7f7f7f
31 46 4 7f7f7f
16 47 4 7f7f7f
17 47 4 7f7f7f
18 47 4 7f7f7f
19 47 4 7f7f7f
20 47 4 7f7f7f
21 47 4 7f7f7f
22 47 4 7f7f7f
23 47 4 7f7f7f
24 47 4 7f7f7f
25 47 4 7f7f7f
26 47 4 7f7f7f
27 47 4 7f7f7f
28 47 4 7f7f7f
29 47 4 7f7f7f
30 47 4 7f7f7f
31 47 4 7f7f7f
16 32 5 7f7f7f
17 32 5 7f7f7f
18 32 5 7f7f7f
19 32 5 7f7f7f
20 32 5 7f7f7f
21 32 5 7f7f7f
22 32 5 7f7f7f
23 32 5 7f7f7f
24 32 5 7f7f7f
25 32 5 7f7f7f
26 32 5 7f7f7f
27 32 5 7f7f7f
28 32 5 7f7f7f
29 32 5 7f7f7f
30 32 5 7f7f7f
31 32 5 7f7f7f
16 33 5 7f7f7f
17 33 5 7f7f7f
18 33 5 7f7f7f
19 33 5 7f7f7f
20 33 5 7f7f7f
21 33 5 7f7f7f
22 33 5 7f7f7f
23 33 5 7f7f7f
24 33 5 7f7f7f
25 33 5 7f7f7f
26 33 5 7f7f7f
27 33 5 7f7f7f
28 33 5 7f7f7f
29 33 5 7f7f7f
30 33 5 7f7f7f
31 33 5 7f7f7f
16 34 5 7f7f7f
17 34 5 7f7f7f
18 34 5 7f7f7f
19 34 5 7f7f7f
20 34 5 7f7f7f
21 34 5 7f7f7f
22 34 5 7f7f7f
23 34 5 7f7f7f
24 34 5 7f7f7f
25 34 5 7f7f7f
26 34 5 7f7f7f
27 34 5 7f7f7f
28 34 5 7f7f7f
29 34 5 7f7f7f
30 34 5 7f7f7f
31 34 5 7f7f7f
16 35 5 7f7f7f
17 35 5 7f7f7f
18 35 5 7f7f7f
19 35 5 7f7f7f
20 35 5 7f7f7f
21 35 5 7f7f7f
22 35 5 7f7f7f
23 35 5 7f7f7f
24 35 5 7f7f7f
25 35 5 7f7f7f
26 35 5 7f7f7f
27 35 5 7f7f7f
28 35 5 7f7f7f
29 35 5 7f7f7f
30 35 5 7f7f7f
31 35 5 7f7f7f
16 36 5 7f7f7f
17 36 5 7f7f7f
18 36 5 7f7f7f
19 36 5 7f7f7f
20 36 5 7f7f7f
21 36 5 7f7f7f
22 36 5 7f7f7f
23 36 5 7f7f7f
24 36 5 7f7f7f
25 36 5 7f7f7f
26 36 5 7f7f7f
27 36 5 7f7f7f
28 36 5 7f7f7f
29 36 5 7f7f7f
30 36 5 7f7f7f
31 36 5 7f7f7f
16 37 5 7f7f7f
17 37 5 7f7f7f
18 37 5 7f7f7f
19 37 5 7f7f7f
20 37 5 7f7f7f
21 37 5 7f7f7f
22 37 5 7f7f7f
23 37 5 7f7f7f
24 37 5 7f7f7f
25 37 5 7f7f7f
26 37 5 7f7f7f
27 37 5 7f7f7f
28 37 5 7f7f7f
29 37 5 7f7f7f
30 37 5 7f7f7f
31 37 5 7f7f7f
16 38 5 7f7f7f
17 38 5 7f7f7f
18 38 5 7f7f7f
19 38 5 7f7f7f
20 38 5 7f7f7f
21 38 5 7f7f7f
22 38 5 7f7f7f
23 38 5 7f7f7f
24 38 5 7f7f7f
25 38 5 7f7f7f
26 38 5 7f7f7f
27 38 5 7f7f7f
28 38 5 7f7f7f
29 38 5 7f7f7f
30 38 5 7f7f7f
31 38 5 7f7f7f
16 39 5 7f7f7f
17 39 5 7f7f7f
18 39 5 7f7f7f
19 39 5 7f7f7f
20 39 5 7f7f7f
21 39 5 7f7f7f
22 39 5 7f7f7f
23 39 5 7f7f7f
24 39 5 7f7f7f
25 39 5 7f7f7f
26 39 5 7f7f7f
27 39 5 7f7f7f
28 39 5 7f7f7f
29 39 5 7f7f7f
30 39 5 7f7f7f
31 39 5 7f7f7f
16 40 5 7f7f7f
17 40 5 7f7f7f
18 40 5 7f7f7f
19 40 5 7f7f7f
20 40 5 7f7f7f
21 40 5 7f7f7f
22 40 5 7f7f7f
23 40 5 7f7f7f
24 40 5 7f7f7f
25 40 5 7f7f7f
26 40 5 7f7f7f
27 40 5 7f7f7f
28 40 5 7f7f7f
29 40 5 7f7f7f
30 40 5 7f7f7f
31 40 5 7f7f7f
16 41 5 7f7f7f
17 41 5 7f7f7f
18 41 5 7f7f7f
19 41 5 7f7f7f
20 41 5 7f7f7f
21 41 5 7f7f7f
22 41 5 7f7f7f
23 41 5 7f7f7f
24 41 5 7f7f7f
25 41 5 7f7f7f
26 41 5 7f7f7f
27 41 5 7f7f7f
28 41 5 7f7f7f
29 41 5 7f7f7f
30 41 5 7f7f7f
31 41 5 7f7f7f
16 42 5 7f7f7f
17 42 5 7f7f7f
18 42 5 7f7f7f
19 42 5 7f7f7f
20 42 5 7f7f7f
21 42 5 7f7f7f
22 42 5 7f7f7f
23 42 5 7f7f7f
24 42 5 7f7f7f
25 42 5 7f7f7f
26 42 5 7f7f7f
27 42 5 7f7f7f
28 42 5 7f7f7f
29 42 5 7f7f7f
30 42 5 7f7f7f
31 42 5 7f7f7f
16 43 5 7f7f7f
17 43 5 7f7f7f
18 43 5 7f7f7f
19 43 5 7f7f7f
20 43 5 7f7f7f
21 43 5 7f7f7f
22 43 5 7f7f7f
23 43 5 7f7f7f
24 43 5 7f7f7f
25 43 5 7f7f7f
26 43 5 7f7f7f
27 43 5 7f7f7f
28 43 5 7f7f7f
29 43 5 7f7f7f
30 43 5 7f7f7f
31 43 5 7f7f7f
16 44 5 7f7f7f
17 44 5 7f7f7f
18 44 5 7f7f7f
19 44 5 7f7f7f
20 44 5 7f7f7f
21 44 5 7f7f7f
22 44 5 7f7f7f
23 44 5 7f7f7f
24 44 5 7f7f7f
25 44 5 7f7f7f
26 44 5 7f7f7f
27 44 5 7f7f7f
28 44 5 7f7f7f
29 44 5 7f7f7f
30 44 5 7f7f7f
31 44 5 7f7f7f
16 45 5 7f7f7f
17 45 5 7f7f7f
18 45 5 7f7f7f
19 45 5 7f7f7f
20 45 5 7f7f7f
21 45 5 7f7f7f
22 45 5 7f7f7f
23 45 5 7f7f7f
24 45 5 7f7f7f
25 45 5 7f7f7f
26 45 5 7f7f7f
27 45 5 7f7f7f
28 45 5 7f7f7f
29 45 5 7f7f7f
30 45 5 7f7f7f
31 45 5 7f7f7f
16 46 5 7f7f7f
17 46 5 7f7f7f
18 46 5 7f7f7f
19 46 5 7f7f7f
20 46 5 7f7f7f
21 46 5 7f7f7f
22 46 5 7f7f7f
23 46 5 7f7f7f
24 46 5 7f7f7f
25 46 5 7f7f7f
26 46 5 7f7f7f
27 46 5 7f7f7f
28 46 5 7f7f7f
29 46 5 7f7f7f
30 46 5 7f7f7f
31 46 5 7f7f7f
16 47 5 7f7f7f
17 47 5 7f7f7f
18 47 5 7f7f7f
19 47 5 7f7f7f
20 47 5 7f7f7f
21 47 5 7f7f7f
22 47 5 7f7f7f
23 47 5 7f7f7f
24 47 5 7f7f7f
25 47 5 7f7f7f
26 47 5 7f7f7f
27 47 5 7f7f7f
28 47 5 7f7f7f
29 47 5 7f7f7f
30 47 5 7f7f7f
31 47 5 7f7f7f
16 32 6 7f7f7f
17 32 6 7f7f7f
18 32 6 7f7f7f
19 32 6 7f7f7f
20 32 6 7f7f7f
21 32 6 7f7f7f
22 32 6 7f7f7f
23 32 6 7f7f7f
24 32 6 7f7f7f
25 32 6 7f7f7f
26 32 6 7f7f7f
27 32 6 7f7f7f
28 32 6 7f7f7f
29 32 6 7f7f7f
30 32 6 7f7f7f
31 32 6 7f7f7f
16 33 6 7f7f7f
17 33 6 7f7f7f
18 33 6 7f7f7f
19 33 6 7f7f7f
20 33 6 7f7f7f
21 33 6 7f7f7f
22 33 6 7f7f7f
23 33 6 7f7f7f
24 33 6 7f7f7f
25 33 6 7f7f7f
26 33 6 7f7f7f
27 33 6 7f7f7f
28 33 6 7f7f7f
29 33 6 7f7f7f
30 33 6 7f7f7f
31 33 6 7f7f7f
16 34 6 7f7f7f
17 34 6 7f7f7f
18 34 6 7f7f7f
19 34 6 7f7f7f
20 34 6 7f7f7f
21 34 6 7f7f7f
22 34 6 7f7f7f
23 34 6 7f7f7f
24 34 6 7f7f7f
25 34 6 7f7f7f
26 34 6 7f7f7f
27 34 6 7f7f7f
28 34 6 7f7f7f
29 34 6 7f7f7f
30 34 6 7f7f7f
31 34 6 7f7f7f
16 35 6 7f7f7f
17 35 6 7f7f7f
18 35 6 7f7f7f
19 35 6 7f7f7f
20 35 6 7f7f7f
21 35 6 7f7f7f
22 35 6 7f7f7f
23 35 6 7f7f7f
24 35 6 7f7f7f
25 35 6 7f7f7f
26 35 6 7f7f7f
27 35 6 7f7f7f
28 35 6 7f7f7f
29 35 6 7f7f7f
30 35 6 7f7f7f
31 35 6 7f7f7f
16 36 6 7f7f7f
17 36 6 7f7f7f
18 36 6 7f7f7f
19 36 6 7f7f7f
20 36 6 7f7f7f
21 36 6 7f7f7f
22 36 6 7f7f7f
23 36 6 7f7f7f
24 36 6 7f7f7f
25 36 6 7f7f7f
26 36 6 7f7f7f
27 36 6 7f7f7f
28 36 6 7f7f7f
29 36 6 7f7f7f
30 36 6 7f7f7f
31 36 6 7f7f7f
16 37 6 7f7f7f
17 37 6 7f7f7f
18 37 6 7f7f7f
19 37 6 7f7f7f
20 37 6 7f7f7f
21 37 6 7f7f7f
22 37 6 7f7f7f
23 37 6 7f7f7f
24 37 6 7f7f7f
25 37 6 7f7f7f
26 37 6 7f7f7f
27 37 6 7f7f7f
28 37 6 7f7f7f
29 37 6 7f7f7f
30 37 6 7f7f7f
31 37 6 7f7f7f
16 38 6 7f7f7f
17 38 6 7f7f7f
18 38 6 7f7f7f
19 38 6 7f7f7f
20 38 6 7f7f7f
21 38 6 7f7f7f
22 38 6 7f7f7f
23 38 6 7f7f7f
24 38 6 7f7f7f
25 38 6 7f7f7f
26 38 6 7f7f7f
27 38 6 7f7f7f
28 38 6 7f7f7f
29 38 6 7f7f7f
30 38 6 7f7f7f
31 38 6 7f7f7f
16 39 6 7f7f7f
17 39 6 7f7f7f
18 39 6 7f7f7f
19 39 6 7f7f7f
20 39 6 7f7f7f
21 39 6 7f7f7f
22 39 6 7f7f7f
23 39 6 7f7f7f
24 39 6 7f7f7f
25 39 6 7f7f7f
26 39 6 7f7f7f
27 39 6 7f7f7f
28 39 6 7f7f7f
29 39 6 7f7f7f
30 39 6 7f7f7f
31 39 6 7f7f7f
16 40 6 7f7f7f
17 40 6 7f7f7f
18 40 6 7f7f7f
19 40 6 7f7f7f
20 40 6 7f7f7f
21 40 6 7f7f7f
22 40 6 7f7f7f
23 40 6 7f7f7f
24 40 6 7f7f7f
25 40 6 7f7f7f
26 40 6 7f7f7f
27 40 6 7f7f7f
28 40 6 7f7f7f
29 40 6 7f7f7f
30 40 6 7f7f7f
16 41 6 7f7f7f
17 41 6 7f7f7f
18 41 6 7f7f7f
19 41 6 7f7f7f
20 41 6 7f7f7f
21 41 6 7f7f7f
22 41 6 7f7f7f
23 41 6 7f7f7f
24 41 6 7f7f7f
25 41 6 7f7f7f
26 41 6 7f7f7f
27 41 6 7f7f7f
28 41 6 7f7f7f
29 41 6 7f7f7f
30 41 6 7f7f7f
16 42 6 7f7f7f
17 42 6 7f7f7f
18 42 6 7f7f7f
19 42 6 7f7f7f
20 42 6 7f7f7f
21 42 6 7f7f7f
22 42 6 7f7f7f
23 42 6 7f7f7f
24 42 6 7f7f7f
25 42 6 7f7f7f
26 42 6 7f7f7f
27 42 6 7f7f7f
28 42 6 7f7f7f
29 42 6 7f7f7f
30 42 6 7f7f7f
16 43 6 7f7f7f
17 43 6 7f7f7f
18 43 6 7f7f7f
19 43 6 7f7f7f
20 43 6 7f7f7f
21 43 6 7f7f7f
22 43 6 7f7f7f
23 43 6 7f7f7f
24 43 6 7f7f7f
25 43 6 7f7f7f
26 43 6 7f7f7f
27 43 6 7f7f7f
28 43 6 7f7f7f
29 43 6 7f7f7f
30 43 6 7f7f7f
16 44 6 7f7f7f
17 44 6 7f7f7f
18 44 6 7f7f7f
19 44 6 7f7f7f
20 44 6 7f7f7f
21 44 6 7f7f7f
22 44 6 7f7f7f
23 44 6 7f7f7f
24 44 6 7f7f7f
25 44 6 7f7f7f
26 44 6 7f7f7f
27 44 6 7f7f7f
28 44 6 7f7f7f
29 44 6 7f7f7f
30 44 6 7f7f7f
16 45 6 7f7f7f
17 45 6 7f7f7f
18 45 6 7f7f7f
19 45 6 7f7f7f
20 45 6 7f7f7f
21 45 6 7f7f7f
22 45 6 7f7f7f
23 45 6 7f7f7f
24 45 6 7f7f7f
25 45 6 7f7f7f
26 45 6 7f7f7f
27 45 6 7f7f7f
28 45 6 7f7f7f
29 45 6 7f7f7f
30 45 6 7f7f7f
16 46 6 7f7f7f
17 46 6 7f7f7f
18 46 6 7f7f7f
19 46 6 7f7f7f
20 46 6 7f7f7f
21 46 6 7f7f7f
22 46 6 7f7f7f
23 46 6 7f7f7f
24 46 6 7f7f7f
25 46 6 7f7f7f
26 46 6 7f7f7f
27 46 6 7f7f7f
28 46 6 7f7f7f
29 46 6 7f7f7f
30 46 6 7f7f7f
16 47 6 7f7f7f
17 47 6 7f7f7f
18 47 6 7f7f7f
19 47 6 7f7f7f
20 47 6 7f7f7f
21 47 6 7f7f7f
22 47 6 7f7f7f
23 47 6 7f7f7f
24 47 6 7f7f7f
25 47 6 7f7f7f
26 47 6 7f7f7f
27 47 6 7f7f7f
28 47 6 7f7f7f
29 47 6 7f7f7f
30 47 6 7f7f7f
16 32 7 7f7f7f
17 32 7 7f7f7f
18 32 7 7f7f7f
19 32 7 7f7f7f
20 32 7 7f7f7f
21 32 7 7f7f7f
22 32 7 7f7f7f
23 32 7 7f7f7f
24 32 7 7f7f7f
25 32 7 7f7f7f
26 32 7 7f7f7f
27 32 7 7f7f7f
28 32 7 7f7f7f
29 32 7 7f7f7f
30 32 7 7f7f7f
31 32 7 7f7f7f
16 33 7 7f7f7f
17 33 7 7f7f7f
18 33 7 7f7f7f
19 33 7 7f7f7f
20 33 7 7f7f7f
21 33 7 7f7f7f
22 33 7 7f7f7f
23 33 7 7f7f7f
24 33 7 7f7f7f
25 33 7 7f7f7f
26 33 7 7f7f7f
27 33 7 7f7f7f
28 33 7 7f7f7f
29 33 7 7f7f7f
30 33 7 7f7f7f
31 33 7 7f7f7f
16 34 7 7f7f7f
17 34 7 7f7f7f
18 34 7 7f7f7f
19 34 7 7f7f7f
20 34 7 7f7f7f
21 34 7 7f7f7f
22 34 7 7f7f7f
23 34 7 7f7f7f
24 34 7 7f7f7f
25 34 7 7f7f7f
26 34 7 7f7f7f
27 34 7 7f7f7f
28 34 7 7f7f7f
29 34 7 7f7f7f
30 34 7 7f7f7f
31 34 7 7f7f7f
16 35 7 7f7f7f
17 35 7 7f7f7f
18 35 7 7f7f7f
19 35 7 7f7f7f
20 35 7 7f7f7f
21 35 7 7f7f7f
22 35 7 7f7f7f
23 35 7 7f7f7f
24 35 7 7f7f7f
25 35 7 7f7f7f
26 35 7 7f7f7f
27 35 7 7f7f7f
28 35 7 7f7f7f
29 35 7 7f7f7f
30 35 7 7f7f7f
31 35 7 7f7f7f
16 36 7 7f7f7f
17 36 7 7f7f7f
18 36 7 7f7f7f
19 36 7 7f7f7f
20 36 7 7f7f7f
21 36 7 7f7f7f
22 36 7 7f7f7f
23 36 7 7f7f7f
24 36 7 7f7f7f
25 36 7 7f7f7f
26 36 7 7f7f7f
27 36 7 7f7f7f
28 36 7 7f7f7f
29 36 7 7f7f7f
30 36 7 7f7f7f
31 36 7 7f7f7f
16 37 7 7f7f7f
17 37 7 7f7f7f
18 37 7 7f7f7f
19 37 7 7f7f7f
20 37 7 7f7f7f
21 37 7 7f7f7f
22 37 7 7f7f7f
23 37 7 7f7f7f
24 37 7 7f7f7f
25 37 7 7f7f7f
26 37 7 7f7f7f
27 37 7 7f7f7f
28 37 7 7f7f7f
29 37 7 7f7f7f
30 37 7 7f7f7f
31 37 7 7f7f7f
16 38 7 7f7f7f
17 38 7 7f7f7f
18 38 7 7f7f7f
19 38 7 7f7f7f
20 38 7 7f7f7f
21 38 7 7f7f7f
22 38 7 7f7f7f
23 38 7 7f7f7f
24 38 7 7f7f7f
25 38 7 7f7f7f
26 38 7 7f7f7f
27 38 7 7f7f7f
28 38 7 7f7f7f
29 38 7 7f7f7f
30 38 7 7f7f7f
31 38 7 7f7f7f
16 39 7 7f7f7f
17 39 7 7f7f7f
18 39 7 7f7f7f
19 39 7 7f7f7f
20 39 7 7f7f7f
21 39 7 7f7f7f
22 39 7 7f7f7f
23 39 7 7f7f7f
24 39 7 7f7f7f
25 39 7 7f7f7f
26 39 7 7f7f7f
27 39 7 7f7f7f
28 39 7 7f7f7f
29 39 7 7f7f7f
30 39 7 7f7f7f
31 39 7 7f7f7f
16 40 7 7f7f7f
17 40 7 7f7f7f
18 40 7 7f7f7f
19 40 7 7f7f7f
20 40 7 7f7f7f
21 40 7 7f7f7f
22 40 7 7f7f7f
23 40 7 7f7f7f
24 40 7 7f7f7f
25 40 7 7f7f7f
26 40 7 7f7f7f
27 40 7 7f7f7f
28 40 7 7f7f7f
29 40 7 7f7f7f
16 41 7 7f7f7f
17 41 7 7f7f7f
18 41 7 7f7f7f
19 41 7 7f7f7f
20 41 7 7f7f7f
21 41 7 7f7f7f
22 41 7 7f7f7f
23 41 7 7f7f7f
24 41 7 7f7f7f
25 41 7 7f7f7f
26 41 7 7f7f7f
27 41 7 7f7f7f
28 41 7 7f7f7f
29 41 7 7f7f7f
16 42 7 7f7f7f
17 42 7 7f7f7f
18 42 7 7f7f7f
19 42 7 7f7f7f
20 42 7 7f7f7f
21 42 7 7f7f7f
22 42 7 7f7f7f
23 42 7 7f7f7f
24 42 7 7f7f7f
25 42 7 7f7f7f
26 42 7 7f7f7f
27 42 7 7f7f7f
28 42 7 7f7f7f
29 42 7 7f7f7f
16 43 7 7f7f7f
17 43 7 7f7f7f
18 43 7 7f7f7f
19 43 7 7f7f7f
20 43 7 7f7f7f
21 43 7 7f7f7f
22 43 7 7f7f7f
23 43 7 7f7f7f
24 43 7 7f7f7f
25 43 7 7f7f7f
26 43 7 7f7f7f
27 43 7 7f7f7f
28 43 7 7f7f7f
29 43 7 7f7f7f
16 44 7 7f7f7f
17 44 7 7f7f7f
18 44 7 7f7f7f
19 44 7 7f7f7f
20 44 7 7f7f7f
21 44 7 7f7f7f
22 44 7 7f7f7f
23 44 7 7f7f7f
24 44 7 7f7f7f
25 44 7 7f7f7f
26 44 7 7f7f7f
27 44 7 7f7f7f
28 44 7 7f7f7f
29 44 7 7f7f7f
16 45 7 7f7f7f
17 45 7 7f7f7f
18 45 7 7f7f7f
19 45 7 7f7f7f
20 45 7 7f7f7f
21 45 7 7f7f7f
22 45 7 7f7f7f
23 45 7 7f7f7f
24 45 7 7f7f7f
25 45 7 7f7f7f
26 45 7 7f7f7f
27 45 7 7f7f7f
28 45 7 7f7f7f
29 45 7 7f7f7f
16 46 7 7f7f7f
17 46 7 7f7f7f
18 46 7 7f7f7f
19 46 7 7f7f7f
20 46 7 7f7f7f
21 46 7 7f7f7f
22 46 7 7f7f7f
23 46 7 7f7f7f
24 46 7 7f7f7f
25 46 7 7f7f7f
26 46 7 7f7f7f
27 46 7 7f7f7f
28 46 7 7f7f7f
29 46 7 7f7f7f
16 47 7 7f7f7f
17 47 7 7f7f7f
18 47 7 7f7f7f
19 47 7 7f7f7f
20 47 7 7f7f7f
21 47 7 7f7f7f
22 47 7 7f7f7f
23 47 7 7f7f7f
24 47 7 7f7f7f
25 47 7 7f7f7f
26 47 7 7f7f7f
27 47 7 7f7f7f
28 47 7 7f7f7f
29 47 7 7f7f7f
16 32 8 7f7f7f
17 32 8 7f7f7f
18 32 8 7f7f7f
19 32 8 7f7f7f
20 32 8 7f7f7f
21 32 8 7f7f7f
22 32 8 7f7f7f
23 32 8 7f7f7f
24 32 8 7f7f7f
25 32 8 7f7f7f
26 32 8 7f7f7f
27 32 8 7f7f7f
28 32 8 7f7f7f
29 32 8 7f7f7f
30 32 8 7f7f7f
31 32 8 7f7f7f
16 33 8 7f7f7f
17 33 8 7f7f7f
18 33 8 7f7f7f
19 33 8 7f7f7f
20 33 8 7f7f7f
21 33 8 7f7f7f
22 33 8 7f7f7f
23 33 8 7f7f7f
24 33 8 7f7f7f
25 33 8 7f7f7f
26 33 8 7f7f7f
27 33 8 7f7f7f
28 33 8 7f7f7f
29 33 8 7f7f7f
30 33 8 7f7f7f
31 33 8 7f7f7f
16 34 8 7f7f7f
17 34 8 7f7f7f
18 34 8 7f7f7f
19 34 8 7f7f7f
20 34 8 7f7f7f
21 34 8 7f7f7f
22 34 8 7f7f7f
23 34 8 7f7f7f
24 34 8 7f7f7f
25 34 8 7f7f7f
26 34 8 7f7f7f
27 34 8 7f7f7f
28 34 8 7f7f7f
29 34 8 7f7f7f
30 34 8 7f7f7f
31 34 8 7f7f7f
16 35 8 7f7f7f
17 35 8 7f7f7f
18 35 8 7f7f7f
19 35 8 7f7f7f
20 35 8 7f7f7f
21 35 8 7f7f7f
22 35 8 7f7f7f
23 35 8 7f7f7f
24 35 8 7f7f7f
25 35 8 7f7f7f
26 35 8 7f7f7f
27 35 8 7f7f7f
28 35 8 7f7f7f
29 35 8 7f7f7f
30 35 8 7f7f7f
31 35 8 7f7f7f
16 36 8 7f7f7f
17 36 8 7f7f7f
18 36 8 7f7f7f
19 36 8 7f7f7f
20 36 8 7f7f7f
21 36 8 7f7f7f
22 36 8 7f7f7f
23 36 8 7f7f7f
24 36 8 7f7f7f
25 36 8 7f7f7f
26 36 8 7f7f7f
27 36 8 7f7f7f
28 36 8 7f7f7f
29 36 8 7f7f7f
30 36 8 7f7f7f
31 36 8 7f7f7f
16 37 8 7f7f7f
17 37 8 7f7f7f
18 37 8 7f7f7f
19 37 8 7f7f7f
20 37 8 7f7f7f
21 37 8 7f7f7f
22 37 8 7f7f7f
23 37 8 7f7f7f
24 37 8 7f7f7f
25 37 8 7f7f7f
26 37 8 7f7f7f
27 37 8 7f7f7f
28 37 8 7f7f7f
29 37 8 7f7f7f
30 37 8 7f7f7f
31 37 8 7f7f7f
16 38 8 7f7f7f
17 38 8 7f7f7f
18 38 8 7f7f7f
19 38 8 7f7f7f
20 38 8 7f7f7f
21 38 8 7f7f7f
22 38 8 7f7f7f
23 38 8 7f7f7f
24 38 8 7f7f7f
25 38 8 7f7f7f
26 38 8 7f7f7f
27 38 8 7f7f7f
28 38 8 7f7f7f
29 38 8 7f7f7f
30 38 8 7f7f7f
31 38 8 7f7f7f
16 39 8 7f7f7f
17 39 8 7f7f7f
18 39 8 7f7f7f
19 39 8 7f7f7f
20 39 8 7f7f7f
21 39 8 7f7f7f
22 39 8 7f7f7f
23 39 8 7f7f7f
24 39 8 7f7f7f
25 39 8 7f7f7f
26 39 8 7f7f7f
27 39 8 7f7f7f
28 39 8 7f7f7f
29 39 8 7f7f7f
30 39 8 7f7f7f
31 39 8 7f7f7f
16 40 8 7f7f7f
17 40 8 7f7f7f
18 40 8 7f7f7f
19 40 8 7f7f7f
20 40 8 7f7f7f
21 40 8 7f7f7f
22 40 8 7f7f7f
23 40 8 7f7f7f
24 40 8 7f7f7f
25 40 8 7f7f7f
26 40 8 7f7f7f
27 40 8 7f7f7f
28 40 8 7f7f7f
16 41 8 7f7f7f
17 41 8 7f7f7f
18 41 8 7f7f7f
19 41 8 7f7f7f
20 41 8 7f7f7f
21 41 8 7f7f7f
22 41 8 7f7f7f
23 41 8 7f7f7f
24 41 8 7f7f7f
25 41 8 7f7f7f
26 41 8 7f7f7f
27 41 8 7f7f7f
28 41 8 7f7f7f
16 42 8 7f7f7f
17 42 8 7f7f7f
18 42 8 7f7f7f
19 42 8 7f7f7f
20 42 8 7f7f7f
21 42 8 7f7f7f
22 42 8 7f7f7f
23 42 8 7f7f7f
24 42 8 7f7f7f
25 42 8 7f7f7f
26 42 8 7f7f7f
27 42 8 7f7f7f
28 42 8 7f7f7f
16 43 8 7f7f7f
17 43 8 7f7f7f
18 43 8 7f7f7f
19 43 8 7f7f7f
20 43 8 7f7f7f
21 43 8 7f7f7f
22 43 8 7f7f7f
23 43 8 7f7f7f
24 43 8 7f7f7f
25 43 8 7f7f7f
26 43 8 7f7f7f
27 43 8 7f7f7f
28 43 8 7f7f7f
16 44 8 7f7f7f
17 44 8 7f7f7f
18 44 8 7f7f7f
19 44 8 7f7f7f
20 44 8 7f7f7f
21 44 8 7f7f7f
22 44 8 7f7f7f
23 44 8 7f7f7f
24 44 8 7f7f7f
25 44 8 7f7f7f
26 44 8 7f7f7f
27 44 8 7f7f7f
28 44 8 7f7f7f
16 45 8 7f7f7f
17 45 8 7f7f7f
18 45 8 7f7f7f
19 45 8 7f7f7f
20 45 8 7f7f7f
21 45 8 7f7f7f
22 45 8 7f7f7f
23 45 8 7f7f7f
24 45 8 7f7f7f
25 45 8 7f7f7f
26 45 8 7f7f7f
27 45 8 7f7f7f
28 45 8 7f7f7f
16 46 8 7f7f7f
17 46 8 7f7f7f
18 46 8 7f7f7f
19 46 8 7f7f7f
20 46 8 7f7f7f
21 46 8 7f7f7f
22 46 8 7f7f7f
23 46 8 7f7f7f
24 46 8 7f7f7f
25 46 8 7f7f7f
26 46 8 7f7f7f
27 46 8 7f7f7f
28 46 8 7f7f7f
16 47 8 7f7f7f
17 47 8 7f7f7f
18 47 8 7f7f7f
19 47 8 7f7f7f
20 47 8 7f7f7f
21 47 8 7f7f7f
22 47 8 7f7f7f
23 47 8 7f7f7f
24 47 8 7f7f7f
25 47 8 7f7f7f
26 47 8 7f7f7f
27 47 8 7f7f7f
28 47 8 7f7f7f
16 32 9 7f7f7f
17 32 9 7f7f7f
18 32 9 7f7f7f
19 32 9 7f7f7f
20 32 9 7f7f7f
21 32 9 7f7f7f
22 32 9 7f7f7f
23 32 9 7f7f7f
24 32 9 7f7f7f
25 32 9 7f7f7f
26 32 9 7f7f7f
27 32 9 7f7f7f
28 32 9 7f7f7f
29 32 9 7f7f7f
30 32 9 7f7f7f
31 32 9 7f7f7f
16 33 9 7f7f7f
17 33 9 7f7f7f
18 33 9 7f7f7f
19 33 9 7f7f7f
20 33 9 7f7f7f
21 33 9 7f7f7f
22 33 9 7f7f7f
23 33 9 7f7f7f
24 33 9 7f7f7f
25 33 9 7f7f7f
26 33 9 7f7f7f
27 33 9 7f7f7f
28 33 9 7f7f7f
29 33 9 7f7f7f
30 33 9 7f7f7f
31 33 9 7f7f7f
16 34 9 7f7f7f
17 34 9 7f7f7f
18 34 9 7f7f7f
19 34 9 7f7f7f
20 34 9 7f7f7f
21 34 9 7f7f7f
22 34 9 7f7f7f
23 34 9 7f7f7f
24 34 9 7f7f7f
25 34 9 7f7f7f
26 34 9 7f7f7f
27 34 9 7f7f7f
28 34 9 7f7f7f
29 34 9 7f7f7f
30 34 9 7f7f7f
31 34 9 7f7f7f
16 35 9 7f7f7f
17 35 9 7f7f7f
18 35 9 7f7f7f
19 35 9 7f7f7f
20 35 9 7f7f7f
21 35 9 7f7f7f
22 35 9 7f7f7f
23 35 9 7f7f7f
24 35 9 7f7f7f
25 35 9 7f7f7f
26 35 9 7f7f7f
27 35 9 7f7f7f
28 35 9 7f7f7f
29 35 9 7f7f7f
30 35 9 7f7f7f
31 35 9 7f7f7f
16 36 9 7f7f7f
17 36 9 7f7f7f
18 36 9 7f7f7f
19 36 9 7f7f7f
20 36 9 7f7f7f
21 36 9 7f7f7f
22 36 9 7f7f7f
23 36 9 7f7f7f
24 36 9 7f7f7f
25 36 9 7f7f7f
26 36 9 7f7f7f
27 36 9 7f7f7f
28 36 9 7f7f7f
29 36 9 7f7f7f
30 36 9 7f7f7f
31 36 9 7f7f7f
16 37 9 7f7f7f
17 37 9 7f7f7f
18 37 9 7f7f7f
19 37 9 7f7f7f
20 37 9 7f7f7f
21 37 9 7f7f7f
22 37 9 7f7f7f
23 37 9 7f7f7f
24 37 9 7f7f7f
25 37 9 7f7f7f
26 37 9 7f7f7f
27 37 9 7f7f7f
28 37 9 7f7f7f
29 37 9 7f7f7f
30 37 9 7f7f7f
31 37 9 7f7f7f
16 38 9 7f7f7f
17 38 9 7f7f7f
18 38 9 7f7f7f
19 38 9 7f7f7f
20 38 9 7f7f7f
21 38 9 7f7f7f
22 38 9 7f7f7f
23 38 9 7f7f7f
24 38 9 7f7f7f
25 38 9 7f7f7f
26 38 9 7f7f7f
27 38 9 7f7f7f
28 38 9 7f7f7f
29 38 9 7f7f7f
30 38 9 7f7f7f
31 38 9 7f7f7f
16 39 9 7f7f7f
17 39 9 7f7f7f
18 39 9 7f7f7f
19 39 9 7f7f7f
20 39 9 7f7f7f
21 39 9 7f7f7f
22 39 9 7f7f7f
23 39 9 7f7f7f
24 39 9 7f7f7f
25 39 9 7f7f7f
26 39 9 7f7f7f
27 39 9 7f7f7f
28 39 9 7f7f7f
29 39 9 7f7f7f
30 39 9 7f7f7f
31 39 9 7f7f7f
16 40 9 7f7f7f
17 40 9 7f7f7f
18 40 9 7f7f7f
19 40 9 7f7f7f
20 40 9 7f7f7f
21 40 9 7f7f7f
22 40 9 7f7f7f
23 40 9 7f7f7f
24 40 9 7f7f7f
25 40 9 7f7f7f
26 40 9 7f7f7f
27 40 9 7f7f7f
16 41 9 7f7f7f
17 41 9 7f7f7f
18 41 9 7f7f7f
19 41 9 7f7f7f
20 41 9 7f7f7f
21 41 9 7f7f7f
22 41 9 7f7f7f
23 41 9 7f7f7f
24 41 9 7f7f7f
25 41 9 7f7f7f
26 41 9 7f7f7f
27 41 9 7f7f7f
16 42 9 7f7f7f
17 42 9 7f7f7f
18 42 9 7f7f7f
19 42 9 7f7f7f
20 42 9 7f7f7f
21 42 9 7f7f7f
22 42 9 7f7f7f
23 42 9 7f7f7f
24 42 9 7f7f7f
25 42 9 7f7f7f
26 42 9 7f7f7f
27 42 9 7f7f7f
16 43 9 7f7f7f
17 43 9 7f7f7f
18 43 9 7f7f7f
19 43 9 7f7f7f
20 43 9 7f7f7f
21 43 9 7f7f7f
22 43 9 7f7f7f
23 43 9 7f7f7f
24 43 9 7f7f7f
25 43 9 7f7f7f
26 43 9 7f7f7f
27 43 9 7f7f7f
16 44 9 7f7f7f
17 44 9 7f7f7f
18 44 9 7f7f7f
19 44 9 7f7f7f
20 44 9 7f7f7f
21 44 9 7f7f7f
22 44 9 7f7f7f
23 44 9 7f7f7f
24 44 9 7f7f7f
25 44 9 7f7f7f
26 44 9 7f7f7f
27 44 9 7f7f7f
16 45 9 7f7f7f
17 45 9 7f7f7f
18 45 9 7f7f7f
19 45 9 7f7f7f
20 45 9 7f7f7f
21 45 9 7f7f7f
22 45 9 7f7f7f
23 45 9 7f7f7f
24 45 9 7f7f7f
25 45 9 7f7f7f
26 45 9 7f7f7f
27 45 9 7f7f7f
16 46 9 7f7f7f
17 46 9 7f7f7f
18 46 9 7f7f7f
19 46 9 7f7f7f
20 46 9 7f7f7f
21 46 9 7f7f7f
22 46 9 7f7f7f
23 46 9 7f7f7f
24 46 9 7f7f7f
25 46 9 7f7f7f
26 46 9 7f7f7f
27 46 9 7f7f7f
16 47 9 7f7f7f
17 47 9 7f7f7f
18 47 9 7f7f7f
19 47 9 7f7f7f
20 47 9 7f7f7f
21 47 9 7f7f7f
22 47 9 7f7f7f
23 47 9 7f7f7f
24 47 9 7f7f7f
25 47 9 7f7f7f
26 47 9 7f7f7f
27 47 9 7f7f7f
16 32 10 7f7f7f
17 32 10 7f7f7f
18 32 10 7f7f7f
19 32 10 7f7f7f
20 32 10 7f7f7f
21 32 10 7f7f7f
22 32 10 7f7f7f
23 32 10 7f7f7f
24 32 10 7f7f7f
25 32 10 7f7f7f
26 32 10 7f7f7f
27 32 10 7f7f7f
28 32 10 7f7f7f
29 32 10 7f7f7f
30 32 10 7f7f7f
31 32 10 7f7f7f
16 33 10 7f7f7f
17 33 10 7f7f7f
18 33 10 7f7f7f
19 33 10 7f7f7f
20 33 10 7f7f7f
21 33 10 7f7f7f
22 33 10 7f7f7f
23 33 10 7f7f7f
24 33 10 7f7f7f
25 33 10 7f7f7f
26 33 10 7f7f7f
27 33 10 7f7f7f
28 33 10 7f7f7f
29 33 10 7f7f7f
30 33 10 7f7f7f
31 33 10 7f7f7f
16 34 10 7f7f7f
17 34 10 7f7f7f
18 34 10 7f7f7f
19 34 10 7f7f7f
20 34 10 7f7f7f
21 34 10 7f7f7f
22 34 10 7f7f7f
23 34 10 7f7f7f
24 34 10 7f7f7f
25 34 10 7f7f7f
26 34 10 7f7f7f
27 34 10 7f7f7f
28 34 10 7f7f7f
29 34 10 7f7f7f
30 34 10 7f7f7f
31 34 10 7f7f7f
16 35 10 7f7f7f
17 35 10 7f7f7f
18 35 10 7f7f7f
19 35 10 7f7f7f
20 35 10 7f7f7f
21 35 10 7f7f7f
22 35 10 7f7f7f
23 35 10 7f7f7f
24 35 10 7f7f7f
25 35 10 7f7f7f
26 35 10 7f7f7f
27 35 10 7f7f7f
28 35 10 7f7f7f
29 35 10 7f7f7f
30 35 10 7f7f7f
31 35 10 7f7f7f
16 36 10 7f7f7f
17 36 10 7f7f7f
18 36 10 7f7f7f
19 36 10 7f7f7f
20 36 10 7f7f7f
21 36 10 7f7f7f
22 36 10 7f7f7f
23 36 10 7f7f7f
24 36 10 7f7f7f
25 36 10 7f7f7f
26 36 10 7f7f7f
27 36 10 7f7f7f
28 36 10 7f7f7f
29 36 10 7f7f7f
30 36 10 7f7f7f
31 36 10 7f7f7f
16 37 10 7f7f7f
17 37 10 7f7f7f
18 37 10 7f7f7f
19 37 10 7f7f7f
20 37 10 7f7f7f
21 37 10 7f7f7f
22 37 10 7f7f7f
23 37 10 7f7f7f
24 37 10 7f7f7f
25 37 10 7f7f7f
26 37 10 7f7f7f
27 37 10 7f7f7f
28 37 10 7f7f7f
29 37 10 7f7f7f
30 37 10 7f7f7f
31 37 10 7f7f7f
16 38 10 7f7f7f
17 38 10 7f7f7f
18 38 10 7f7f7f
19 38 10 7f7f7f
20 38 10 7f7f7f
21 38 10 7f7f7f
22 38 10 7f7f7f
23 38 10 7f7f7f
24 38 10 7f7f7f
25 38 10 7f7f7f
26 38 10 7f7f7f
27 38 10 7f7f7f
28 38 10 7f7f7f
29 38 10 7f7f7f
30 38 10 7f7f7f
31 38 10 7f7f7f
16 39 10 7f7f7f
17 39 10 7f7f7f
18 39 10 7f7f7f
19 39 10 7f7f7f
20 39 10 7f7f7f
21 39 10 7f7f7f
22 39 10 7f7f7f
23 39 10 7f7f7f
24 39 10 7f7f7f
25 39 10 7f7f7f
26 39 10 7f7f7f
27 39 10 7f7f7f
28 39 10 7f7f7f
29 39 10 7f7f7f
30 39 10 7f7f7f
31 39 10 7f7f7f
16 32 11 7f7f7f
17 32 11 7f7f7f
18 32 11 7f7f7f
19 32 11 7f7f7f
20 32 11 7f7f7f
21 32 11 7f7f7f
22 32 11 7f7f7f
23 32 11 7f7f7f
24 32 11 7f7f7f
25 32 11 7f7f7f
26 32 11 7f7f7f
27 32 11 7f7f7f
28 32 11 7f7f7f
29 32 11 7f7f7f
30 32 11 7f7f7f
31 32 11 7f7f7f
16 33 11 7f7f7f
17 33 11 7f7f7f
18 33 11 7f7f7f
19 33 11 7f7f7f
20 33 11 7f7f7f
21 33 11 7f7f7f
22 33 11 7f7f7f
23 33 11 7f7f7f
24 33 11 7f7f7f
25 33 11 7f7f7f
26 33 11 7f7f7f
27 33 11 7f7f7f
28 33 11 7f7f7f
29 33 11 7f7f7f
30 33 11 7f7f7f
31 33 11 7f7f7f
16 34 11 7f7f7f
17 34 11 7f7f7f
18 34 11 7f7f7f
19 34 11 7f7f7f
20 34 11 7f7f7f
21 34 11 7f7f7f
22 34 11 7f7f7f
23 34 11 7f7f7f
24 34 11 7f7f7f
25 34 11 7f7f7f
26 34 11 7f7f7f
27 34 11 7f7f7f
28 34 11 7f7f7f
29 34 11 7f7f7f
30 34 11 7f7f7f
31 34 11 7f7f7f
16 35 11 7f7f7f
17 35 11 7f7f7f
18 35 11 7f7f7f
19 35 11 7f7f7f
20 35 11 7f7f7f
21 35 11 7f7f7f
22 35 11 7f7f7f
23 35 11 7f7f7f
24 35 11 7f7f7f
25 35 11 7f7f7f
26 35 11 7f7f7f
27 35 11 7f7f7f
28 35 11 7f7f7f
29 35 11 7f7f7f
30 35 11 7f7f7f
31 35 11 7f7f7f
16 36 11 7f7f7f
17 36 11 7f7f7f
18 36 11 7f7f7f
19 36 11 7f7f7f
20 36 11 7f7f7f
21 36 11 7f7f7f
22 36 11 7f7f7f
23 36 11 7f7f7f
24 36 11 7f7f7f
25 36 11 7f7f7f
26 36 11 7f7f7f
27 36 11 7f7f7f
28 36 11 7f7f7f
29 36 11 7f7f7f
30 36 11 7f7f7f
31 36 11 7f7f7f
16 37 11 7f7f7f
17 37 11 7f7f7f
18 37 11 7f7f7f
19 37 11 7f7f7f
20 37 11 7f7f7f
21 37 11 7f7f7f
22 37 11 7f7f7f
23 37 11 7f7f7f
24 37 11 7f7f7f
25 37 11 7f7f7f
26 37 11 7f7f7f
27 37 11 7f7f7f
28 37 11 7f7f7f
29 37 11 7f7f7f
30 37 11 7f7f7f
31 37 11 7f7f7f
16 38 11 7f7f7f
17 38 11 7f7f7f
18 38 11 7f7f7f
19 38 11 7f7f7f
20 38 11 7f7f7f
21 38 11 7f7f7f
22 38 11 7f7f7f
23 38 11 7f7f7f
24 38 11 7f7f7f
25 38 11 7f7f7f
26 38 11 7f7f7f
27 38 11 7f7f7f
28 38 11 7f7f7f
29 38 11 7f7f7f
30 38 11 7f7f7f
31 38 11 7f7f7f
16 39 11 7f7f7f
17 39 11 7f7f7f
18 39 11 7f7f7f
19 39 11 7f7f7f
20 39 11 7f7f7f
21 39 11 7f7f7f
22 39 11 7f7f7f
23 39 11 7f7f7f
24 39 11 7f7f7f
25 39 11 7f7f7f
26 39 11 7f7f7f
27 39 11 7f7f7f
28 39 11 7f7f7f
29 39 11 7f7f7f
30 39 11 7f7f7f
31 39 11 7f7f7f
16 32 12 7f7f7f
17 32 12 7f7f7f
18 32 12 7f7f7f
19 32 12 7f7f7f
20 32 12 7f7f7f
21 32 12 7f7f7f
22 32 12 7f7f7f
23 32 12 7f7f7f
24 32 12 7f7f7f
25 32 12 7f7f7f
26 32 12 7f7f7f
27 32 12 7f7f7f
28 32 12 7f7f7f
29 32 12 7f7f7f
30 32 12 7f7f7f
31 32 12 7f7f7f
16 33 12 7f7f7f
17 33 12 7f7f7f
18 33 12 7f7f7f
19 33 12 7f7f7f
20 33 12 7f7f7f
21 33 12 7f7f7f
22 33 12 7f7f7f
23 33 12 7f7f7f
24 33 12 7f7f7f
25 33 12 7f7f7f
26 33 12 7f7f7f
27 33 12 7f7f7f
28 33 12 7f7f7f
29 33 12 7f7f7f
30 33 12 7f7f7f
31 33 12 7f7f7f
16 34 12 7f7f7f
17 34 12 7f7f7f
18 34 12 7f7f7f
19 34 12 7f7f7f
20 34 12 7f7f7f
21 34 12 7f7f7f
22 34 12 7f7f7f
23 34 12 7f7f7f
24 34 12 7f7f7f
25 34 12 7f7f7f
26 34 12 7f7f7f
27 34 12 7f7f7f
28 34 12 7f7f7f
29 34 12 7f7f7f
30 34 12 7f7f7f
31 34 12 7f7f7f
16 35 12 7f7f7f
17 35 12 7f7f7f
18 35 12 7f7f7f
19 35 12 7f7f7f
20 35 12 7f7f7f
21 35 12 7f7f7f
22 35 12 7f7f7f
23 35 12 7f7f7f
24 35 12 7f7f7f
25 35 12 7f7f7f
26 35 12 7f7f7f
27 35 12 7f7f7f
28 35 12 7f7f7f
29 35 12 7f7f7f
30 35 12 7f7f7f
31 35 12 7f7f7f
16 36 12 7f7f7f
17 36 12 7f7f7f
18 36 12 7f7f7f
19 36 12 7f7f7f
20 36 12 7f7f7f
21 36 12 7f7f7f
22 36 12 7f7f7f
23 36 12 7f7f7f
24 36 12 7f7f7f
25 36 12 7f7f7f
26 36 12 7f7f7f
27 36 12 7f7f7f
28 36 12 7f7f7f
29 36 12 7f7f7f
30 36 12 7f7f7f
31 36 12 7f7f7f
16 37 12 7f7f7f
